distributed.nanny - INFO -         Start Nanny at: 'tcp://10.148.9.128:57031'
distributed.worker - INFO -       Start worker at:   tcp://10.148.9.128:56537
distributed.worker - INFO -          Listening to:   tcp://10.148.9.128:56537
distributed.worker - INFO -              nanny at:         10.148.9.128:57031
distributed.worker - INFO -              bokeh at:         10.148.9.128:56985
distributed.worker - INFO - Waiting to connect to:    tcp://10.148.5.46:40005
distributed.worker - INFO - -------------------------------------------------
distributed.worker - INFO -               Threads:                         36
distributed.worker - INFO -                Memory:                  100.00 GB
distributed.worker - INFO -       Local Directory: /var/tmp/pbs.4279622.chadmin1/worker-pg123hb9
distributed.worker - INFO - -------------------------------------------------
distributed.worker - INFO -         Registered to:    tcp://10.148.5.46:40005
distributed.worker - INFO - -------------------------------------------------
distributed.core - INFO - Starting established connection
distributed.core - INFO - Event loop was unresponsive in Worker for 21.31s.  This is often caused by long-running GIL-holding functions or moving large chunks of data. This can cause timeouts and instability.
distributed.core - INFO - Event loop was unresponsive in Worker for 31.49s.  This is often caused by long-running GIL-holding functions or moving large chunks of data. This can cause timeouts and instability.
distributed.core - INFO - Event loop was unresponsive in Worker for 39.22s.  This is often caused by long-running GIL-holding functions or moving large chunks of data. This can cause timeouts and instability.
distributed.core - INFO - Event loop was unresponsive in Worker for 9.71s.  This is often caused by long-running GIL-holding functions or moving large chunks of data. This can cause timeouts and instability.
distributed.core - INFO - Event loop was unresponsive in Worker for 34.55s.  This is often caused by long-running GIL-holding functions or moving large chunks of data. This can cause timeouts and instability.
distributed.core - INFO - Event loop was unresponsive in Worker for 39.67s.  This is often caused by long-running GIL-holding functions or moving large chunks of data. This can cause timeouts and instability.
distributed.worker - INFO - Failed to put key in memory
Traceback (most recent call last):
  File "/glade/u/home/baird/miniconda3/envs/pangeo/lib/python3.7/site-packages/distributed/worker.py", line 1356, in transition_executing_done
    self.put_key_in_memory(key, value, transition=False)
  File "/glade/u/home/baird/miniconda3/envs/pangeo/lib/python3.7/site-packages/distributed/worker.py", line 1548, in put_key_in_memory
    self.data[key] = value
  File "/glade/u/home/baird/miniconda3/envs/pangeo/lib/python3.7/site-packages/zict/buffer.py", line 80, in __setitem__
    self.fast[key] = value
  File "/glade/u/home/baird/miniconda3/envs/pangeo/lib/python3.7/site-packages/zict/lru.py", line 71, in __setitem__
    self.evict()
  File "/glade/u/home/baird/miniconda3/envs/pangeo/lib/python3.7/site-packages/zict/lru.py", line 90, in evict
    cb(k, v)
  File "/glade/u/home/baird/miniconda3/envs/pangeo/lib/python3.7/site-packages/zict/buffer.py", line 52, in fast_to_slow
    self.slow[key] = value
  File "/glade/u/home/baird/miniconda3/envs/pangeo/lib/python3.7/site-packages/zict/func.py", line 42, in __setitem__
    self.d[key] = self.dump(value)
  File "/glade/u/home/baird/miniconda3/envs/pangeo/lib/python3.7/site-packages/zict/file.py", line 83, in __setitem__
    f.write(v)
OSError: [Errno 28] No space left on device
distributed.worker - INFO - Failed to put key in memory
Traceback (most recent call last):
  File "/glade/u/home/baird/miniconda3/envs/pangeo/lib/python3.7/site-packages/zict/file.py", line 83, in __setitem__
    f.write(v)
OSError: [Errno 28] No space left on device

During handling of the above exception, another exception occurred:

Traceback (most recent call last):
  File "/glade/u/home/baird/miniconda3/envs/pangeo/lib/python3.7/site-packages/distributed/worker.py", line 1356, in transition_executing_done
    self.put_key_in_memory(key, value, transition=False)
  File "/glade/u/home/baird/miniconda3/envs/pangeo/lib/python3.7/site-packages/distributed/worker.py", line 1548, in put_key_in_memory
    self.data[key] = value
  File "/glade/u/home/baird/miniconda3/envs/pangeo/lib/python3.7/site-packages/zict/buffer.py", line 80, in __setitem__
    self.fast[key] = value
  File "/glade/u/home/baird/miniconda3/envs/pangeo/lib/python3.7/site-packages/zict/lru.py", line 71, in __setitem__
    self.evict()
  File "/glade/u/home/baird/miniconda3/envs/pangeo/lib/python3.7/site-packages/zict/lru.py", line 90, in evict
    cb(k, v)
  File "/glade/u/home/baird/miniconda3/envs/pangeo/lib/python3.7/site-packages/zict/buffer.py", line 52, in fast_to_slow
    self.slow[key] = value
  File "/glade/u/home/baird/miniconda3/envs/pangeo/lib/python3.7/site-packages/zict/func.py", line 42, in __setitem__
    self.d[key] = self.dump(value)
  File "/glade/u/home/baird/miniconda3/envs/pangeo/lib/python3.7/site-packages/zict/file.py", line 85, in __setitem__
    f.write(value)
OSError: [Errno 28] No space left on device
distributed.worker - INFO - Failed to put key in memory
Traceback (most recent call last):
  File "/glade/u/home/baird/miniconda3/envs/pangeo/lib/python3.7/site-packages/zict/file.py", line 83, in __setitem__
    f.write(v)
OSError: [Errno 28] No space left on device

During handling of the above exception, another exception occurred:

Traceback (most recent call last):
  File "/glade/u/home/baird/miniconda3/envs/pangeo/lib/python3.7/site-packages/distributed/worker.py", line 1356, in transition_executing_done
    self.put_key_in_memory(key, value, transition=False)
  File "/glade/u/home/baird/miniconda3/envs/pangeo/lib/python3.7/site-packages/distributed/worker.py", line 1548, in put_key_in_memory
    self.data[key] = value
  File "/glade/u/home/baird/miniconda3/envs/pangeo/lib/python3.7/site-packages/zict/buffer.py", line 80, in __setitem__
    self.fast[key] = value
  File "/glade/u/home/baird/miniconda3/envs/pangeo/lib/python3.7/site-packages/zict/lru.py", line 71, in __setitem__
    self.evict()
  File "/glade/u/home/baird/miniconda3/envs/pangeo/lib/python3.7/site-packages/zict/lru.py", line 90, in evict
    cb(k, v)
  File "/glade/u/home/baird/miniconda3/envs/pangeo/lib/python3.7/site-packages/zict/buffer.py", line 52, in fast_to_slow
    self.slow[key] = value
  File "/glade/u/home/baird/miniconda3/envs/pangeo/lib/python3.7/site-packages/zict/func.py", line 42, in __setitem__
    self.d[key] = self.dump(value)
  File "/glade/u/home/baird/miniconda3/envs/pangeo/lib/python3.7/site-packages/zict/file.py", line 85, in __setitem__
    f.write(value)
OSError: [Errno 28] No space left on device
distributed.worker - INFO - Failed to put key in memory
Traceback (most recent call last):
  File "/glade/u/home/baird/miniconda3/envs/pangeo/lib/python3.7/site-packages/zict/file.py", line 83, in __setitem__
    f.write(v)
OSError: [Errno 28] No space left on device

During handling of the above exception, another exception occurred:

Traceback (most recent call last):
  File "/glade/u/home/baird/miniconda3/envs/pangeo/lib/python3.7/site-packages/distributed/worker.py", line 1356, in transition_executing_done
    self.put_key_in_memory(key, value, transition=False)
  File "/glade/u/home/baird/miniconda3/envs/pangeo/lib/python3.7/site-packages/distributed/worker.py", line 1548, in put_key_in_memory
    self.data[key] = value
  File "/glade/u/home/baird/miniconda3/envs/pangeo/lib/python3.7/site-packages/zict/buffer.py", line 80, in __setitem__
    self.fast[key] = value
  File "/glade/u/home/baird/miniconda3/envs/pangeo/lib/python3.7/site-packages/zict/lru.py", line 71, in __setitem__
    self.evict()
  File "/glade/u/home/baird/miniconda3/envs/pangeo/lib/python3.7/site-packages/zict/lru.py", line 90, in evict
    cb(k, v)
  File "/glade/u/home/baird/miniconda3/envs/pangeo/lib/python3.7/site-packages/zict/buffer.py", line 52, in fast_to_slow
    self.slow[key] = value
  File "/glade/u/home/baird/miniconda3/envs/pangeo/lib/python3.7/site-packages/zict/func.py", line 42, in __setitem__
    self.d[key] = self.dump(value)
  File "/glade/u/home/baird/miniconda3/envs/pangeo/lib/python3.7/site-packages/zict/file.py", line 85, in __setitem__
    f.write(value)
OSError: [Errno 28] No space left on device
distributed.worker - INFO - Failed to put key in memory
Traceback (most recent call last):
  File "/glade/u/home/baird/miniconda3/envs/pangeo/lib/python3.7/site-packages/zict/file.py", line 83, in __setitem__
    f.write(v)
OSError: [Errno 28] No space left on device

During handling of the above exception, another exception occurred:

Traceback (most recent call last):
  File "/glade/u/home/baird/miniconda3/envs/pangeo/lib/python3.7/site-packages/distributed/worker.py", line 1356, in transition_executing_done
    self.put_key_in_memory(key, value, transition=False)
  File "/glade/u/home/baird/miniconda3/envs/pangeo/lib/python3.7/site-packages/distributed/worker.py", line 1548, in put_key_in_memory
    self.data[key] = value
  File "/glade/u/home/baird/miniconda3/envs/pangeo/lib/python3.7/site-packages/zict/buffer.py", line 80, in __setitem__
    self.fast[key] = value
  File "/glade/u/home/baird/miniconda3/envs/pangeo/lib/python3.7/site-packages/zict/lru.py", line 71, in __setitem__
    self.evict()
  File "/glade/u/home/baird/miniconda3/envs/pangeo/lib/python3.7/site-packages/zict/lru.py", line 90, in evict
    cb(k, v)
  File "/glade/u/home/baird/miniconda3/envs/pangeo/lib/python3.7/site-packages/zict/buffer.py", line 52, in fast_to_slow
    self.slow[key] = value
  File "/glade/u/home/baird/miniconda3/envs/pangeo/lib/python3.7/site-packages/zict/func.py", line 42, in __setitem__
    self.d[key] = self.dump(value)
  File "/glade/u/home/baird/miniconda3/envs/pangeo/lib/python3.7/site-packages/zict/file.py", line 85, in __setitem__
    f.write(value)
OSError: [Errno 28] No space left on device
distributed.worker - INFO - Failed to put key in memory
Traceback (most recent call last):
  File "/glade/u/home/baird/miniconda3/envs/pangeo/lib/python3.7/site-packages/zict/file.py", line 83, in __setitem__
    f.write(v)
OSError: [Errno 28] No space left on device

During handling of the above exception, another exception occurred:

Traceback (most recent call last):
  File "/glade/u/home/baird/miniconda3/envs/pangeo/lib/python3.7/site-packages/distributed/worker.py", line 1356, in transition_executing_done
    self.put_key_in_memory(key, value, transition=False)
  File "/glade/u/home/baird/miniconda3/envs/pangeo/lib/python3.7/site-packages/distributed/worker.py", line 1548, in put_key_in_memory
    self.data[key] = value
  File "/glade/u/home/baird/miniconda3/envs/pangeo/lib/python3.7/site-packages/zict/buffer.py", line 80, in __setitem__
    self.fast[key] = value
  File "/glade/u/home/baird/miniconda3/envs/pangeo/lib/python3.7/site-packages/zict/lru.py", line 71, in __setitem__
    self.evict()
  File "/glade/u/home/baird/miniconda3/envs/pangeo/lib/python3.7/site-packages/zict/lru.py", line 90, in evict
    cb(k, v)
  File "/glade/u/home/baird/miniconda3/envs/pangeo/lib/python3.7/site-packages/zict/buffer.py", line 52, in fast_to_slow
    self.slow[key] = value
  File "/glade/u/home/baird/miniconda3/envs/pangeo/lib/python3.7/site-packages/zict/func.py", line 42, in __setitem__
    self.d[key] = self.dump(value)
  File "/glade/u/home/baird/miniconda3/envs/pangeo/lib/python3.7/site-packages/zict/file.py", line 85, in __setitem__
    f.write(value)
OSError: [Errno 28] No space left on device
distributed.worker - INFO - Failed to put key in memory
Traceback (most recent call last):
  File "/glade/u/home/baird/miniconda3/envs/pangeo/lib/python3.7/site-packages/zict/file.py", line 83, in __setitem__
    f.write(v)
OSError: [Errno 28] No space left on device

During handling of the above exception, another exception occurred:

Traceback (most recent call last):
  File "/glade/u/home/baird/miniconda3/envs/pangeo/lib/python3.7/site-packages/distributed/worker.py", line 1356, in transition_executing_done
    self.put_key_in_memory(key, value, transition=False)
  File "/glade/u/home/baird/miniconda3/envs/pangeo/lib/python3.7/site-packages/distributed/worker.py", line 1548, in put_key_in_memory
    self.data[key] = value
  File "/glade/u/home/baird/miniconda3/envs/pangeo/lib/python3.7/site-packages/zict/buffer.py", line 80, in __setitem__
    self.fast[key] = value
  File "/glade/u/home/baird/miniconda3/envs/pangeo/lib/python3.7/site-packages/zict/lru.py", line 71, in __setitem__
    self.evict()
  File "/glade/u/home/baird/miniconda3/envs/pangeo/lib/python3.7/site-packages/zict/lru.py", line 90, in evict
    cb(k, v)
  File "/glade/u/home/baird/miniconda3/envs/pangeo/lib/python3.7/site-packages/zict/buffer.py", line 52, in fast_to_slow
    self.slow[key] = value
  File "/glade/u/home/baird/miniconda3/envs/pangeo/lib/python3.7/site-packages/zict/func.py", line 42, in __setitem__
    self.d[key] = self.dump(value)
  File "/glade/u/home/baird/miniconda3/envs/pangeo/lib/python3.7/site-packages/zict/file.py", line 85, in __setitem__
    f.write(value)
OSError: [Errno 28] No space left on device
distributed.worker - INFO - Failed to put key in memory
Traceback (most recent call last):
  File "/glade/u/home/baird/miniconda3/envs/pangeo/lib/python3.7/site-packages/zict/file.py", line 83, in __setitem__
    f.write(v)
OSError: [Errno 28] No space left on device

During handling of the above exception, another exception occurred:

Traceback (most recent call last):
  File "/glade/u/home/baird/miniconda3/envs/pangeo/lib/python3.7/site-packages/distributed/worker.py", line 1356, in transition_executing_done
    self.put_key_in_memory(key, value, transition=False)
  File "/glade/u/home/baird/miniconda3/envs/pangeo/lib/python3.7/site-packages/distributed/worker.py", line 1548, in put_key_in_memory
    self.data[key] = value
  File "/glade/u/home/baird/miniconda3/envs/pangeo/lib/python3.7/site-packages/zict/buffer.py", line 80, in __setitem__
    self.fast[key] = value
  File "/glade/u/home/baird/miniconda3/envs/pangeo/lib/python3.7/site-packages/zict/lru.py", line 71, in __setitem__
    self.evict()
  File "/glade/u/home/baird/miniconda3/envs/pangeo/lib/python3.7/site-packages/zict/lru.py", line 90, in evict
    cb(k, v)
  File "/glade/u/home/baird/miniconda3/envs/pangeo/lib/python3.7/site-packages/zict/buffer.py", line 52, in fast_to_slow
    self.slow[key] = value
  File "/glade/u/home/baird/miniconda3/envs/pangeo/lib/python3.7/site-packages/zict/func.py", line 42, in __setitem__
    self.d[key] = self.dump(value)
  File "/glade/u/home/baird/miniconda3/envs/pangeo/lib/python3.7/site-packages/zict/file.py", line 85, in __setitem__
    f.write(value)
OSError: [Errno 28] No space left on device
distributed.worker - INFO - Failed to put key in memory
Traceback (most recent call last):
  File "/glade/u/home/baird/miniconda3/envs/pangeo/lib/python3.7/site-packages/zict/file.py", line 83, in __setitem__
    f.write(v)
OSError: [Errno 28] No space left on device

During handling of the above exception, another exception occurred:

Traceback (most recent call last):
  File "/glade/u/home/baird/miniconda3/envs/pangeo/lib/python3.7/site-packages/distributed/worker.py", line 1356, in transition_executing_done
    self.put_key_in_memory(key, value, transition=False)
  File "/glade/u/home/baird/miniconda3/envs/pangeo/lib/python3.7/site-packages/distributed/worker.py", line 1548, in put_key_in_memory
    self.data[key] = value
  File "/glade/u/home/baird/miniconda3/envs/pangeo/lib/python3.7/site-packages/zict/buffer.py", line 80, in __setitem__
    self.fast[key] = value
  File "/glade/u/home/baird/miniconda3/envs/pangeo/lib/python3.7/site-packages/zict/lru.py", line 71, in __setitem__
    self.evict()
  File "/glade/u/home/baird/miniconda3/envs/pangeo/lib/python3.7/site-packages/zict/lru.py", line 90, in evict
    cb(k, v)
  File "/glade/u/home/baird/miniconda3/envs/pangeo/lib/python3.7/site-packages/zict/buffer.py", line 52, in fast_to_slow
    self.slow[key] = value
  File "/glade/u/home/baird/miniconda3/envs/pangeo/lib/python3.7/site-packages/zict/func.py", line 42, in __setitem__
    self.d[key] = self.dump(value)
  File "/glade/u/home/baird/miniconda3/envs/pangeo/lib/python3.7/site-packages/zict/file.py", line 85, in __setitem__
    f.write(value)
OSError: [Errno 28] No space left on device
distributed.worker - INFO - Failed to put key in memory
Traceback (most recent call last):
  File "/glade/u/home/baird/miniconda3/envs/pangeo/lib/python3.7/site-packages/zict/file.py", line 83, in __setitem__
    f.write(v)
OSError: [Errno 28] No space left on device

During handling of the above exception, another exception occurred:

Traceback (most recent call last):
  File "/glade/u/home/baird/miniconda3/envs/pangeo/lib/python3.7/site-packages/distributed/worker.py", line 1356, in transition_executing_done
    self.put_key_in_memory(key, value, transition=False)
  File "/glade/u/home/baird/miniconda3/envs/pangeo/lib/python3.7/site-packages/distributed/worker.py", line 1548, in put_key_in_memory
    self.data[key] = value
  File "/glade/u/home/baird/miniconda3/envs/pangeo/lib/python3.7/site-packages/zict/buffer.py", line 80, in __setitem__
    self.fast[key] = value
  File "/glade/u/home/baird/miniconda3/envs/pangeo/lib/python3.7/site-packages/zict/lru.py", line 71, in __setitem__
    self.evict()
  File "/glade/u/home/baird/miniconda3/envs/pangeo/lib/python3.7/site-packages/zict/lru.py", line 90, in evict
    cb(k, v)
  File "/glade/u/home/baird/miniconda3/envs/pangeo/lib/python3.7/site-packages/zict/buffer.py", line 52, in fast_to_slow
    self.slow[key] = value
  File "/glade/u/home/baird/miniconda3/envs/pangeo/lib/python3.7/site-packages/zict/func.py", line 42, in __setitem__
    self.d[key] = self.dump(value)
  File "/glade/u/home/baird/miniconda3/envs/pangeo/lib/python3.7/site-packages/zict/file.py", line 85, in __setitem__
    f.write(value)
OSError: [Errno 28] No space left on device
distributed.worker - INFO - Failed to put key in memory
Traceback (most recent call last):
  File "/glade/u/home/baird/miniconda3/envs/pangeo/lib/python3.7/site-packages/zict/file.py", line 83, in __setitem__
    f.write(v)
OSError: [Errno 28] No space left on device

During handling of the above exception, another exception occurred:

Traceback (most recent call last):
  File "/glade/u/home/baird/miniconda3/envs/pangeo/lib/python3.7/site-packages/distributed/worker.py", line 1356, in transition_executing_done
    self.put_key_in_memory(key, value, transition=False)
  File "/glade/u/home/baird/miniconda3/envs/pangeo/lib/python3.7/site-packages/distributed/worker.py", line 1548, in put_key_in_memory
    self.data[key] = value
  File "/glade/u/home/baird/miniconda3/envs/pangeo/lib/python3.7/site-packages/zict/buffer.py", line 80, in __setitem__
    self.fast[key] = value
  File "/glade/u/home/baird/miniconda3/envs/pangeo/lib/python3.7/site-packages/zict/lru.py", line 71, in __setitem__
    self.evict()
  File "/glade/u/home/baird/miniconda3/envs/pangeo/lib/python3.7/site-packages/zict/lru.py", line 90, in evict
    cb(k, v)
  File "/glade/u/home/baird/miniconda3/envs/pangeo/lib/python3.7/site-packages/zict/buffer.py", line 52, in fast_to_slow
    self.slow[key] = value
  File "/glade/u/home/baird/miniconda3/envs/pangeo/lib/python3.7/site-packages/zict/func.py", line 42, in __setitem__
    self.d[key] = self.dump(value)
  File "/glade/u/home/baird/miniconda3/envs/pangeo/lib/python3.7/site-packages/zict/file.py", line 85, in __setitem__
    f.write(value)
OSError: [Errno 28] No space left on device
distributed.worker - INFO - Failed to put key in memory
Traceback (most recent call last):
  File "/glade/u/home/baird/miniconda3/envs/pangeo/lib/python3.7/site-packages/zict/file.py", line 83, in __setitem__
    f.write(v)
OSError: [Errno 28] No space left on device

During handling of the above exception, another exception occurred:

Traceback (most recent call last):
  File "/glade/u/home/baird/miniconda3/envs/pangeo/lib/python3.7/site-packages/distributed/worker.py", line 1356, in transition_executing_done
    self.put_key_in_memory(key, value, transition=False)
  File "/glade/u/home/baird/miniconda3/envs/pangeo/lib/python3.7/site-packages/distributed/worker.py", line 1548, in put_key_in_memory
    self.data[key] = value
  File "/glade/u/home/baird/miniconda3/envs/pangeo/lib/python3.7/site-packages/zict/buffer.py", line 80, in __setitem__
    self.fast[key] = value
  File "/glade/u/home/baird/miniconda3/envs/pangeo/lib/python3.7/site-packages/zict/lru.py", line 71, in __setitem__
    self.evict()
  File "/glade/u/home/baird/miniconda3/envs/pangeo/lib/python3.7/site-packages/zict/lru.py", line 90, in evict
    cb(k, v)
  File "/glade/u/home/baird/miniconda3/envs/pangeo/lib/python3.7/site-packages/zict/buffer.py", line 52, in fast_to_slow
    self.slow[key] = value
  File "/glade/u/home/baird/miniconda3/envs/pangeo/lib/python3.7/site-packages/zict/func.py", line 42, in __setitem__
    self.d[key] = self.dump(value)
  File "/glade/u/home/baird/miniconda3/envs/pangeo/lib/python3.7/site-packages/zict/file.py", line 85, in __setitem__
    f.write(value)
OSError: [Errno 28] No space left on device
distributed.worker - INFO - Failed to put key in memory
Traceback (most recent call last):
  File "/glade/u/home/baird/miniconda3/envs/pangeo/lib/python3.7/site-packages/zict/file.py", line 83, in __setitem__
    f.write(v)
OSError: [Errno 28] No space left on device

During handling of the above exception, another exception occurred:

Traceback (most recent call last):
  File "/glade/u/home/baird/miniconda3/envs/pangeo/lib/python3.7/site-packages/distributed/worker.py", line 1356, in transition_executing_done
    self.put_key_in_memory(key, value, transition=False)
  File "/glade/u/home/baird/miniconda3/envs/pangeo/lib/python3.7/site-packages/distributed/worker.py", line 1548, in put_key_in_memory
    self.data[key] = value
  File "/glade/u/home/baird/miniconda3/envs/pangeo/lib/python3.7/site-packages/zict/buffer.py", line 80, in __setitem__
    self.fast[key] = value
  File "/glade/u/home/baird/miniconda3/envs/pangeo/lib/python3.7/site-packages/zict/lru.py", line 71, in __setitem__
    self.evict()
  File "/glade/u/home/baird/miniconda3/envs/pangeo/lib/python3.7/site-packages/zict/lru.py", line 90, in evict
    cb(k, v)
  File "/glade/u/home/baird/miniconda3/envs/pangeo/lib/python3.7/site-packages/zict/buffer.py", line 52, in fast_to_slow
    self.slow[key] = value
  File "/glade/u/home/baird/miniconda3/envs/pangeo/lib/python3.7/site-packages/zict/func.py", line 42, in __setitem__
    self.d[key] = self.dump(value)
  File "/glade/u/home/baird/miniconda3/envs/pangeo/lib/python3.7/site-packages/zict/file.py", line 85, in __setitem__
    f.write(value)
OSError: [Errno 28] No space left on device
distributed.worker - INFO - Failed to put key in memory
Traceback (most recent call last):
  File "/glade/u/home/baird/miniconda3/envs/pangeo/lib/python3.7/site-packages/zict/file.py", line 83, in __setitem__
    f.write(v)
OSError: [Errno 28] No space left on device

During handling of the above exception, another exception occurred:

Traceback (most recent call last):
  File "/glade/u/home/baird/miniconda3/envs/pangeo/lib/python3.7/site-packages/distributed/worker.py", line 1356, in transition_executing_done
    self.put_key_in_memory(key, value, transition=False)
  File "/glade/u/home/baird/miniconda3/envs/pangeo/lib/python3.7/site-packages/distributed/worker.py", line 1548, in put_key_in_memory
    self.data[key] = value
  File "/glade/u/home/baird/miniconda3/envs/pangeo/lib/python3.7/site-packages/zict/buffer.py", line 80, in __setitem__
    self.fast[key] = value
  File "/glade/u/home/baird/miniconda3/envs/pangeo/lib/python3.7/site-packages/zict/lru.py", line 71, in __setitem__
    self.evict()
  File "/glade/u/home/baird/miniconda3/envs/pangeo/lib/python3.7/site-packages/zict/lru.py", line 90, in evict
    cb(k, v)
  File "/glade/u/home/baird/miniconda3/envs/pangeo/lib/python3.7/site-packages/zict/buffer.py", line 52, in fast_to_slow
    self.slow[key] = value
  File "/glade/u/home/baird/miniconda3/envs/pangeo/lib/python3.7/site-packages/zict/func.py", line 42, in __setitem__
    self.d[key] = self.dump(value)
  File "/glade/u/home/baird/miniconda3/envs/pangeo/lib/python3.7/site-packages/zict/file.py", line 85, in __setitem__
    f.write(value)
OSError: [Errno 28] No space left on device
distributed.worker - INFO - Failed to put key in memory
Traceback (most recent call last):
  File "/glade/u/home/baird/miniconda3/envs/pangeo/lib/python3.7/site-packages/zict/file.py", line 83, in __setitem__
    f.write(v)
OSError: [Errno 28] No space left on device

During handling of the above exception, another exception occurred:

Traceback (most recent call last):
  File "/glade/u/home/baird/miniconda3/envs/pangeo/lib/python3.7/site-packages/distributed/worker.py", line 1356, in transition_executing_done
    self.put_key_in_memory(key, value, transition=False)
  File "/glade/u/home/baird/miniconda3/envs/pangeo/lib/python3.7/site-packages/distributed/worker.py", line 1548, in put_key_in_memory
    self.data[key] = value
  File "/glade/u/home/baird/miniconda3/envs/pangeo/lib/python3.7/site-packages/zict/buffer.py", line 80, in __setitem__
    self.fast[key] = value
  File "/glade/u/home/baird/miniconda3/envs/pangeo/lib/python3.7/site-packages/zict/lru.py", line 71, in __setitem__
    self.evict()
  File "/glade/u/home/baird/miniconda3/envs/pangeo/lib/python3.7/site-packages/zict/lru.py", line 90, in evict
    cb(k, v)
  File "/glade/u/home/baird/miniconda3/envs/pangeo/lib/python3.7/site-packages/zict/buffer.py", line 52, in fast_to_slow
    self.slow[key] = value
  File "/glade/u/home/baird/miniconda3/envs/pangeo/lib/python3.7/site-packages/zict/func.py", line 42, in __setitem__
    self.d[key] = self.dump(value)
  File "/glade/u/home/baird/miniconda3/envs/pangeo/lib/python3.7/site-packages/zict/file.py", line 85, in __setitem__
    f.write(value)
OSError: [Errno 28] No space left on device
distributed.worker - INFO - Failed to put key in memory
Traceback (most recent call last):
  File "/glade/u/home/baird/miniconda3/envs/pangeo/lib/python3.7/site-packages/zict/file.py", line 83, in __setitem__
    f.write(v)
OSError: [Errno 28] No space left on device

During handling of the above exception, another exception occurred:

Traceback (most recent call last):
  File "/glade/u/home/baird/miniconda3/envs/pangeo/lib/python3.7/site-packages/distributed/worker.py", line 1356, in transition_executing_done
    self.put_key_in_memory(key, value, transition=False)
  File "/glade/u/home/baird/miniconda3/envs/pangeo/lib/python3.7/site-packages/distributed/worker.py", line 1548, in put_key_in_memory
    self.data[key] = value
  File "/glade/u/home/baird/miniconda3/envs/pangeo/lib/python3.7/site-packages/zict/buffer.py", line 80, in __setitem__
    self.fast[key] = value
  File "/glade/u/home/baird/miniconda3/envs/pangeo/lib/python3.7/site-packages/zict/lru.py", line 71, in __setitem__
    self.evict()
  File "/glade/u/home/baird/miniconda3/envs/pangeo/lib/python3.7/site-packages/zict/lru.py", line 90, in evict
    cb(k, v)
  File "/glade/u/home/baird/miniconda3/envs/pangeo/lib/python3.7/site-packages/zict/buffer.py", line 52, in fast_to_slow
    self.slow[key] = value
  File "/glade/u/home/baird/miniconda3/envs/pangeo/lib/python3.7/site-packages/zict/func.py", line 42, in __setitem__
    self.d[key] = self.dump(value)
  File "/glade/u/home/baird/miniconda3/envs/pangeo/lib/python3.7/site-packages/zict/file.py", line 85, in __setitem__
    f.write(value)
OSError: [Errno 28] No space left on device
distributed.worker - INFO - Failed to put key in memory
Traceback (most recent call last):
  File "/glade/u/home/baird/miniconda3/envs/pangeo/lib/python3.7/site-packages/zict/file.py", line 83, in __setitem__
    f.write(v)
OSError: [Errno 28] No space left on device

During handling of the above exception, another exception occurred:

Traceback (most recent call last):
  File "/glade/u/home/baird/miniconda3/envs/pangeo/lib/python3.7/site-packages/distributed/worker.py", line 1356, in transition_executing_done
    self.put_key_in_memory(key, value, transition=False)
  File "/glade/u/home/baird/miniconda3/envs/pangeo/lib/python3.7/site-packages/distributed/worker.py", line 1548, in put_key_in_memory
    self.data[key] = value
  File "/glade/u/home/baird/miniconda3/envs/pangeo/lib/python3.7/site-packages/zict/buffer.py", line 80, in __setitem__
    self.fast[key] = value
  File "/glade/u/home/baird/miniconda3/envs/pangeo/lib/python3.7/site-packages/zict/lru.py", line 71, in __setitem__
    self.evict()
  File "/glade/u/home/baird/miniconda3/envs/pangeo/lib/python3.7/site-packages/zict/lru.py", line 90, in evict
    cb(k, v)
  File "/glade/u/home/baird/miniconda3/envs/pangeo/lib/python3.7/site-packages/zict/buffer.py", line 52, in fast_to_slow
    self.slow[key] = value
  File "/glade/u/home/baird/miniconda3/envs/pangeo/lib/python3.7/site-packages/zict/func.py", line 42, in __setitem__
    self.d[key] = self.dump(value)
  File "/glade/u/home/baird/miniconda3/envs/pangeo/lib/python3.7/site-packages/zict/file.py", line 85, in __setitem__
    f.write(value)
OSError: [Errno 28] No space left on device
distributed.worker - INFO - Failed to put key in memory
Traceback (most recent call last):
  File "/glade/u/home/baird/miniconda3/envs/pangeo/lib/python3.7/site-packages/zict/file.py", line 83, in __setitem__
    f.write(v)
OSError: [Errno 28] No space left on device

During handling of the above exception, another exception occurred:

Traceback (most recent call last):
  File "/glade/u/home/baird/miniconda3/envs/pangeo/lib/python3.7/site-packages/distributed/worker.py", line 1356, in transition_executing_done
    self.put_key_in_memory(key, value, transition=False)
  File "/glade/u/home/baird/miniconda3/envs/pangeo/lib/python3.7/site-packages/distributed/worker.py", line 1548, in put_key_in_memory
    self.data[key] = value
  File "/glade/u/home/baird/miniconda3/envs/pangeo/lib/python3.7/site-packages/zict/buffer.py", line 80, in __setitem__
    self.fast[key] = value
  File "/glade/u/home/baird/miniconda3/envs/pangeo/lib/python3.7/site-packages/zict/lru.py", line 71, in __setitem__
    self.evict()
  File "/glade/u/home/baird/miniconda3/envs/pangeo/lib/python3.7/site-packages/zict/lru.py", line 90, in evict
    cb(k, v)
  File "/glade/u/home/baird/miniconda3/envs/pangeo/lib/python3.7/site-packages/zict/buffer.py", line 52, in fast_to_slow
    self.slow[key] = value
  File "/glade/u/home/baird/miniconda3/envs/pangeo/lib/python3.7/site-packages/zict/func.py", line 42, in __setitem__
    self.d[key] = self.dump(value)
  File "/glade/u/home/baird/miniconda3/envs/pangeo/lib/python3.7/site-packages/zict/file.py", line 85, in __setitem__
    f.write(value)
OSError: [Errno 28] No space left on device
distributed.worker - INFO - Failed to put key in memory
Traceback (most recent call last):
  File "/glade/u/home/baird/miniconda3/envs/pangeo/lib/python3.7/site-packages/zict/file.py", line 83, in __setitem__
    f.write(v)
OSError: [Errno 28] No space left on device

During handling of the above exception, another exception occurred:

Traceback (most recent call last):
  File "/glade/u/home/baird/miniconda3/envs/pangeo/lib/python3.7/site-packages/distributed/worker.py", line 1356, in transition_executing_done
    self.put_key_in_memory(key, value, transition=False)
  File "/glade/u/home/baird/miniconda3/envs/pangeo/lib/python3.7/site-packages/distributed/worker.py", line 1548, in put_key_in_memory
    self.data[key] = value
  File "/glade/u/home/baird/miniconda3/envs/pangeo/lib/python3.7/site-packages/zict/buffer.py", line 80, in __setitem__
    self.fast[key] = value
  File "/glade/u/home/baird/miniconda3/envs/pangeo/lib/python3.7/site-packages/zict/lru.py", line 71, in __setitem__
    self.evict()
  File "/glade/u/home/baird/miniconda3/envs/pangeo/lib/python3.7/site-packages/zict/lru.py", line 90, in evict
    cb(k, v)
  File "/glade/u/home/baird/miniconda3/envs/pangeo/lib/python3.7/site-packages/zict/buffer.py", line 52, in fast_to_slow
    self.slow[key] = value
  File "/glade/u/home/baird/miniconda3/envs/pangeo/lib/python3.7/site-packages/zict/func.py", line 42, in __setitem__
    self.d[key] = self.dump(value)
  File "/glade/u/home/baird/miniconda3/envs/pangeo/lib/python3.7/site-packages/zict/file.py", line 85, in __setitem__
    f.write(value)
OSError: [Errno 28] No space left on device
distributed.worker - INFO - Failed to put key in memory
Traceback (most recent call last):
  File "/glade/u/home/baird/miniconda3/envs/pangeo/lib/python3.7/site-packages/zict/file.py", line 83, in __setitem__
    f.write(v)
OSError: [Errno 28] No space left on device

During handling of the above exception, another exception occurred:

Traceback (most recent call last):
  File "/glade/u/home/baird/miniconda3/envs/pangeo/lib/python3.7/site-packages/distributed/worker.py", line 1356, in transition_executing_done
    self.put_key_in_memory(key, value, transition=False)
  File "/glade/u/home/baird/miniconda3/envs/pangeo/lib/python3.7/site-packages/distributed/worker.py", line 1548, in put_key_in_memory
    self.data[key] = value
  File "/glade/u/home/baird/miniconda3/envs/pangeo/lib/python3.7/site-packages/zict/buffer.py", line 80, in __setitem__
    self.fast[key] = value
  File "/glade/u/home/baird/miniconda3/envs/pangeo/lib/python3.7/site-packages/zict/lru.py", line 71, in __setitem__
    self.evict()
  File "/glade/u/home/baird/miniconda3/envs/pangeo/lib/python3.7/site-packages/zict/lru.py", line 90, in evict
    cb(k, v)
  File "/glade/u/home/baird/miniconda3/envs/pangeo/lib/python3.7/site-packages/zict/buffer.py", line 52, in fast_to_slow
    self.slow[key] = value
  File "/glade/u/home/baird/miniconda3/envs/pangeo/lib/python3.7/site-packages/zict/func.py", line 42, in __setitem__
    self.d[key] = self.dump(value)
  File "/glade/u/home/baird/miniconda3/envs/pangeo/lib/python3.7/site-packages/zict/file.py", line 85, in __setitem__
    f.write(value)
OSError: [Errno 28] No space left on device
distributed.worker - INFO - Failed to put key in memory
Traceback (most recent call last):
  File "/glade/u/home/baird/miniconda3/envs/pangeo/lib/python3.7/site-packages/zict/file.py", line 83, in __setitem__
    f.write(v)
OSError: [Errno 28] No space left on device

During handling of the above exception, another exception occurred:

Traceback (most recent call last):
  File "/glade/u/home/baird/miniconda3/envs/pangeo/lib/python3.7/site-packages/distributed/worker.py", line 1356, in transition_executing_done
    self.put_key_in_memory(key, value, transition=False)
  File "/glade/u/home/baird/miniconda3/envs/pangeo/lib/python3.7/site-packages/distributed/worker.py", line 1548, in put_key_in_memory
    self.data[key] = value
  File "/glade/u/home/baird/miniconda3/envs/pangeo/lib/python3.7/site-packages/zict/buffer.py", line 80, in __setitem__
    self.fast[key] = value
  File "/glade/u/home/baird/miniconda3/envs/pangeo/lib/python3.7/site-packages/zict/lru.py", line 71, in __setitem__
    self.evict()
  File "/glade/u/home/baird/miniconda3/envs/pangeo/lib/python3.7/site-packages/zict/lru.py", line 90, in evict
    cb(k, v)
  File "/glade/u/home/baird/miniconda3/envs/pangeo/lib/python3.7/site-packages/zict/buffer.py", line 52, in fast_to_slow
    self.slow[key] = value
  File "/glade/u/home/baird/miniconda3/envs/pangeo/lib/python3.7/site-packages/zict/func.py", line 42, in __setitem__
    self.d[key] = self.dump(value)
  File "/glade/u/home/baird/miniconda3/envs/pangeo/lib/python3.7/site-packages/zict/file.py", line 85, in __setitem__
    f.write(value)
OSError: [Errno 28] No space left on device
distributed.worker - INFO - Failed to put key in memory
Traceback (most recent call last):
  File "/glade/u/home/baird/miniconda3/envs/pangeo/lib/python3.7/site-packages/zict/file.py", line 83, in __setitem__
    f.write(v)
OSError: [Errno 28] No space left on device

During handling of the above exception, another exception occurred:

Traceback (most recent call last):
  File "/glade/u/home/baird/miniconda3/envs/pangeo/lib/python3.7/site-packages/distributed/worker.py", line 1356, in transition_executing_done
    self.put_key_in_memory(key, value, transition=False)
  File "/glade/u/home/baird/miniconda3/envs/pangeo/lib/python3.7/site-packages/distributed/worker.py", line 1548, in put_key_in_memory
    self.data[key] = value
  File "/glade/u/home/baird/miniconda3/envs/pangeo/lib/python3.7/site-packages/zict/buffer.py", line 80, in __setitem__
    self.fast[key] = value
  File "/glade/u/home/baird/miniconda3/envs/pangeo/lib/python3.7/site-packages/zict/lru.py", line 71, in __setitem__
    self.evict()
  File "/glade/u/home/baird/miniconda3/envs/pangeo/lib/python3.7/site-packages/zict/lru.py", line 90, in evict
    cb(k, v)
  File "/glade/u/home/baird/miniconda3/envs/pangeo/lib/python3.7/site-packages/zict/buffer.py", line 52, in fast_to_slow
    self.slow[key] = value
  File "/glade/u/home/baird/miniconda3/envs/pangeo/lib/python3.7/site-packages/zict/func.py", line 42, in __setitem__
    self.d[key] = self.dump(value)
  File "/glade/u/home/baird/miniconda3/envs/pangeo/lib/python3.7/site-packages/zict/file.py", line 85, in __setitem__
    f.write(value)
OSError: [Errno 28] No space left on device
distributed.worker - INFO - Failed to put key in memory
Traceback (most recent call last):
  File "/glade/u/home/baird/miniconda3/envs/pangeo/lib/python3.7/site-packages/zict/file.py", line 83, in __setitem__
    f.write(v)
OSError: [Errno 28] No space left on device

During handling of the above exception, another exception occurred:

Traceback (most recent call last):
  File "/glade/u/home/baird/miniconda3/envs/pangeo/lib/python3.7/site-packages/distributed/worker.py", line 1356, in transition_executing_done
    self.put_key_in_memory(key, value, transition=False)
  File "/glade/u/home/baird/miniconda3/envs/pangeo/lib/python3.7/site-packages/distributed/worker.py", line 1548, in put_key_in_memory
    self.data[key] = value
  File "/glade/u/home/baird/miniconda3/envs/pangeo/lib/python3.7/site-packages/zict/buffer.py", line 80, in __setitem__
    self.fast[key] = value
  File "/glade/u/home/baird/miniconda3/envs/pangeo/lib/python3.7/site-packages/zict/lru.py", line 71, in __setitem__
    self.evict()
  File "/glade/u/home/baird/miniconda3/envs/pangeo/lib/python3.7/site-packages/zict/lru.py", line 90, in evict
    cb(k, v)
  File "/glade/u/home/baird/miniconda3/envs/pangeo/lib/python3.7/site-packages/zict/buffer.py", line 52, in fast_to_slow
    self.slow[key] = value
  File "/glade/u/home/baird/miniconda3/envs/pangeo/lib/python3.7/site-packages/zict/func.py", line 42, in __setitem__
    self.d[key] = self.dump(value)
  File "/glade/u/home/baird/miniconda3/envs/pangeo/lib/python3.7/site-packages/zict/file.py", line 85, in __setitem__
    f.write(value)
OSError: [Errno 28] No space left on device
distributed.worker - INFO - Failed to put key in memory
Traceback (most recent call last):
  File "/glade/u/home/baird/miniconda3/envs/pangeo/lib/python3.7/site-packages/zict/file.py", line 83, in __setitem__
    f.write(v)
OSError: [Errno 28] No space left on device

During handling of the above exception, another exception occurred:

Traceback (most recent call last):
  File "/glade/u/home/baird/miniconda3/envs/pangeo/lib/python3.7/site-packages/distributed/worker.py", line 1356, in transition_executing_done
    self.put_key_in_memory(key, value, transition=False)
  File "/glade/u/home/baird/miniconda3/envs/pangeo/lib/python3.7/site-packages/distributed/worker.py", line 1548, in put_key_in_memory
    self.data[key] = value
  File "/glade/u/home/baird/miniconda3/envs/pangeo/lib/python3.7/site-packages/zict/buffer.py", line 80, in __setitem__
    self.fast[key] = value
  File "/glade/u/home/baird/miniconda3/envs/pangeo/lib/python3.7/site-packages/zict/lru.py", line 71, in __setitem__
    self.evict()
  File "/glade/u/home/baird/miniconda3/envs/pangeo/lib/python3.7/site-packages/zict/lru.py", line 90, in evict
    cb(k, v)
  File "/glade/u/home/baird/miniconda3/envs/pangeo/lib/python3.7/site-packages/zict/buffer.py", line 52, in fast_to_slow
    self.slow[key] = value
  File "/glade/u/home/baird/miniconda3/envs/pangeo/lib/python3.7/site-packages/zict/func.py", line 42, in __setitem__
    self.d[key] = self.dump(value)
  File "/glade/u/home/baird/miniconda3/envs/pangeo/lib/python3.7/site-packages/zict/file.py", line 85, in __setitem__
    f.write(value)
OSError: [Errno 28] No space left on device
distributed.worker - INFO - Failed to put key in memory
Traceback (most recent call last):
  File "/glade/u/home/baird/miniconda3/envs/pangeo/lib/python3.7/site-packages/zict/file.py", line 83, in __setitem__
    f.write(v)
OSError: [Errno 28] No space left on device

During handling of the above exception, another exception occurred:

Traceback (most recent call last):
  File "/glade/u/home/baird/miniconda3/envs/pangeo/lib/python3.7/site-packages/distributed/worker.py", line 1356, in transition_executing_done
    self.put_key_in_memory(key, value, transition=False)
  File "/glade/u/home/baird/miniconda3/envs/pangeo/lib/python3.7/site-packages/distributed/worker.py", line 1548, in put_key_in_memory
    self.data[key] = value
  File "/glade/u/home/baird/miniconda3/envs/pangeo/lib/python3.7/site-packages/zict/buffer.py", line 80, in __setitem__
    self.fast[key] = value
  File "/glade/u/home/baird/miniconda3/envs/pangeo/lib/python3.7/site-packages/zict/lru.py", line 71, in __setitem__
    self.evict()
  File "/glade/u/home/baird/miniconda3/envs/pangeo/lib/python3.7/site-packages/zict/lru.py", line 90, in evict
    cb(k, v)
  File "/glade/u/home/baird/miniconda3/envs/pangeo/lib/python3.7/site-packages/zict/buffer.py", line 52, in fast_to_slow
    self.slow[key] = value
  File "/glade/u/home/baird/miniconda3/envs/pangeo/lib/python3.7/site-packages/zict/func.py", line 42, in __setitem__
    self.d[key] = self.dump(value)
  File "/glade/u/home/baird/miniconda3/envs/pangeo/lib/python3.7/site-packages/zict/file.py", line 85, in __setitem__
    f.write(value)
OSError: [Errno 28] No space left on device
distributed.worker - INFO - Failed to put key in memory
Traceback (most recent call last):
  File "/glade/u/home/baird/miniconda3/envs/pangeo/lib/python3.7/site-packages/zict/file.py", line 83, in __setitem__
    f.write(v)
OSError: [Errno 28] No space left on device

During handling of the above exception, another exception occurred:

Traceback (most recent call last):
  File "/glade/u/home/baird/miniconda3/envs/pangeo/lib/python3.7/site-packages/distributed/worker.py", line 1356, in transition_executing_done
    self.put_key_in_memory(key, value, transition=False)
  File "/glade/u/home/baird/miniconda3/envs/pangeo/lib/python3.7/site-packages/distributed/worker.py", line 1548, in put_key_in_memory
    self.data[key] = value
  File "/glade/u/home/baird/miniconda3/envs/pangeo/lib/python3.7/site-packages/zict/buffer.py", line 80, in __setitem__
    self.fast[key] = value
  File "/glade/u/home/baird/miniconda3/envs/pangeo/lib/python3.7/site-packages/zict/lru.py", line 71, in __setitem__
    self.evict()
  File "/glade/u/home/baird/miniconda3/envs/pangeo/lib/python3.7/site-packages/zict/lru.py", line 90, in evict
    cb(k, v)
  File "/glade/u/home/baird/miniconda3/envs/pangeo/lib/python3.7/site-packages/zict/buffer.py", line 52, in fast_to_slow
    self.slow[key] = value
  File "/glade/u/home/baird/miniconda3/envs/pangeo/lib/python3.7/site-packages/zict/func.py", line 42, in __setitem__
    self.d[key] = self.dump(value)
  File "/glade/u/home/baird/miniconda3/envs/pangeo/lib/python3.7/site-packages/zict/file.py", line 85, in __setitem__
    f.write(value)
OSError: [Errno 28] No space left on device
distributed.worker - ERROR - "('func-overlap-getitem-bb62fae0cdb5f699993015b96324e87e', 16, 7, 6, 0)"
Traceback (most recent call last):
  File "/glade/u/home/baird/miniconda3/envs/pangeo/lib/python3.7/site-packages/distributed/worker.py", line 2053, in execute
    data[k] = self.data[k]
  File "/glade/u/home/baird/miniconda3/envs/pangeo/lib/python3.7/site-packages/zict/buffer.py", line 72, in __getitem__
    raise KeyError(key)
KeyError: "('func-overlap-getitem-bb62fae0cdb5f699993015b96324e87e', 16, 7, 6, 0)"

During handling of the above exception, another exception occurred:

Traceback (most recent call last):
  File "/glade/u/home/baird/miniconda3/envs/pangeo/lib/python3.7/site-packages/distributed/worker.py", line 2056, in execute
    data[k] = Actor(type(self.actors[k]), self.address, k, self)
KeyError: "('func-overlap-getitem-bb62fae0cdb5f699993015b96324e87e', 16, 7, 6, 0)"
distributed.worker - ERROR - "('func-overlap-getitem-bb62fae0cdb5f699993015b96324e87e', 17, 2, 4, 0)"
Traceback (most recent call last):
  File "/glade/u/home/baird/miniconda3/envs/pangeo/lib/python3.7/site-packages/distributed/worker.py", line 2053, in execute
    data[k] = self.data[k]
  File "/glade/u/home/baird/miniconda3/envs/pangeo/lib/python3.7/site-packages/zict/buffer.py", line 72, in __getitem__
    raise KeyError(key)
KeyError: "('func-overlap-getitem-bb62fae0cdb5f699993015b96324e87e', 17, 2, 4, 0)"

During handling of the above exception, another exception occurred:

Traceback (most recent call last):
  File "/glade/u/home/baird/miniconda3/envs/pangeo/lib/python3.7/site-packages/distributed/worker.py", line 2056, in execute
    data[k] = Actor(type(self.actors[k]), self.address, k, self)
KeyError: "('func-overlap-getitem-bb62fae0cdb5f699993015b96324e87e', 17, 2, 4, 0)"
distributed.worker - ERROR - "('func-overlap-getitem-bb62fae0cdb5f699993015b96324e87e', 17, 2, 13, 0)"
Traceback (most recent call last):
  File "/glade/u/home/baird/miniconda3/envs/pangeo/lib/python3.7/site-packages/distributed/worker.py", line 2053, in execute
    data[k] = self.data[k]
  File "/glade/u/home/baird/miniconda3/envs/pangeo/lib/python3.7/site-packages/zict/buffer.py", line 72, in __getitem__
    raise KeyError(key)
KeyError: "('func-overlap-getitem-bb62fae0cdb5f699993015b96324e87e', 17, 2, 13, 0)"

During handling of the above exception, another exception occurred:

Traceback (most recent call last):
  File "/glade/u/home/baird/miniconda3/envs/pangeo/lib/python3.7/site-packages/distributed/worker.py", line 2056, in execute
    data[k] = Actor(type(self.actors[k]), self.address, k, self)
KeyError: "('func-overlap-getitem-bb62fae0cdb5f699993015b96324e87e', 17, 2, 13, 0)"
distributed.core - ERROR - [Errno 28] No space left on device
Traceback (most recent call last):
  File "/glade/u/home/baird/miniconda3/envs/pangeo/lib/python3.7/site-packages/distributed/core.py", line 346, in handle_comm
    result = yield result
  File "/glade/u/home/baird/miniconda3/envs/pangeo/lib/python3.7/site-packages/tornado/gen.py", line 1133, in run
    value = future.result()
  File "/glade/u/home/baird/miniconda3/envs/pangeo/lib/python3.7/site-packages/tornado/gen.py", line 326, in wrapper
    yielded = next(result)
  File "/glade/u/home/baird/miniconda3/envs/pangeo/lib/python3.7/site-packages/distributed/worker.py", line 932, in get_data
    data = {k: self.data[k] for k in keys if k in self.data}
  File "/glade/u/home/baird/miniconda3/envs/pangeo/lib/python3.7/site-packages/distributed/worker.py", line 932, in <dictcomp>
    data = {k: self.data[k] for k in keys if k in self.data}
  File "/glade/u/home/baird/miniconda3/envs/pangeo/lib/python3.7/site-packages/zict/buffer.py", line 70, in __getitem__
    return self.slow_to_fast(key)
  File "/glade/u/home/baird/miniconda3/envs/pangeo/lib/python3.7/site-packages/zict/buffer.py", line 61, in slow_to_fast
    self.fast[key] = value
  File "/glade/u/home/baird/miniconda3/envs/pangeo/lib/python3.7/site-packages/zict/lru.py", line 71, in __setitem__
    self.evict()
  File "/glade/u/home/baird/miniconda3/envs/pangeo/lib/python3.7/site-packages/zict/lru.py", line 90, in evict
    cb(k, v)
  File "/glade/u/home/baird/miniconda3/envs/pangeo/lib/python3.7/site-packages/zict/buffer.py", line 52, in fast_to_slow
    self.slow[key] = value
  File "/glade/u/home/baird/miniconda3/envs/pangeo/lib/python3.7/site-packages/zict/func.py", line 42, in __setitem__
    self.d[key] = self.dump(value)
  File "/glade/u/home/baird/miniconda3/envs/pangeo/lib/python3.7/site-packages/zict/file.py", line 83, in __setitem__
    f.write(v)
OSError: [Errno 28] No space left on device
distributed.core - INFO - Event loop was unresponsive in Worker for 3.23s.  This is often caused by long-running GIL-holding functions or moving large chunks of data. This can cause timeouts and instability.
tornado.application - ERROR - Exception in callback functools.partial(<function wrap.<locals>.null_wrapper at 0x2aab6e4cb7b8>, <Future finished exception=KeyError("('func-overlap-getitem-bb62fae0cdb5f699993015b96324e87e', 16, 7, 6, 0)")>)
Traceback (most recent call last):
  File "/glade/u/home/baird/miniconda3/envs/pangeo/lib/python3.7/site-packages/distributed/worker.py", line 2053, in execute
    data[k] = self.data[k]
  File "/glade/u/home/baird/miniconda3/envs/pangeo/lib/python3.7/site-packages/zict/buffer.py", line 72, in __getitem__
    raise KeyError(key)
KeyError: "('func-overlap-getitem-bb62fae0cdb5f699993015b96324e87e', 16, 7, 6, 0)"

During handling of the above exception, another exception occurred:

Traceback (most recent call last):
  File "/glade/u/home/baird/miniconda3/envs/pangeo/lib/python3.7/site-packages/tornado/ioloop.py", line 758, in _run_callback
    ret = callback()
  File "/glade/u/home/baird/miniconda3/envs/pangeo/lib/python3.7/site-packages/tornado/stack_context.py", line 300, in null_wrapper
    return fn(*args, **kwargs)
  File "/glade/u/home/baird/miniconda3/envs/pangeo/lib/python3.7/site-packages/tornado/ioloop.py", line 779, in _discard_future_result
    future.result()
  File "/glade/u/home/baird/miniconda3/envs/pangeo/lib/python3.7/site-packages/tornado/gen.py", line 326, in wrapper
    yielded = next(result)
  File "/glade/u/home/baird/miniconda3/envs/pangeo/lib/python3.7/site-packages/distributed/worker.py", line 2056, in execute
    data[k] = Actor(type(self.actors[k]), self.address, k, self)
KeyError: "('func-overlap-getitem-bb62fae0cdb5f699993015b96324e87e', 16, 7, 6, 0)"
tornado.application - ERROR - Exception in callback functools.partial(<function wrap.<locals>.null_wrapper at 0x2aab8195e7b8>, <Future finished exception=KeyError("('func-overlap-getitem-bb62fae0cdb5f699993015b96324e87e', 17, 2, 4, 0)")>)
Traceback (most recent call last):
  File "/glade/u/home/baird/miniconda3/envs/pangeo/lib/python3.7/site-packages/distributed/worker.py", line 2053, in execute
    data[k] = self.data[k]
  File "/glade/u/home/baird/miniconda3/envs/pangeo/lib/python3.7/site-packages/zict/buffer.py", line 72, in __getitem__
    raise KeyError(key)
KeyError: "('func-overlap-getitem-bb62fae0cdb5f699993015b96324e87e', 17, 2, 4, 0)"

During handling of the above exception, another exception occurred:

Traceback (most recent call last):
  File "/glade/u/home/baird/miniconda3/envs/pangeo/lib/python3.7/site-packages/tornado/ioloop.py", line 758, in _run_callback
    ret = callback()
  File "/glade/u/home/baird/miniconda3/envs/pangeo/lib/python3.7/site-packages/tornado/stack_context.py", line 300, in null_wrapper
    return fn(*args, **kwargs)
  File "/glade/u/home/baird/miniconda3/envs/pangeo/lib/python3.7/site-packages/tornado/ioloop.py", line 779, in _discard_future_result
    future.result()
  File "/glade/u/home/baird/miniconda3/envs/pangeo/lib/python3.7/site-packages/tornado/gen.py", line 326, in wrapper
    yielded = next(result)
  File "/glade/u/home/baird/miniconda3/envs/pangeo/lib/python3.7/site-packages/distributed/worker.py", line 2056, in execute
    data[k] = Actor(type(self.actors[k]), self.address, k, self)
KeyError: "('func-overlap-getitem-bb62fae0cdb5f699993015b96324e87e', 17, 2, 4, 0)"
tornado.application - ERROR - Exception in callback functools.partial(<function wrap.<locals>.null_wrapper at 0x2aab8195e268>, <Future finished exception=KeyError("('func-overlap-getitem-bb62fae0cdb5f699993015b96324e87e', 17, 2, 13, 0)")>)
Traceback (most recent call last):
  File "/glade/u/home/baird/miniconda3/envs/pangeo/lib/python3.7/site-packages/distributed/worker.py", line 2053, in execute
    data[k] = self.data[k]
  File "/glade/u/home/baird/miniconda3/envs/pangeo/lib/python3.7/site-packages/zict/buffer.py", line 72, in __getitem__
    raise KeyError(key)
KeyError: "('func-overlap-getitem-bb62fae0cdb5f699993015b96324e87e', 17, 2, 13, 0)"

During handling of the above exception, another exception occurred:

Traceback (most recent call last):
  File "/glade/u/home/baird/miniconda3/envs/pangeo/lib/python3.7/site-packages/tornado/ioloop.py", line 758, in _run_callback
    ret = callback()
  File "/glade/u/home/baird/miniconda3/envs/pangeo/lib/python3.7/site-packages/tornado/stack_context.py", line 300, in null_wrapper
    return fn(*args, **kwargs)
  File "/glade/u/home/baird/miniconda3/envs/pangeo/lib/python3.7/site-packages/tornado/ioloop.py", line 779, in _discard_future_result
    future.result()
  File "/glade/u/home/baird/miniconda3/envs/pangeo/lib/python3.7/site-packages/tornado/gen.py", line 326, in wrapper
    yielded = next(result)
  File "/glade/u/home/baird/miniconda3/envs/pangeo/lib/python3.7/site-packages/distributed/worker.py", line 2056, in execute
    data[k] = Actor(type(self.actors[k]), self.address, k, self)
KeyError: "('func-overlap-getitem-bb62fae0cdb5f699993015b96324e87e', 17, 2, 13, 0)"
distributed.worker - INFO - Failed to put key in memory
Traceback (most recent call last):
  File "/glade/u/home/baird/miniconda3/envs/pangeo/lib/python3.7/site-packages/zict/file.py", line 83, in __setitem__
    f.write(v)
OSError: [Errno 28] No space left on device

During handling of the above exception, another exception occurred:

Traceback (most recent call last):
  File "/glade/u/home/baird/miniconda3/envs/pangeo/lib/python3.7/site-packages/distributed/worker.py", line 1356, in transition_executing_done
    self.put_key_in_memory(key, value, transition=False)
  File "/glade/u/home/baird/miniconda3/envs/pangeo/lib/python3.7/site-packages/distributed/worker.py", line 1548, in put_key_in_memory
    self.data[key] = value
  File "/glade/u/home/baird/miniconda3/envs/pangeo/lib/python3.7/site-packages/zict/buffer.py", line 80, in __setitem__
    self.fast[key] = value
  File "/glade/u/home/baird/miniconda3/envs/pangeo/lib/python3.7/site-packages/zict/lru.py", line 71, in __setitem__
    self.evict()
  File "/glade/u/home/baird/miniconda3/envs/pangeo/lib/python3.7/site-packages/zict/lru.py", line 90, in evict
    cb(k, v)
  File "/glade/u/home/baird/miniconda3/envs/pangeo/lib/python3.7/site-packages/zict/buffer.py", line 52, in fast_to_slow
    self.slow[key] = value
  File "/glade/u/home/baird/miniconda3/envs/pangeo/lib/python3.7/site-packages/zict/func.py", line 42, in __setitem__
    self.d[key] = self.dump(value)
  File "/glade/u/home/baird/miniconda3/envs/pangeo/lib/python3.7/site-packages/zict/file.py", line 85, in __setitem__
    f.write(value)
OSError: [Errno 28] No space left on device
distributed.worker - ERROR - "('concatenate-d2fe6d71716384862735cab74de7be2d', 2, 6, 15)"
Traceback (most recent call last):
  File "/glade/u/home/baird/miniconda3/envs/pangeo/lib/python3.7/site-packages/distributed/worker.py", line 2053, in execute
    data[k] = self.data[k]
  File "/glade/u/home/baird/miniconda3/envs/pangeo/lib/python3.7/site-packages/zict/buffer.py", line 72, in __getitem__
    raise KeyError(key)
KeyError: "('concatenate-d2fe6d71716384862735cab74de7be2d', 2, 6, 15)"

During handling of the above exception, another exception occurred:

Traceback (most recent call last):
  File "/glade/u/home/baird/miniconda3/envs/pangeo/lib/python3.7/site-packages/distributed/worker.py", line 2056, in execute
    data[k] = Actor(type(self.actors[k]), self.address, k, self)
KeyError: "('concatenate-d2fe6d71716384862735cab74de7be2d', 2, 6, 15)"
distributed.worker - ERROR - "('concatenate-d2fe6d71716384862735cab74de7be2d', 5, 5, 1)"
Traceback (most recent call last):
  File "/glade/u/home/baird/miniconda3/envs/pangeo/lib/python3.7/site-packages/distributed/worker.py", line 2053, in execute
    data[k] = self.data[k]
  File "/glade/u/home/baird/miniconda3/envs/pangeo/lib/python3.7/site-packages/zict/buffer.py", line 72, in __getitem__
    raise KeyError(key)
KeyError: "('concatenate-d2fe6d71716384862735cab74de7be2d', 5, 5, 1)"

During handling of the above exception, another exception occurred:

Traceback (most recent call last):
  File "/glade/u/home/baird/miniconda3/envs/pangeo/lib/python3.7/site-packages/distributed/worker.py", line 2056, in execute
    data[k] = Actor(type(self.actors[k]), self.address, k, self)
KeyError: "('concatenate-d2fe6d71716384862735cab74de7be2d', 5, 5, 1)"
distributed.worker - ERROR - "('concatenate-d2fe6d71716384862735cab74de7be2d', 13, 4, 7)"
Traceback (most recent call last):
  File "/glade/u/home/baird/miniconda3/envs/pangeo/lib/python3.7/site-packages/distributed/worker.py", line 2053, in execute
    data[k] = self.data[k]
  File "/glade/u/home/baird/miniconda3/envs/pangeo/lib/python3.7/site-packages/zict/buffer.py", line 72, in __getitem__
    raise KeyError(key)
KeyError: "('concatenate-d2fe6d71716384862735cab74de7be2d', 13, 4, 7)"

During handling of the above exception, another exception occurred:

Traceback (most recent call last):
  File "/glade/u/home/baird/miniconda3/envs/pangeo/lib/python3.7/site-packages/distributed/worker.py", line 2056, in execute
    data[k] = Actor(type(self.actors[k]), self.address, k, self)
KeyError: "('concatenate-d2fe6d71716384862735cab74de7be2d', 13, 4, 7)"
distributed.worker - ERROR - "('concatenate-d2fe6d71716384862735cab74de7be2d', 14, 4, 6)"
Traceback (most recent call last):
  File "/glade/u/home/baird/miniconda3/envs/pangeo/lib/python3.7/site-packages/distributed/worker.py", line 2053, in execute
    data[k] = self.data[k]
  File "/glade/u/home/baird/miniconda3/envs/pangeo/lib/python3.7/site-packages/zict/buffer.py", line 72, in __getitem__
    raise KeyError(key)
KeyError: "('concatenate-d2fe6d71716384862735cab74de7be2d', 14, 4, 6)"

During handling of the above exception, another exception occurred:

Traceback (most recent call last):
  File "/glade/u/home/baird/miniconda3/envs/pangeo/lib/python3.7/site-packages/distributed/worker.py", line 2056, in execute
    data[k] = Actor(type(self.actors[k]), self.address, k, self)
KeyError: "('concatenate-d2fe6d71716384862735cab74de7be2d', 14, 4, 6)"
tornado.application - ERROR - Exception in callback functools.partial(<function wrap.<locals>.null_wrapper at 0x2aaabdf8e378>, <Future finished exception=KeyError("('concatenate-d2fe6d71716384862735cab74de7be2d', 2, 6, 15)")>)
Traceback (most recent call last):
  File "/glade/u/home/baird/miniconda3/envs/pangeo/lib/python3.7/site-packages/distributed/worker.py", line 2053, in execute
    data[k] = self.data[k]
  File "/glade/u/home/baird/miniconda3/envs/pangeo/lib/python3.7/site-packages/zict/buffer.py", line 72, in __getitem__
    raise KeyError(key)
KeyError: "('concatenate-d2fe6d71716384862735cab74de7be2d', 2, 6, 15)"

During handling of the above exception, another exception occurred:

Traceback (most recent call last):
  File "/glade/u/home/baird/miniconda3/envs/pangeo/lib/python3.7/site-packages/tornado/ioloop.py", line 758, in _run_callback
    ret = callback()
  File "/glade/u/home/baird/miniconda3/envs/pangeo/lib/python3.7/site-packages/tornado/stack_context.py", line 300, in null_wrapper
    return fn(*args, **kwargs)
  File "/glade/u/home/baird/miniconda3/envs/pangeo/lib/python3.7/site-packages/tornado/ioloop.py", line 779, in _discard_future_result
    future.result()
  File "/glade/u/home/baird/miniconda3/envs/pangeo/lib/python3.7/site-packages/tornado/gen.py", line 326, in wrapper
    yielded = next(result)
  File "/glade/u/home/baird/miniconda3/envs/pangeo/lib/python3.7/site-packages/distributed/worker.py", line 2056, in execute
    data[k] = Actor(type(self.actors[k]), self.address, k, self)
KeyError: "('concatenate-d2fe6d71716384862735cab74de7be2d', 2, 6, 15)"
tornado.application - ERROR - Exception in callback functools.partial(<function wrap.<locals>.null_wrapper at 0x2aab83c4de18>, <Future finished exception=KeyError("('concatenate-d2fe6d71716384862735cab74de7be2d', 5, 5, 1)")>)
Traceback (most recent call last):
  File "/glade/u/home/baird/miniconda3/envs/pangeo/lib/python3.7/site-packages/distributed/worker.py", line 2053, in execute
    data[k] = self.data[k]
  File "/glade/u/home/baird/miniconda3/envs/pangeo/lib/python3.7/site-packages/zict/buffer.py", line 72, in __getitem__
    raise KeyError(key)
KeyError: "('concatenate-d2fe6d71716384862735cab74de7be2d', 5, 5, 1)"

During handling of the above exception, another exception occurred:

Traceback (most recent call last):
  File "/glade/u/home/baird/miniconda3/envs/pangeo/lib/python3.7/site-packages/tornado/ioloop.py", line 758, in _run_callback
    ret = callback()
  File "/glade/u/home/baird/miniconda3/envs/pangeo/lib/python3.7/site-packages/tornado/stack_context.py", line 300, in null_wrapper
    return fn(*args, **kwargs)
  File "/glade/u/home/baird/miniconda3/envs/pangeo/lib/python3.7/site-packages/tornado/ioloop.py", line 779, in _discard_future_result
    future.result()
  File "/glade/u/home/baird/miniconda3/envs/pangeo/lib/python3.7/site-packages/tornado/gen.py", line 326, in wrapper
    yielded = next(result)
  File "/glade/u/home/baird/miniconda3/envs/pangeo/lib/python3.7/site-packages/distributed/worker.py", line 2056, in execute
    data[k] = Actor(type(self.actors[k]), self.address, k, self)
KeyError: "('concatenate-d2fe6d71716384862735cab74de7be2d', 5, 5, 1)"
tornado.application - ERROR - Exception in callback functools.partial(<function wrap.<locals>.null_wrapper at 0x2aab83c4dea0>, <Future finished exception=KeyError("('concatenate-d2fe6d71716384862735cab74de7be2d', 13, 4, 7)")>)
Traceback (most recent call last):
  File "/glade/u/home/baird/miniconda3/envs/pangeo/lib/python3.7/site-packages/distributed/worker.py", line 2053, in execute
    data[k] = self.data[k]
  File "/glade/u/home/baird/miniconda3/envs/pangeo/lib/python3.7/site-packages/zict/buffer.py", line 72, in __getitem__
    raise KeyError(key)
KeyError: "('concatenate-d2fe6d71716384862735cab74de7be2d', 13, 4, 7)"

During handling of the above exception, another exception occurred:

Traceback (most recent call last):
  File "/glade/u/home/baird/miniconda3/envs/pangeo/lib/python3.7/site-packages/tornado/ioloop.py", line 758, in _run_callback
    ret = callback()
  File "/glade/u/home/baird/miniconda3/envs/pangeo/lib/python3.7/site-packages/tornado/stack_context.py", line 300, in null_wrapper
    return fn(*args, **kwargs)
  File "/glade/u/home/baird/miniconda3/envs/pangeo/lib/python3.7/site-packages/tornado/ioloop.py", line 779, in _discard_future_result
    future.result()
  File "/glade/u/home/baird/miniconda3/envs/pangeo/lib/python3.7/site-packages/tornado/gen.py", line 326, in wrapper
    yielded = next(result)
  File "/glade/u/home/baird/miniconda3/envs/pangeo/lib/python3.7/site-packages/distributed/worker.py", line 2056, in execute
    data[k] = Actor(type(self.actors[k]), self.address, k, self)
KeyError: "('concatenate-d2fe6d71716384862735cab74de7be2d', 13, 4, 7)"
tornado.application - ERROR - Exception in callback functools.partial(<function wrap.<locals>.null_wrapper at 0x2aab83c4df28>, <Future finished exception=KeyError("('concatenate-d2fe6d71716384862735cab74de7be2d', 14, 4, 6)")>)
Traceback (most recent call last):
  File "/glade/u/home/baird/miniconda3/envs/pangeo/lib/python3.7/site-packages/distributed/worker.py", line 2053, in execute
    data[k] = self.data[k]
  File "/glade/u/home/baird/miniconda3/envs/pangeo/lib/python3.7/site-packages/zict/buffer.py", line 72, in __getitem__
    raise KeyError(key)
KeyError: "('concatenate-d2fe6d71716384862735cab74de7be2d', 14, 4, 6)"

During handling of the above exception, another exception occurred:

Traceback (most recent call last):
  File "/glade/u/home/baird/miniconda3/envs/pangeo/lib/python3.7/site-packages/tornado/ioloop.py", line 758, in _run_callback
    ret = callback()
  File "/glade/u/home/baird/miniconda3/envs/pangeo/lib/python3.7/site-packages/tornado/stack_context.py", line 300, in null_wrapper
    return fn(*args, **kwargs)
  File "/glade/u/home/baird/miniconda3/envs/pangeo/lib/python3.7/site-packages/tornado/ioloop.py", line 779, in _discard_future_result
    future.result()
  File "/glade/u/home/baird/miniconda3/envs/pangeo/lib/python3.7/site-packages/tornado/gen.py", line 326, in wrapper
    yielded = next(result)
  File "/glade/u/home/baird/miniconda3/envs/pangeo/lib/python3.7/site-packages/distributed/worker.py", line 2056, in execute
    data[k] = Actor(type(self.actors[k]), self.address, k, self)
KeyError: "('concatenate-d2fe6d71716384862735cab74de7be2d', 14, 4, 6)"
distributed.worker - INFO - Failed to put key in memory
Traceback (most recent call last):
  File "/glade/u/home/baird/miniconda3/envs/pangeo/lib/python3.7/site-packages/distributed/worker.py", line 1356, in transition_executing_done
    self.put_key_in_memory(key, value, transition=False)
  File "/glade/u/home/baird/miniconda3/envs/pangeo/lib/python3.7/site-packages/distributed/worker.py", line 1548, in put_key_in_memory
    self.data[key] = value
  File "/glade/u/home/baird/miniconda3/envs/pangeo/lib/python3.7/site-packages/zict/buffer.py", line 80, in __setitem__
    self.fast[key] = value
  File "/glade/u/home/baird/miniconda3/envs/pangeo/lib/python3.7/site-packages/zict/lru.py", line 71, in __setitem__
    self.evict()
  File "/glade/u/home/baird/miniconda3/envs/pangeo/lib/python3.7/site-packages/zict/lru.py", line 90, in evict
    cb(k, v)
  File "/glade/u/home/baird/miniconda3/envs/pangeo/lib/python3.7/site-packages/zict/buffer.py", line 52, in fast_to_slow
    self.slow[key] = value
  File "/glade/u/home/baird/miniconda3/envs/pangeo/lib/python3.7/site-packages/zict/func.py", line 42, in __setitem__
    self.d[key] = self.dump(value)
  File "/glade/u/home/baird/miniconda3/envs/pangeo/lib/python3.7/site-packages/zict/file.py", line 83, in __setitem__
    f.write(v)
OSError: [Errno 28] No space left on device
distributed.worker - INFO - Failed to put key in memory
Traceback (most recent call last):
  File "/glade/u/home/baird/miniconda3/envs/pangeo/lib/python3.7/site-packages/zict/file.py", line 83, in __setitem__
    f.write(v)
OSError: [Errno 28] No space left on device

During handling of the above exception, another exception occurred:

Traceback (most recent call last):
  File "/glade/u/home/baird/miniconda3/envs/pangeo/lib/python3.7/site-packages/distributed/worker.py", line 1356, in transition_executing_done
    self.put_key_in_memory(key, value, transition=False)
  File "/glade/u/home/baird/miniconda3/envs/pangeo/lib/python3.7/site-packages/distributed/worker.py", line 1548, in put_key_in_memory
    self.data[key] = value
  File "/glade/u/home/baird/miniconda3/envs/pangeo/lib/python3.7/site-packages/zict/buffer.py", line 80, in __setitem__
    self.fast[key] = value
  File "/glade/u/home/baird/miniconda3/envs/pangeo/lib/python3.7/site-packages/zict/lru.py", line 71, in __setitem__
    self.evict()
  File "/glade/u/home/baird/miniconda3/envs/pangeo/lib/python3.7/site-packages/zict/lru.py", line 90, in evict
    cb(k, v)
  File "/glade/u/home/baird/miniconda3/envs/pangeo/lib/python3.7/site-packages/zict/buffer.py", line 52, in fast_to_slow
    self.slow[key] = value
  File "/glade/u/home/baird/miniconda3/envs/pangeo/lib/python3.7/site-packages/zict/func.py", line 42, in __setitem__
    self.d[key] = self.dump(value)
  File "/glade/u/home/baird/miniconda3/envs/pangeo/lib/python3.7/site-packages/zict/file.py", line 85, in __setitem__
    f.write(value)
OSError: [Errno 28] No space left on device
distributed.worker - INFO - Failed to put key in memory
Traceback (most recent call last):
  File "/glade/u/home/baird/miniconda3/envs/pangeo/lib/python3.7/site-packages/zict/file.py", line 83, in __setitem__
    f.write(v)
OSError: [Errno 28] No space left on device

During handling of the above exception, another exception occurred:

Traceback (most recent call last):
  File "/glade/u/home/baird/miniconda3/envs/pangeo/lib/python3.7/site-packages/distributed/worker.py", line 1356, in transition_executing_done
    self.put_key_in_memory(key, value, transition=False)
  File "/glade/u/home/baird/miniconda3/envs/pangeo/lib/python3.7/site-packages/distributed/worker.py", line 1548, in put_key_in_memory
    self.data[key] = value
  File "/glade/u/home/baird/miniconda3/envs/pangeo/lib/python3.7/site-packages/zict/buffer.py", line 80, in __setitem__
    self.fast[key] = value
  File "/glade/u/home/baird/miniconda3/envs/pangeo/lib/python3.7/site-packages/zict/lru.py", line 71, in __setitem__
    self.evict()
  File "/glade/u/home/baird/miniconda3/envs/pangeo/lib/python3.7/site-packages/zict/lru.py", line 90, in evict
    cb(k, v)
  File "/glade/u/home/baird/miniconda3/envs/pangeo/lib/python3.7/site-packages/zict/buffer.py", line 52, in fast_to_slow
    self.slow[key] = value
  File "/glade/u/home/baird/miniconda3/envs/pangeo/lib/python3.7/site-packages/zict/func.py", line 42, in __setitem__
    self.d[key] = self.dump(value)
  File "/glade/u/home/baird/miniconda3/envs/pangeo/lib/python3.7/site-packages/zict/file.py", line 85, in __setitem__
    f.write(value)
OSError: [Errno 28] No space left on device
distributed.worker - INFO - Failed to put key in memory
Traceback (most recent call last):
  File "/glade/u/home/baird/miniconda3/envs/pangeo/lib/python3.7/site-packages/zict/file.py", line 83, in __setitem__
    f.write(v)
OSError: [Errno 28] No space left on device

During handling of the above exception, another exception occurred:

Traceback (most recent call last):
  File "/glade/u/home/baird/miniconda3/envs/pangeo/lib/python3.7/site-packages/distributed/worker.py", line 1356, in transition_executing_done
    self.put_key_in_memory(key, value, transition=False)
  File "/glade/u/home/baird/miniconda3/envs/pangeo/lib/python3.7/site-packages/distributed/worker.py", line 1548, in put_key_in_memory
    self.data[key] = value
  File "/glade/u/home/baird/miniconda3/envs/pangeo/lib/python3.7/site-packages/zict/buffer.py", line 80, in __setitem__
    self.fast[key] = value
  File "/glade/u/home/baird/miniconda3/envs/pangeo/lib/python3.7/site-packages/zict/lru.py", line 71, in __setitem__
    self.evict()
  File "/glade/u/home/baird/miniconda3/envs/pangeo/lib/python3.7/site-packages/zict/lru.py", line 90, in evict
    cb(k, v)
  File "/glade/u/home/baird/miniconda3/envs/pangeo/lib/python3.7/site-packages/zict/buffer.py", line 52, in fast_to_slow
    self.slow[key] = value
  File "/glade/u/home/baird/miniconda3/envs/pangeo/lib/python3.7/site-packages/zict/func.py", line 42, in __setitem__
    self.d[key] = self.dump(value)
  File "/glade/u/home/baird/miniconda3/envs/pangeo/lib/python3.7/site-packages/zict/file.py", line 85, in __setitem__
    f.write(value)
OSError: [Errno 28] No space left on device
distributed.worker - INFO - Failed to put key in memory
Traceback (most recent call last):
  File "/glade/u/home/baird/miniconda3/envs/pangeo/lib/python3.7/site-packages/zict/file.py", line 83, in __setitem__
    f.write(v)
OSError: [Errno 28] No space left on device

During handling of the above exception, another exception occurred:

Traceback (most recent call last):
  File "/glade/u/home/baird/miniconda3/envs/pangeo/lib/python3.7/site-packages/distributed/worker.py", line 1356, in transition_executing_done
    self.put_key_in_memory(key, value, transition=False)
  File "/glade/u/home/baird/miniconda3/envs/pangeo/lib/python3.7/site-packages/distributed/worker.py", line 1548, in put_key_in_memory
    self.data[key] = value
  File "/glade/u/home/baird/miniconda3/envs/pangeo/lib/python3.7/site-packages/zict/buffer.py", line 80, in __setitem__
    self.fast[key] = value
  File "/glade/u/home/baird/miniconda3/envs/pangeo/lib/python3.7/site-packages/zict/lru.py", line 71, in __setitem__
    self.evict()
  File "/glade/u/home/baird/miniconda3/envs/pangeo/lib/python3.7/site-packages/zict/lru.py", line 90, in evict
    cb(k, v)
  File "/glade/u/home/baird/miniconda3/envs/pangeo/lib/python3.7/site-packages/zict/buffer.py", line 52, in fast_to_slow
    self.slow[key] = value
  File "/glade/u/home/baird/miniconda3/envs/pangeo/lib/python3.7/site-packages/zict/func.py", line 42, in __setitem__
    self.d[key] = self.dump(value)
  File "/glade/u/home/baird/miniconda3/envs/pangeo/lib/python3.7/site-packages/zict/file.py", line 85, in __setitem__
    f.write(value)
OSError: [Errno 28] No space left on device
distributed.worker - ERROR - "('concatenate-d2fe6d71716384862735cab74de7be2d', 4, 5, 15)"
Traceback (most recent call last):
  File "/glade/u/home/baird/miniconda3/envs/pangeo/lib/python3.7/site-packages/distributed/worker.py", line 2053, in execute
    data[k] = self.data[k]
  File "/glade/u/home/baird/miniconda3/envs/pangeo/lib/python3.7/site-packages/zict/buffer.py", line 72, in __getitem__
    raise KeyError(key)
KeyError: "('concatenate-d2fe6d71716384862735cab74de7be2d', 4, 5, 15)"

During handling of the above exception, another exception occurred:

Traceback (most recent call last):
  File "/glade/u/home/baird/miniconda3/envs/pangeo/lib/python3.7/site-packages/distributed/worker.py", line 2056, in execute
    data[k] = Actor(type(self.actors[k]), self.address, k, self)
KeyError: "('concatenate-d2fe6d71716384862735cab74de7be2d', 4, 5, 15)"
tornado.application - ERROR - Exception in callback functools.partial(<function wrap.<locals>.null_wrapper at 0x2aaabdf8ea60>, <Future finished exception=KeyError("('concatenate-d2fe6d71716384862735cab74de7be2d', 4, 5, 15)")>)
Traceback (most recent call last):
  File "/glade/u/home/baird/miniconda3/envs/pangeo/lib/python3.7/site-packages/distributed/worker.py", line 2053, in execute
    data[k] = self.data[k]
  File "/glade/u/home/baird/miniconda3/envs/pangeo/lib/python3.7/site-packages/zict/buffer.py", line 72, in __getitem__
    raise KeyError(key)
KeyError: "('concatenate-d2fe6d71716384862735cab74de7be2d', 4, 5, 15)"

During handling of the above exception, another exception occurred:

Traceback (most recent call last):
  File "/glade/u/home/baird/miniconda3/envs/pangeo/lib/python3.7/site-packages/tornado/ioloop.py", line 758, in _run_callback
    ret = callback()
  File "/glade/u/home/baird/miniconda3/envs/pangeo/lib/python3.7/site-packages/tornado/stack_context.py", line 300, in null_wrapper
    return fn(*args, **kwargs)
  File "/glade/u/home/baird/miniconda3/envs/pangeo/lib/python3.7/site-packages/tornado/ioloop.py", line 779, in _discard_future_result
    future.result()
  File "/glade/u/home/baird/miniconda3/envs/pangeo/lib/python3.7/site-packages/tornado/gen.py", line 326, in wrapper
    yielded = next(result)
  File "/glade/u/home/baird/miniconda3/envs/pangeo/lib/python3.7/site-packages/distributed/worker.py", line 2056, in execute
    data[k] = Actor(type(self.actors[k]), self.address, k, self)
KeyError: "('concatenate-d2fe6d71716384862735cab74de7be2d', 4, 5, 15)"
distributed.worker - ERROR - "('concatenate-d2fe6d71716384862735cab74de7be2d', 9, 7, 7)"
Traceback (most recent call last):
  File "/glade/u/home/baird/miniconda3/envs/pangeo/lib/python3.7/site-packages/distributed/worker.py", line 2053, in execute
    data[k] = self.data[k]
  File "/glade/u/home/baird/miniconda3/envs/pangeo/lib/python3.7/site-packages/zict/buffer.py", line 72, in __getitem__
    raise KeyError(key)
KeyError: "('concatenate-d2fe6d71716384862735cab74de7be2d', 9, 7, 7)"

During handling of the above exception, another exception occurred:

Traceback (most recent call last):
  File "/glade/u/home/baird/miniconda3/envs/pangeo/lib/python3.7/site-packages/distributed/worker.py", line 2056, in execute
    data[k] = Actor(type(self.actors[k]), self.address, k, self)
KeyError: "('concatenate-d2fe6d71716384862735cab74de7be2d', 9, 7, 7)"
tornado.application - ERROR - Exception in callback functools.partial(<function wrap.<locals>.null_wrapper at 0x2aaabffa5158>, <Future finished exception=KeyError("('concatenate-d2fe6d71716384862735cab74de7be2d', 9, 7, 7)")>)
Traceback (most recent call last):
  File "/glade/u/home/baird/miniconda3/envs/pangeo/lib/python3.7/site-packages/distributed/worker.py", line 2053, in execute
    data[k] = self.data[k]
  File "/glade/u/home/baird/miniconda3/envs/pangeo/lib/python3.7/site-packages/zict/buffer.py", line 72, in __getitem__
    raise KeyError(key)
KeyError: "('concatenate-d2fe6d71716384862735cab74de7be2d', 9, 7, 7)"

During handling of the above exception, another exception occurred:

Traceback (most recent call last):
  File "/glade/u/home/baird/miniconda3/envs/pangeo/lib/python3.7/site-packages/tornado/ioloop.py", line 758, in _run_callback
    ret = callback()
  File "/glade/u/home/baird/miniconda3/envs/pangeo/lib/python3.7/site-packages/tornado/stack_context.py", line 300, in null_wrapper
    return fn(*args, **kwargs)
  File "/glade/u/home/baird/miniconda3/envs/pangeo/lib/python3.7/site-packages/tornado/ioloop.py", line 779, in _discard_future_result
    future.result()
  File "/glade/u/home/baird/miniconda3/envs/pangeo/lib/python3.7/site-packages/tornado/gen.py", line 326, in wrapper
    yielded = next(result)
  File "/glade/u/home/baird/miniconda3/envs/pangeo/lib/python3.7/site-packages/distributed/worker.py", line 2056, in execute
    data[k] = Actor(type(self.actors[k]), self.address, k, self)
KeyError: "('concatenate-d2fe6d71716384862735cab74de7be2d', 9, 7, 7)"
distributed.worker - ERROR - "('concatenate-d2fe6d71716384862735cab74de7be2d', 2, 3, 3)"
Traceback (most recent call last):
  File "/glade/u/home/baird/miniconda3/envs/pangeo/lib/python3.7/site-packages/distributed/worker.py", line 2053, in execute
    data[k] = self.data[k]
  File "/glade/u/home/baird/miniconda3/envs/pangeo/lib/python3.7/site-packages/zict/buffer.py", line 72, in __getitem__
    raise KeyError(key)
KeyError: "('concatenate-d2fe6d71716384862735cab74de7be2d', 2, 3, 3)"

During handling of the above exception, another exception occurred:

Traceback (most recent call last):
  File "/glade/u/home/baird/miniconda3/envs/pangeo/lib/python3.7/site-packages/distributed/worker.py", line 2056, in execute
    data[k] = Actor(type(self.actors[k]), self.address, k, self)
KeyError: "('concatenate-d2fe6d71716384862735cab74de7be2d', 2, 3, 3)"
distributed.worker - ERROR - "('concatenate-d2fe6d71716384862735cab74de7be2d', 12, 6, 2)"
Traceback (most recent call last):
  File "/glade/u/home/baird/miniconda3/envs/pangeo/lib/python3.7/site-packages/distributed/worker.py", line 2053, in execute
    data[k] = self.data[k]
  File "/glade/u/home/baird/miniconda3/envs/pangeo/lib/python3.7/site-packages/zict/buffer.py", line 72, in __getitem__
    raise KeyError(key)
KeyError: "('concatenate-d2fe6d71716384862735cab74de7be2d', 12, 6, 2)"

During handling of the above exception, another exception occurred:

Traceback (most recent call last):
  File "/glade/u/home/baird/miniconda3/envs/pangeo/lib/python3.7/site-packages/distributed/worker.py", line 2056, in execute
    data[k] = Actor(type(self.actors[k]), self.address, k, self)
KeyError: "('concatenate-d2fe6d71716384862735cab74de7be2d', 12, 6, 2)"
tornado.application - ERROR - Exception in callback functools.partial(<function wrap.<locals>.null_wrapper at 0x2aaaadf00400>, <Future finished exception=KeyError("('concatenate-d2fe6d71716384862735cab74de7be2d', 2, 3, 3)")>)
Traceback (most recent call last):
  File "/glade/u/home/baird/miniconda3/envs/pangeo/lib/python3.7/site-packages/distributed/worker.py", line 2053, in execute
    data[k] = self.data[k]
  File "/glade/u/home/baird/miniconda3/envs/pangeo/lib/python3.7/site-packages/zict/buffer.py", line 72, in __getitem__
    raise KeyError(key)
KeyError: "('concatenate-d2fe6d71716384862735cab74de7be2d', 2, 3, 3)"

During handling of the above exception, another exception occurred:

Traceback (most recent call last):
  File "/glade/u/home/baird/miniconda3/envs/pangeo/lib/python3.7/site-packages/tornado/ioloop.py", line 758, in _run_callback
    ret = callback()
  File "/glade/u/home/baird/miniconda3/envs/pangeo/lib/python3.7/site-packages/tornado/stack_context.py", line 300, in null_wrapper
    return fn(*args, **kwargs)
  File "/glade/u/home/baird/miniconda3/envs/pangeo/lib/python3.7/site-packages/tornado/ioloop.py", line 779, in _discard_future_result
    future.result()
  File "/glade/u/home/baird/miniconda3/envs/pangeo/lib/python3.7/site-packages/tornado/gen.py", line 326, in wrapper
    yielded = next(result)
  File "/glade/u/home/baird/miniconda3/envs/pangeo/lib/python3.7/site-packages/distributed/worker.py", line 2056, in execute
    data[k] = Actor(type(self.actors[k]), self.address, k, self)
KeyError: "('concatenate-d2fe6d71716384862735cab74de7be2d', 2, 3, 3)"
tornado.application - ERROR - Exception in callback functools.partial(<function wrap.<locals>.null_wrapper at 0x2aab14b409d8>, <Future finished exception=KeyError("('concatenate-d2fe6d71716384862735cab74de7be2d', 12, 6, 2)")>)
Traceback (most recent call last):
  File "/glade/u/home/baird/miniconda3/envs/pangeo/lib/python3.7/site-packages/distributed/worker.py", line 2053, in execute
    data[k] = self.data[k]
  File "/glade/u/home/baird/miniconda3/envs/pangeo/lib/python3.7/site-packages/zict/buffer.py", line 72, in __getitem__
    raise KeyError(key)
KeyError: "('concatenate-d2fe6d71716384862735cab74de7be2d', 12, 6, 2)"

During handling of the above exception, another exception occurred:

Traceback (most recent call last):
  File "/glade/u/home/baird/miniconda3/envs/pangeo/lib/python3.7/site-packages/tornado/ioloop.py", line 758, in _run_callback
    ret = callback()
  File "/glade/u/home/baird/miniconda3/envs/pangeo/lib/python3.7/site-packages/tornado/stack_context.py", line 300, in null_wrapper
    return fn(*args, **kwargs)
  File "/glade/u/home/baird/miniconda3/envs/pangeo/lib/python3.7/site-packages/tornado/ioloop.py", line 779, in _discard_future_result
    future.result()
  File "/glade/u/home/baird/miniconda3/envs/pangeo/lib/python3.7/site-packages/tornado/gen.py", line 326, in wrapper
    yielded = next(result)
  File "/glade/u/home/baird/miniconda3/envs/pangeo/lib/python3.7/site-packages/distributed/worker.py", line 2056, in execute
    data[k] = Actor(type(self.actors[k]), self.address, k, self)
KeyError: "('concatenate-d2fe6d71716384862735cab74de7be2d', 12, 6, 2)"
distributed.worker - ERROR - "('concatenate-d2fe6d71716384862735cab74de7be2d', 12, 6, 2)"
Traceback (most recent call last):
  File "/glade/u/home/baird/miniconda3/envs/pangeo/lib/python3.7/site-packages/distributed/worker.py", line 2053, in execute
    data[k] = self.data[k]
  File "/glade/u/home/baird/miniconda3/envs/pangeo/lib/python3.7/site-packages/zict/buffer.py", line 72, in __getitem__
    raise KeyError(key)
KeyError: "('concatenate-d2fe6d71716384862735cab74de7be2d', 12, 6, 2)"

During handling of the above exception, another exception occurred:

Traceback (most recent call last):
  File "/glade/u/home/baird/miniconda3/envs/pangeo/lib/python3.7/site-packages/distributed/worker.py", line 2056, in execute
    data[k] = Actor(type(self.actors[k]), self.address, k, self)
KeyError: "('concatenate-d2fe6d71716384862735cab74de7be2d', 12, 6, 2)"
tornado.application - ERROR - Exception in callback functools.partial(<function wrap.<locals>.null_wrapper at 0x2aab14b40e18>, <Future finished exception=KeyError("('concatenate-d2fe6d71716384862735cab74de7be2d', 12, 6, 2)")>)
Traceback (most recent call last):
  File "/glade/u/home/baird/miniconda3/envs/pangeo/lib/python3.7/site-packages/distributed/worker.py", line 2053, in execute
    data[k] = self.data[k]
  File "/glade/u/home/baird/miniconda3/envs/pangeo/lib/python3.7/site-packages/zict/buffer.py", line 72, in __getitem__
    raise KeyError(key)
KeyError: "('concatenate-d2fe6d71716384862735cab74de7be2d', 12, 6, 2)"

During handling of the above exception, another exception occurred:

Traceback (most recent call last):
  File "/glade/u/home/baird/miniconda3/envs/pangeo/lib/python3.7/site-packages/tornado/ioloop.py", line 758, in _run_callback
    ret = callback()
  File "/glade/u/home/baird/miniconda3/envs/pangeo/lib/python3.7/site-packages/tornado/stack_context.py", line 300, in null_wrapper
    return fn(*args, **kwargs)
  File "/glade/u/home/baird/miniconda3/envs/pangeo/lib/python3.7/site-packages/tornado/ioloop.py", line 779, in _discard_future_result
    future.result()
  File "/glade/u/home/baird/miniconda3/envs/pangeo/lib/python3.7/site-packages/tornado/gen.py", line 326, in wrapper
    yielded = next(result)
  File "/glade/u/home/baird/miniconda3/envs/pangeo/lib/python3.7/site-packages/distributed/worker.py", line 2056, in execute
    data[k] = Actor(type(self.actors[k]), self.address, k, self)
KeyError: "('concatenate-d2fe6d71716384862735cab74de7be2d', 12, 6, 2)"
distributed.worker - INFO - Stopping worker at tcp://10.148.9.128:56537
distributed.worker - INFO - Connection to scheduler broken.  Reconnecting...
distributed.worker - INFO - -------------------------------------------------
distributed.nanny - INFO - Closing Nanny at 'tcp://10.148.9.128:57031'
distributed.dask_worker - INFO - End worker
