distributed.nanny - INFO -         Start Nanny at: 'tcp://10.148.9.132:34490'
distributed.worker - INFO -       Start worker at:   tcp://10.148.9.132:35176
distributed.worker - INFO -          Listening to:   tcp://10.148.9.132:35176
distributed.worker - INFO -              nanny at:         10.148.9.132:34490
distributed.worker - INFO -              bokeh at:         10.148.9.132:50480
distributed.worker - INFO - Waiting to connect to:    tcp://10.148.5.46:40005
distributed.worker - INFO - -------------------------------------------------
distributed.worker - INFO -               Threads:                         36
distributed.worker - INFO -                Memory:                  100.00 GB
distributed.worker - INFO -       Local Directory: /var/tmp/pbs.4279624.chadmin1/worker-kzs1phxr
distributed.worker - INFO - -------------------------------------------------
distributed.worker - INFO -         Registered to:    tcp://10.148.5.46:40005
distributed.worker - INFO - -------------------------------------------------
distributed.core - INFO - Starting established connection
distributed.core - INFO - Event loop was unresponsive in Worker for 4.69s.  This is often caused by long-running GIL-holding functions or moving large chunks of data. This can cause timeouts and instability.
distributed.core - INFO - Event loop was unresponsive in Worker for 7.44s.  This is often caused by long-running GIL-holding functions or moving large chunks of data. This can cause timeouts and instability.
distributed.core - INFO - Event loop was unresponsive in Worker for 38.18s.  This is often caused by long-running GIL-holding functions or moving large chunks of data. This can cause timeouts and instability.
distributed.core - INFO - Event loop was unresponsive in Worker for 37.44s.  This is often caused by long-running GIL-holding functions or moving large chunks of data. This can cause timeouts and instability.
distributed.core - INFO - Event loop was unresponsive in Worker for 23.59s.  This is often caused by long-running GIL-holding functions or moving large chunks of data. This can cause timeouts and instability.
distributed.core - INFO - Event loop was unresponsive in Worker for 29.13s.  This is often caused by long-running GIL-holding functions or moving large chunks of data. This can cause timeouts and instability.
distributed.worker - INFO - Failed to put key in memory
Traceback (most recent call last):
  File "/glade/u/home/baird/miniconda3/envs/pangeo/lib/python3.7/site-packages/distributed/worker.py", line 1356, in transition_executing_done
    self.put_key_in_memory(key, value, transition=False)
  File "/glade/u/home/baird/miniconda3/envs/pangeo/lib/python3.7/site-packages/distributed/worker.py", line 1548, in put_key_in_memory
    self.data[key] = value
  File "/glade/u/home/baird/miniconda3/envs/pangeo/lib/python3.7/site-packages/zict/buffer.py", line 80, in __setitem__
    self.fast[key] = value
  File "/glade/u/home/baird/miniconda3/envs/pangeo/lib/python3.7/site-packages/zict/lru.py", line 71, in __setitem__
    self.evict()
  File "/glade/u/home/baird/miniconda3/envs/pangeo/lib/python3.7/site-packages/zict/lru.py", line 90, in evict
    cb(k, v)
  File "/glade/u/home/baird/miniconda3/envs/pangeo/lib/python3.7/site-packages/zict/buffer.py", line 52, in fast_to_slow
    self.slow[key] = value
  File "/glade/u/home/baird/miniconda3/envs/pangeo/lib/python3.7/site-packages/zict/func.py", line 42, in __setitem__
    self.d[key] = self.dump(value)
  File "/glade/u/home/baird/miniconda3/envs/pangeo/lib/python3.7/site-packages/zict/file.py", line 83, in __setitem__
    f.write(v)
OSError: [Errno 28] No space left on device
distributed.worker - INFO - Failed to put key in memory
Traceback (most recent call last):
  File "/glade/u/home/baird/miniconda3/envs/pangeo/lib/python3.7/site-packages/zict/file.py", line 83, in __setitem__
    f.write(v)
OSError: [Errno 28] No space left on device

During handling of the above exception, another exception occurred:

Traceback (most recent call last):
  File "/glade/u/home/baird/miniconda3/envs/pangeo/lib/python3.7/site-packages/distributed/worker.py", line 1356, in transition_executing_done
    self.put_key_in_memory(key, value, transition=False)
  File "/glade/u/home/baird/miniconda3/envs/pangeo/lib/python3.7/site-packages/distributed/worker.py", line 1548, in put_key_in_memory
    self.data[key] = value
  File "/glade/u/home/baird/miniconda3/envs/pangeo/lib/python3.7/site-packages/zict/buffer.py", line 80, in __setitem__
    self.fast[key] = value
  File "/glade/u/home/baird/miniconda3/envs/pangeo/lib/python3.7/site-packages/zict/lru.py", line 71, in __setitem__
    self.evict()
  File "/glade/u/home/baird/miniconda3/envs/pangeo/lib/python3.7/site-packages/zict/lru.py", line 90, in evict
    cb(k, v)
  File "/glade/u/home/baird/miniconda3/envs/pangeo/lib/python3.7/site-packages/zict/buffer.py", line 52, in fast_to_slow
    self.slow[key] = value
  File "/glade/u/home/baird/miniconda3/envs/pangeo/lib/python3.7/site-packages/zict/func.py", line 42, in __setitem__
    self.d[key] = self.dump(value)
  File "/glade/u/home/baird/miniconda3/envs/pangeo/lib/python3.7/site-packages/zict/file.py", line 85, in __setitem__
    f.write(value)
OSError: [Errno 28] No space left on device
distributed.worker - INFO - Failed to put key in memory
Traceback (most recent call last):
  File "/glade/u/home/baird/miniconda3/envs/pangeo/lib/python3.7/site-packages/zict/file.py", line 83, in __setitem__
    f.write(v)
OSError: [Errno 28] No space left on device

During handling of the above exception, another exception occurred:

Traceback (most recent call last):
  File "/glade/u/home/baird/miniconda3/envs/pangeo/lib/python3.7/site-packages/distributed/worker.py", line 1356, in transition_executing_done
    self.put_key_in_memory(key, value, transition=False)
  File "/glade/u/home/baird/miniconda3/envs/pangeo/lib/python3.7/site-packages/distributed/worker.py", line 1548, in put_key_in_memory
    self.data[key] = value
  File "/glade/u/home/baird/miniconda3/envs/pangeo/lib/python3.7/site-packages/zict/buffer.py", line 80, in __setitem__
    self.fast[key] = value
  File "/glade/u/home/baird/miniconda3/envs/pangeo/lib/python3.7/site-packages/zict/lru.py", line 71, in __setitem__
    self.evict()
  File "/glade/u/home/baird/miniconda3/envs/pangeo/lib/python3.7/site-packages/zict/lru.py", line 90, in evict
    cb(k, v)
  File "/glade/u/home/baird/miniconda3/envs/pangeo/lib/python3.7/site-packages/zict/buffer.py", line 52, in fast_to_slow
    self.slow[key] = value
  File "/glade/u/home/baird/miniconda3/envs/pangeo/lib/python3.7/site-packages/zict/func.py", line 42, in __setitem__
    self.d[key] = self.dump(value)
  File "/glade/u/home/baird/miniconda3/envs/pangeo/lib/python3.7/site-packages/zict/file.py", line 85, in __setitem__
    f.write(value)
OSError: [Errno 28] No space left on device
distributed.worker - INFO - Failed to put key in memory
Traceback (most recent call last):
  File "/glade/u/home/baird/miniconda3/envs/pangeo/lib/python3.7/site-packages/zict/file.py", line 83, in __setitem__
    f.write(v)
OSError: [Errno 28] No space left on device

During handling of the above exception, another exception occurred:

Traceback (most recent call last):
  File "/glade/u/home/baird/miniconda3/envs/pangeo/lib/python3.7/site-packages/distributed/worker.py", line 1356, in transition_executing_done
    self.put_key_in_memory(key, value, transition=False)
  File "/glade/u/home/baird/miniconda3/envs/pangeo/lib/python3.7/site-packages/distributed/worker.py", line 1548, in put_key_in_memory
    self.data[key] = value
  File "/glade/u/home/baird/miniconda3/envs/pangeo/lib/python3.7/site-packages/zict/buffer.py", line 80, in __setitem__
    self.fast[key] = value
  File "/glade/u/home/baird/miniconda3/envs/pangeo/lib/python3.7/site-packages/zict/lru.py", line 71, in __setitem__
    self.evict()
  File "/glade/u/home/baird/miniconda3/envs/pangeo/lib/python3.7/site-packages/zict/lru.py", line 90, in evict
    cb(k, v)
  File "/glade/u/home/baird/miniconda3/envs/pangeo/lib/python3.7/site-packages/zict/buffer.py", line 52, in fast_to_slow
    self.slow[key] = value
  File "/glade/u/home/baird/miniconda3/envs/pangeo/lib/python3.7/site-packages/zict/func.py", line 42, in __setitem__
    self.d[key] = self.dump(value)
  File "/glade/u/home/baird/miniconda3/envs/pangeo/lib/python3.7/site-packages/zict/file.py", line 85, in __setitem__
    f.write(value)
OSError: [Errno 28] No space left on device
distributed.worker - INFO - Failed to put key in memory
Traceback (most recent call last):
  File "/glade/u/home/baird/miniconda3/envs/pangeo/lib/python3.7/site-packages/zict/file.py", line 83, in __setitem__
    f.write(v)
OSError: [Errno 28] No space left on device

During handling of the above exception, another exception occurred:

Traceback (most recent call last):
  File "/glade/u/home/baird/miniconda3/envs/pangeo/lib/python3.7/site-packages/distributed/worker.py", line 1356, in transition_executing_done
    self.put_key_in_memory(key, value, transition=False)
  File "/glade/u/home/baird/miniconda3/envs/pangeo/lib/python3.7/site-packages/distributed/worker.py", line 1548, in put_key_in_memory
    self.data[key] = value
  File "/glade/u/home/baird/miniconda3/envs/pangeo/lib/python3.7/site-packages/zict/buffer.py", line 80, in __setitem__
    self.fast[key] = value
  File "/glade/u/home/baird/miniconda3/envs/pangeo/lib/python3.7/site-packages/zict/lru.py", line 71, in __setitem__
    self.evict()
  File "/glade/u/home/baird/miniconda3/envs/pangeo/lib/python3.7/site-packages/zict/lru.py", line 90, in evict
    cb(k, v)
  File "/glade/u/home/baird/miniconda3/envs/pangeo/lib/python3.7/site-packages/zict/buffer.py", line 52, in fast_to_slow
    self.slow[key] = value
  File "/glade/u/home/baird/miniconda3/envs/pangeo/lib/python3.7/site-packages/zict/func.py", line 42, in __setitem__
    self.d[key] = self.dump(value)
  File "/glade/u/home/baird/miniconda3/envs/pangeo/lib/python3.7/site-packages/zict/file.py", line 85, in __setitem__
    f.write(value)
OSError: [Errno 28] No space left on device
distributed.worker - INFO - Failed to put key in memory
Traceback (most recent call last):
  File "/glade/u/home/baird/miniconda3/envs/pangeo/lib/python3.7/site-packages/zict/file.py", line 83, in __setitem__
    f.write(v)
OSError: [Errno 28] No space left on device

During handling of the above exception, another exception occurred:

Traceback (most recent call last):
  File "/glade/u/home/baird/miniconda3/envs/pangeo/lib/python3.7/site-packages/distributed/worker.py", line 1356, in transition_executing_done
    self.put_key_in_memory(key, value, transition=False)
  File "/glade/u/home/baird/miniconda3/envs/pangeo/lib/python3.7/site-packages/distributed/worker.py", line 1548, in put_key_in_memory
    self.data[key] = value
  File "/glade/u/home/baird/miniconda3/envs/pangeo/lib/python3.7/site-packages/zict/buffer.py", line 80, in __setitem__
    self.fast[key] = value
  File "/glade/u/home/baird/miniconda3/envs/pangeo/lib/python3.7/site-packages/zict/lru.py", line 71, in __setitem__
    self.evict()
  File "/glade/u/home/baird/miniconda3/envs/pangeo/lib/python3.7/site-packages/zict/lru.py", line 90, in evict
    cb(k, v)
  File "/glade/u/home/baird/miniconda3/envs/pangeo/lib/python3.7/site-packages/zict/buffer.py", line 52, in fast_to_slow
    self.slow[key] = value
  File "/glade/u/home/baird/miniconda3/envs/pangeo/lib/python3.7/site-packages/zict/func.py", line 42, in __setitem__
    self.d[key] = self.dump(value)
  File "/glade/u/home/baird/miniconda3/envs/pangeo/lib/python3.7/site-packages/zict/file.py", line 85, in __setitem__
    f.write(value)
OSError: [Errno 28] No space left on device
distributed.worker - INFO - Failed to put key in memory
Traceback (most recent call last):
  File "/glade/u/home/baird/miniconda3/envs/pangeo/lib/python3.7/site-packages/zict/file.py", line 83, in __setitem__
    f.write(v)
OSError: [Errno 28] No space left on device

During handling of the above exception, another exception occurred:

Traceback (most recent call last):
  File "/glade/u/home/baird/miniconda3/envs/pangeo/lib/python3.7/site-packages/distributed/worker.py", line 1356, in transition_executing_done
    self.put_key_in_memory(key, value, transition=False)
  File "/glade/u/home/baird/miniconda3/envs/pangeo/lib/python3.7/site-packages/distributed/worker.py", line 1548, in put_key_in_memory
    self.data[key] = value
  File "/glade/u/home/baird/miniconda3/envs/pangeo/lib/python3.7/site-packages/zict/buffer.py", line 80, in __setitem__
    self.fast[key] = value
  File "/glade/u/home/baird/miniconda3/envs/pangeo/lib/python3.7/site-packages/zict/lru.py", line 71, in __setitem__
    self.evict()
  File "/glade/u/home/baird/miniconda3/envs/pangeo/lib/python3.7/site-packages/zict/lru.py", line 90, in evict
    cb(k, v)
  File "/glade/u/home/baird/miniconda3/envs/pangeo/lib/python3.7/site-packages/zict/buffer.py", line 52, in fast_to_slow
    self.slow[key] = value
  File "/glade/u/home/baird/miniconda3/envs/pangeo/lib/python3.7/site-packages/zict/func.py", line 42, in __setitem__
    self.d[key] = self.dump(value)
  File "/glade/u/home/baird/miniconda3/envs/pangeo/lib/python3.7/site-packages/zict/file.py", line 85, in __setitem__
    f.write(value)
OSError: [Errno 28] No space left on device
distributed.worker - INFO - Failed to put key in memory
Traceback (most recent call last):
  File "/glade/u/home/baird/miniconda3/envs/pangeo/lib/python3.7/site-packages/zict/file.py", line 83, in __setitem__
    f.write(v)
OSError: [Errno 28] No space left on device

During handling of the above exception, another exception occurred:

Traceback (most recent call last):
  File "/glade/u/home/baird/miniconda3/envs/pangeo/lib/python3.7/site-packages/distributed/worker.py", line 1356, in transition_executing_done
    self.put_key_in_memory(key, value, transition=False)
  File "/glade/u/home/baird/miniconda3/envs/pangeo/lib/python3.7/site-packages/distributed/worker.py", line 1548, in put_key_in_memory
    self.data[key] = value
  File "/glade/u/home/baird/miniconda3/envs/pangeo/lib/python3.7/site-packages/zict/buffer.py", line 80, in __setitem__
    self.fast[key] = value
  File "/glade/u/home/baird/miniconda3/envs/pangeo/lib/python3.7/site-packages/zict/lru.py", line 71, in __setitem__
    self.evict()
  File "/glade/u/home/baird/miniconda3/envs/pangeo/lib/python3.7/site-packages/zict/lru.py", line 90, in evict
    cb(k, v)
  File "/glade/u/home/baird/miniconda3/envs/pangeo/lib/python3.7/site-packages/zict/buffer.py", line 52, in fast_to_slow
    self.slow[key] = value
  File "/glade/u/home/baird/miniconda3/envs/pangeo/lib/python3.7/site-packages/zict/func.py", line 42, in __setitem__
    self.d[key] = self.dump(value)
  File "/glade/u/home/baird/miniconda3/envs/pangeo/lib/python3.7/site-packages/zict/file.py", line 85, in __setitem__
    f.write(value)
OSError: [Errno 28] No space left on device
distributed.worker - INFO - Failed to put key in memory
Traceback (most recent call last):
  File "/glade/u/home/baird/miniconda3/envs/pangeo/lib/python3.7/site-packages/zict/file.py", line 83, in __setitem__
    f.write(v)
OSError: [Errno 28] No space left on device

During handling of the above exception, another exception occurred:

Traceback (most recent call last):
  File "/glade/u/home/baird/miniconda3/envs/pangeo/lib/python3.7/site-packages/distributed/worker.py", line 1356, in transition_executing_done
    self.put_key_in_memory(key, value, transition=False)
  File "/glade/u/home/baird/miniconda3/envs/pangeo/lib/python3.7/site-packages/distributed/worker.py", line 1548, in put_key_in_memory
    self.data[key] = value
  File "/glade/u/home/baird/miniconda3/envs/pangeo/lib/python3.7/site-packages/zict/buffer.py", line 80, in __setitem__
    self.fast[key] = value
  File "/glade/u/home/baird/miniconda3/envs/pangeo/lib/python3.7/site-packages/zict/lru.py", line 71, in __setitem__
    self.evict()
  File "/glade/u/home/baird/miniconda3/envs/pangeo/lib/python3.7/site-packages/zict/lru.py", line 90, in evict
    cb(k, v)
  File "/glade/u/home/baird/miniconda3/envs/pangeo/lib/python3.7/site-packages/zict/buffer.py", line 52, in fast_to_slow
    self.slow[key] = value
  File "/glade/u/home/baird/miniconda3/envs/pangeo/lib/python3.7/site-packages/zict/func.py", line 42, in __setitem__
    self.d[key] = self.dump(value)
  File "/glade/u/home/baird/miniconda3/envs/pangeo/lib/python3.7/site-packages/zict/file.py", line 85, in __setitem__
    f.write(value)
OSError: [Errno 28] No space left on device
distributed.worker - INFO - Failed to put key in memory
Traceback (most recent call last):
  File "/glade/u/home/baird/miniconda3/envs/pangeo/lib/python3.7/site-packages/zict/file.py", line 83, in __setitem__
    f.write(v)
OSError: [Errno 28] No space left on device

During handling of the above exception, another exception occurred:

Traceback (most recent call last):
  File "/glade/u/home/baird/miniconda3/envs/pangeo/lib/python3.7/site-packages/distributed/worker.py", line 1356, in transition_executing_done
    self.put_key_in_memory(key, value, transition=False)
  File "/glade/u/home/baird/miniconda3/envs/pangeo/lib/python3.7/site-packages/distributed/worker.py", line 1548, in put_key_in_memory
    self.data[key] = value
  File "/glade/u/home/baird/miniconda3/envs/pangeo/lib/python3.7/site-packages/zict/buffer.py", line 80, in __setitem__
    self.fast[key] = value
  File "/glade/u/home/baird/miniconda3/envs/pangeo/lib/python3.7/site-packages/zict/lru.py", line 71, in __setitem__
    self.evict()
  File "/glade/u/home/baird/miniconda3/envs/pangeo/lib/python3.7/site-packages/zict/lru.py", line 90, in evict
    cb(k, v)
  File "/glade/u/home/baird/miniconda3/envs/pangeo/lib/python3.7/site-packages/zict/buffer.py", line 52, in fast_to_slow
    self.slow[key] = value
  File "/glade/u/home/baird/miniconda3/envs/pangeo/lib/python3.7/site-packages/zict/func.py", line 42, in __setitem__
    self.d[key] = self.dump(value)
  File "/glade/u/home/baird/miniconda3/envs/pangeo/lib/python3.7/site-packages/zict/file.py", line 85, in __setitem__
    f.write(value)
OSError: [Errno 28] No space left on device
distributed.worker - INFO - Failed to put key in memory
Traceback (most recent call last):
  File "/glade/u/home/baird/miniconda3/envs/pangeo/lib/python3.7/site-packages/zict/file.py", line 83, in __setitem__
    f.write(v)
OSError: [Errno 28] No space left on device

During handling of the above exception, another exception occurred:

Traceback (most recent call last):
  File "/glade/u/home/baird/miniconda3/envs/pangeo/lib/python3.7/site-packages/distributed/worker.py", line 1356, in transition_executing_done
    self.put_key_in_memory(key, value, transition=False)
  File "/glade/u/home/baird/miniconda3/envs/pangeo/lib/python3.7/site-packages/distributed/worker.py", line 1548, in put_key_in_memory
    self.data[key] = value
  File "/glade/u/home/baird/miniconda3/envs/pangeo/lib/python3.7/site-packages/zict/buffer.py", line 80, in __setitem__
    self.fast[key] = value
  File "/glade/u/home/baird/miniconda3/envs/pangeo/lib/python3.7/site-packages/zict/lru.py", line 71, in __setitem__
    self.evict()
  File "/glade/u/home/baird/miniconda3/envs/pangeo/lib/python3.7/site-packages/zict/lru.py", line 90, in evict
    cb(k, v)
  File "/glade/u/home/baird/miniconda3/envs/pangeo/lib/python3.7/site-packages/zict/buffer.py", line 52, in fast_to_slow
    self.slow[key] = value
  File "/glade/u/home/baird/miniconda3/envs/pangeo/lib/python3.7/site-packages/zict/func.py", line 42, in __setitem__
    self.d[key] = self.dump(value)
  File "/glade/u/home/baird/miniconda3/envs/pangeo/lib/python3.7/site-packages/zict/file.py", line 85, in __setitem__
    f.write(value)
OSError: [Errno 28] No space left on device
distributed.worker - INFO - Failed to put key in memory
Traceback (most recent call last):
  File "/glade/u/home/baird/miniconda3/envs/pangeo/lib/python3.7/site-packages/zict/file.py", line 83, in __setitem__
    f.write(v)
OSError: [Errno 28] No space left on device

During handling of the above exception, another exception occurred:

Traceback (most recent call last):
  File "/glade/u/home/baird/miniconda3/envs/pangeo/lib/python3.7/site-packages/distributed/worker.py", line 1356, in transition_executing_done
    self.put_key_in_memory(key, value, transition=False)
  File "/glade/u/home/baird/miniconda3/envs/pangeo/lib/python3.7/site-packages/distributed/worker.py", line 1548, in put_key_in_memory
    self.data[key] = value
  File "/glade/u/home/baird/miniconda3/envs/pangeo/lib/python3.7/site-packages/zict/buffer.py", line 80, in __setitem__
    self.fast[key] = value
  File "/glade/u/home/baird/miniconda3/envs/pangeo/lib/python3.7/site-packages/zict/lru.py", line 71, in __setitem__
    self.evict()
  File "/glade/u/home/baird/miniconda3/envs/pangeo/lib/python3.7/site-packages/zict/lru.py", line 90, in evict
    cb(k, v)
  File "/glade/u/home/baird/miniconda3/envs/pangeo/lib/python3.7/site-packages/zict/buffer.py", line 52, in fast_to_slow
    self.slow[key] = value
  File "/glade/u/home/baird/miniconda3/envs/pangeo/lib/python3.7/site-packages/zict/func.py", line 42, in __setitem__
    self.d[key] = self.dump(value)
  File "/glade/u/home/baird/miniconda3/envs/pangeo/lib/python3.7/site-packages/zict/file.py", line 85, in __setitem__
    f.write(value)
OSError: [Errno 28] No space left on device
distributed.worker - INFO - Failed to put key in memory
Traceback (most recent call last):
  File "/glade/u/home/baird/miniconda3/envs/pangeo/lib/python3.7/site-packages/zict/file.py", line 83, in __setitem__
    f.write(v)
OSError: [Errno 28] No space left on device

During handling of the above exception, another exception occurred:

Traceback (most recent call last):
  File "/glade/u/home/baird/miniconda3/envs/pangeo/lib/python3.7/site-packages/distributed/worker.py", line 1356, in transition_executing_done
    self.put_key_in_memory(key, value, transition=False)
  File "/glade/u/home/baird/miniconda3/envs/pangeo/lib/python3.7/site-packages/distributed/worker.py", line 1548, in put_key_in_memory
    self.data[key] = value
  File "/glade/u/home/baird/miniconda3/envs/pangeo/lib/python3.7/site-packages/zict/buffer.py", line 80, in __setitem__
    self.fast[key] = value
  File "/glade/u/home/baird/miniconda3/envs/pangeo/lib/python3.7/site-packages/zict/lru.py", line 71, in __setitem__
    self.evict()
  File "/glade/u/home/baird/miniconda3/envs/pangeo/lib/python3.7/site-packages/zict/lru.py", line 90, in evict
    cb(k, v)
  File "/glade/u/home/baird/miniconda3/envs/pangeo/lib/python3.7/site-packages/zict/buffer.py", line 52, in fast_to_slow
    self.slow[key] = value
  File "/glade/u/home/baird/miniconda3/envs/pangeo/lib/python3.7/site-packages/zict/func.py", line 42, in __setitem__
    self.d[key] = self.dump(value)
  File "/glade/u/home/baird/miniconda3/envs/pangeo/lib/python3.7/site-packages/zict/file.py", line 85, in __setitem__
    f.write(value)
OSError: [Errno 28] No space left on device
distributed.worker - INFO - Failed to put key in memory
Traceback (most recent call last):
  File "/glade/u/home/baird/miniconda3/envs/pangeo/lib/python3.7/site-packages/zict/file.py", line 83, in __setitem__
    f.write(v)
OSError: [Errno 28] No space left on device

During handling of the above exception, another exception occurred:

Traceback (most recent call last):
  File "/glade/u/home/baird/miniconda3/envs/pangeo/lib/python3.7/site-packages/distributed/worker.py", line 1356, in transition_executing_done
    self.put_key_in_memory(key, value, transition=False)
  File "/glade/u/home/baird/miniconda3/envs/pangeo/lib/python3.7/site-packages/distributed/worker.py", line 1548, in put_key_in_memory
    self.data[key] = value
  File "/glade/u/home/baird/miniconda3/envs/pangeo/lib/python3.7/site-packages/zict/buffer.py", line 80, in __setitem__
    self.fast[key] = value
  File "/glade/u/home/baird/miniconda3/envs/pangeo/lib/python3.7/site-packages/zict/lru.py", line 71, in __setitem__
    self.evict()
  File "/glade/u/home/baird/miniconda3/envs/pangeo/lib/python3.7/site-packages/zict/lru.py", line 90, in evict
    cb(k, v)
  File "/glade/u/home/baird/miniconda3/envs/pangeo/lib/python3.7/site-packages/zict/buffer.py", line 52, in fast_to_slow
    self.slow[key] = value
  File "/glade/u/home/baird/miniconda3/envs/pangeo/lib/python3.7/site-packages/zict/func.py", line 42, in __setitem__
    self.d[key] = self.dump(value)
  File "/glade/u/home/baird/miniconda3/envs/pangeo/lib/python3.7/site-packages/zict/file.py", line 85, in __setitem__
    f.write(value)
OSError: [Errno 28] No space left on device
distributed.worker - INFO - Failed to put key in memory
Traceback (most recent call last):
  File "/glade/u/home/baird/miniconda3/envs/pangeo/lib/python3.7/site-packages/zict/file.py", line 83, in __setitem__
    f.write(v)
OSError: [Errno 28] No space left on device

During handling of the above exception, another exception occurred:

Traceback (most recent call last):
  File "/glade/u/home/baird/miniconda3/envs/pangeo/lib/python3.7/site-packages/distributed/worker.py", line 1356, in transition_executing_done
    self.put_key_in_memory(key, value, transition=False)
  File "/glade/u/home/baird/miniconda3/envs/pangeo/lib/python3.7/site-packages/distributed/worker.py", line 1548, in put_key_in_memory
    self.data[key] = value
  File "/glade/u/home/baird/miniconda3/envs/pangeo/lib/python3.7/site-packages/zict/buffer.py", line 80, in __setitem__
    self.fast[key] = value
  File "/glade/u/home/baird/miniconda3/envs/pangeo/lib/python3.7/site-packages/zict/lru.py", line 71, in __setitem__
    self.evict()
  File "/glade/u/home/baird/miniconda3/envs/pangeo/lib/python3.7/site-packages/zict/lru.py", line 90, in evict
    cb(k, v)
  File "/glade/u/home/baird/miniconda3/envs/pangeo/lib/python3.7/site-packages/zict/buffer.py", line 52, in fast_to_slow
    self.slow[key] = value
  File "/glade/u/home/baird/miniconda3/envs/pangeo/lib/python3.7/site-packages/zict/func.py", line 42, in __setitem__
    self.d[key] = self.dump(value)
  File "/glade/u/home/baird/miniconda3/envs/pangeo/lib/python3.7/site-packages/zict/file.py", line 85, in __setitem__
    f.write(value)
OSError: [Errno 28] No space left on device
distributed.worker - INFO - Failed to put key in memory
Traceback (most recent call last):
  File "/glade/u/home/baird/miniconda3/envs/pangeo/lib/python3.7/site-packages/zict/file.py", line 83, in __setitem__
    f.write(v)
OSError: [Errno 28] No space left on device

During handling of the above exception, another exception occurred:

Traceback (most recent call last):
  File "/glade/u/home/baird/miniconda3/envs/pangeo/lib/python3.7/site-packages/distributed/worker.py", line 1356, in transition_executing_done
    self.put_key_in_memory(key, value, transition=False)
  File "/glade/u/home/baird/miniconda3/envs/pangeo/lib/python3.7/site-packages/distributed/worker.py", line 1548, in put_key_in_memory
    self.data[key] = value
  File "/glade/u/home/baird/miniconda3/envs/pangeo/lib/python3.7/site-packages/zict/buffer.py", line 80, in __setitem__
    self.fast[key] = value
  File "/glade/u/home/baird/miniconda3/envs/pangeo/lib/python3.7/site-packages/zict/lru.py", line 71, in __setitem__
    self.evict()
  File "/glade/u/home/baird/miniconda3/envs/pangeo/lib/python3.7/site-packages/zict/lru.py", line 90, in evict
    cb(k, v)
  File "/glade/u/home/baird/miniconda3/envs/pangeo/lib/python3.7/site-packages/zict/buffer.py", line 52, in fast_to_slow
    self.slow[key] = value
  File "/glade/u/home/baird/miniconda3/envs/pangeo/lib/python3.7/site-packages/zict/func.py", line 42, in __setitem__
    self.d[key] = self.dump(value)
  File "/glade/u/home/baird/miniconda3/envs/pangeo/lib/python3.7/site-packages/zict/file.py", line 85, in __setitem__
    f.write(value)
OSError: [Errno 28] No space left on device
distributed.worker - INFO - Failed to put key in memory
Traceback (most recent call last):
  File "/glade/u/home/baird/miniconda3/envs/pangeo/lib/python3.7/site-packages/zict/file.py", line 83, in __setitem__
    f.write(v)
OSError: [Errno 28] No space left on device

During handling of the above exception, another exception occurred:

Traceback (most recent call last):
  File "/glade/u/home/baird/miniconda3/envs/pangeo/lib/python3.7/site-packages/distributed/worker.py", line 1356, in transition_executing_done
    self.put_key_in_memory(key, value, transition=False)
  File "/glade/u/home/baird/miniconda3/envs/pangeo/lib/python3.7/site-packages/distributed/worker.py", line 1548, in put_key_in_memory
    self.data[key] = value
  File "/glade/u/home/baird/miniconda3/envs/pangeo/lib/python3.7/site-packages/zict/buffer.py", line 80, in __setitem__
    self.fast[key] = value
  File "/glade/u/home/baird/miniconda3/envs/pangeo/lib/python3.7/site-packages/zict/lru.py", line 71, in __setitem__
    self.evict()
  File "/glade/u/home/baird/miniconda3/envs/pangeo/lib/python3.7/site-packages/zict/lru.py", line 90, in evict
    cb(k, v)
  File "/glade/u/home/baird/miniconda3/envs/pangeo/lib/python3.7/site-packages/zict/buffer.py", line 52, in fast_to_slow
    self.slow[key] = value
  File "/glade/u/home/baird/miniconda3/envs/pangeo/lib/python3.7/site-packages/zict/func.py", line 42, in __setitem__
    self.d[key] = self.dump(value)
  File "/glade/u/home/baird/miniconda3/envs/pangeo/lib/python3.7/site-packages/zict/file.py", line 85, in __setitem__
    f.write(value)
OSError: [Errno 28] No space left on device
distributed.worker - INFO - Failed to put key in memory
Traceback (most recent call last):
  File "/glade/u/home/baird/miniconda3/envs/pangeo/lib/python3.7/site-packages/zict/file.py", line 83, in __setitem__
    f.write(v)
OSError: [Errno 28] No space left on device

During handling of the above exception, another exception occurred:

Traceback (most recent call last):
  File "/glade/u/home/baird/miniconda3/envs/pangeo/lib/python3.7/site-packages/distributed/worker.py", line 1356, in transition_executing_done
    self.put_key_in_memory(key, value, transition=False)
  File "/glade/u/home/baird/miniconda3/envs/pangeo/lib/python3.7/site-packages/distributed/worker.py", line 1548, in put_key_in_memory
    self.data[key] = value
  File "/glade/u/home/baird/miniconda3/envs/pangeo/lib/python3.7/site-packages/zict/buffer.py", line 80, in __setitem__
    self.fast[key] = value
  File "/glade/u/home/baird/miniconda3/envs/pangeo/lib/python3.7/site-packages/zict/lru.py", line 71, in __setitem__
    self.evict()
  File "/glade/u/home/baird/miniconda3/envs/pangeo/lib/python3.7/site-packages/zict/lru.py", line 90, in evict
    cb(k, v)
  File "/glade/u/home/baird/miniconda3/envs/pangeo/lib/python3.7/site-packages/zict/buffer.py", line 52, in fast_to_slow
    self.slow[key] = value
  File "/glade/u/home/baird/miniconda3/envs/pangeo/lib/python3.7/site-packages/zict/func.py", line 42, in __setitem__
    self.d[key] = self.dump(value)
  File "/glade/u/home/baird/miniconda3/envs/pangeo/lib/python3.7/site-packages/zict/file.py", line 85, in __setitem__
    f.write(value)
OSError: [Errno 28] No space left on device
distributed.worker - INFO - Failed to put key in memory
Traceback (most recent call last):
  File "/glade/u/home/baird/miniconda3/envs/pangeo/lib/python3.7/site-packages/zict/file.py", line 83, in __setitem__
    f.write(v)
OSError: [Errno 28] No space left on device

During handling of the above exception, another exception occurred:

Traceback (most recent call last):
  File "/glade/u/home/baird/miniconda3/envs/pangeo/lib/python3.7/site-packages/distributed/worker.py", line 1356, in transition_executing_done
    self.put_key_in_memory(key, value, transition=False)
  File "/glade/u/home/baird/miniconda3/envs/pangeo/lib/python3.7/site-packages/distributed/worker.py", line 1548, in put_key_in_memory
    self.data[key] = value
  File "/glade/u/home/baird/miniconda3/envs/pangeo/lib/python3.7/site-packages/zict/buffer.py", line 80, in __setitem__
    self.fast[key] = value
  File "/glade/u/home/baird/miniconda3/envs/pangeo/lib/python3.7/site-packages/zict/lru.py", line 71, in __setitem__
    self.evict()
  File "/glade/u/home/baird/miniconda3/envs/pangeo/lib/python3.7/site-packages/zict/lru.py", line 90, in evict
    cb(k, v)
  File "/glade/u/home/baird/miniconda3/envs/pangeo/lib/python3.7/site-packages/zict/buffer.py", line 52, in fast_to_slow
    self.slow[key] = value
  File "/glade/u/home/baird/miniconda3/envs/pangeo/lib/python3.7/site-packages/zict/func.py", line 42, in __setitem__
    self.d[key] = self.dump(value)
  File "/glade/u/home/baird/miniconda3/envs/pangeo/lib/python3.7/site-packages/zict/file.py", line 85, in __setitem__
    f.write(value)
OSError: [Errno 28] No space left on device
distributed.worker - INFO - Failed to put key in memory
Traceback (most recent call last):
  File "/glade/u/home/baird/miniconda3/envs/pangeo/lib/python3.7/site-packages/zict/file.py", line 83, in __setitem__
    f.write(v)
OSError: [Errno 28] No space left on device

During handling of the above exception, another exception occurred:

Traceback (most recent call last):
  File "/glade/u/home/baird/miniconda3/envs/pangeo/lib/python3.7/site-packages/distributed/worker.py", line 1356, in transition_executing_done
    self.put_key_in_memory(key, value, transition=False)
  File "/glade/u/home/baird/miniconda3/envs/pangeo/lib/python3.7/site-packages/distributed/worker.py", line 1548, in put_key_in_memory
    self.data[key] = value
  File "/glade/u/home/baird/miniconda3/envs/pangeo/lib/python3.7/site-packages/zict/buffer.py", line 80, in __setitem__
    self.fast[key] = value
  File "/glade/u/home/baird/miniconda3/envs/pangeo/lib/python3.7/site-packages/zict/lru.py", line 71, in __setitem__
    self.evict()
  File "/glade/u/home/baird/miniconda3/envs/pangeo/lib/python3.7/site-packages/zict/lru.py", line 90, in evict
    cb(k, v)
  File "/glade/u/home/baird/miniconda3/envs/pangeo/lib/python3.7/site-packages/zict/buffer.py", line 52, in fast_to_slow
    self.slow[key] = value
  File "/glade/u/home/baird/miniconda3/envs/pangeo/lib/python3.7/site-packages/zict/func.py", line 42, in __setitem__
    self.d[key] = self.dump(value)
  File "/glade/u/home/baird/miniconda3/envs/pangeo/lib/python3.7/site-packages/zict/file.py", line 85, in __setitem__
    f.write(value)
OSError: [Errno 28] No space left on device
distributed.worker - INFO - Failed to put key in memory
Traceback (most recent call last):
  File "/glade/u/home/baird/miniconda3/envs/pangeo/lib/python3.7/site-packages/zict/file.py", line 83, in __setitem__
    f.write(v)
OSError: [Errno 28] No space left on device

During handling of the above exception, another exception occurred:

Traceback (most recent call last):
  File "/glade/u/home/baird/miniconda3/envs/pangeo/lib/python3.7/site-packages/distributed/worker.py", line 1356, in transition_executing_done
    self.put_key_in_memory(key, value, transition=False)
  File "/glade/u/home/baird/miniconda3/envs/pangeo/lib/python3.7/site-packages/distributed/worker.py", line 1548, in put_key_in_memory
    self.data[key] = value
  File "/glade/u/home/baird/miniconda3/envs/pangeo/lib/python3.7/site-packages/zict/buffer.py", line 80, in __setitem__
    self.fast[key] = value
  File "/glade/u/home/baird/miniconda3/envs/pangeo/lib/python3.7/site-packages/zict/lru.py", line 71, in __setitem__
    self.evict()
  File "/glade/u/home/baird/miniconda3/envs/pangeo/lib/python3.7/site-packages/zict/lru.py", line 90, in evict
    cb(k, v)
  File "/glade/u/home/baird/miniconda3/envs/pangeo/lib/python3.7/site-packages/zict/buffer.py", line 52, in fast_to_slow
    self.slow[key] = value
  File "/glade/u/home/baird/miniconda3/envs/pangeo/lib/python3.7/site-packages/zict/func.py", line 42, in __setitem__
    self.d[key] = self.dump(value)
  File "/glade/u/home/baird/miniconda3/envs/pangeo/lib/python3.7/site-packages/zict/file.py", line 85, in __setitem__
    f.write(value)
OSError: [Errno 28] No space left on device
distributed.worker - INFO - Failed to put key in memory
Traceback (most recent call last):
  File "/glade/u/home/baird/miniconda3/envs/pangeo/lib/python3.7/site-packages/zict/file.py", line 83, in __setitem__
    f.write(v)
OSError: [Errno 28] No space left on device

During handling of the above exception, another exception occurred:

Traceback (most recent call last):
  File "/glade/u/home/baird/miniconda3/envs/pangeo/lib/python3.7/site-packages/distributed/worker.py", line 1356, in transition_executing_done
    self.put_key_in_memory(key, value, transition=False)
  File "/glade/u/home/baird/miniconda3/envs/pangeo/lib/python3.7/site-packages/distributed/worker.py", line 1548, in put_key_in_memory
    self.data[key] = value
  File "/glade/u/home/baird/miniconda3/envs/pangeo/lib/python3.7/site-packages/zict/buffer.py", line 80, in __setitem__
    self.fast[key] = value
  File "/glade/u/home/baird/miniconda3/envs/pangeo/lib/python3.7/site-packages/zict/lru.py", line 71, in __setitem__
    self.evict()
  File "/glade/u/home/baird/miniconda3/envs/pangeo/lib/python3.7/site-packages/zict/lru.py", line 90, in evict
    cb(k, v)
  File "/glade/u/home/baird/miniconda3/envs/pangeo/lib/python3.7/site-packages/zict/buffer.py", line 52, in fast_to_slow
    self.slow[key] = value
  File "/glade/u/home/baird/miniconda3/envs/pangeo/lib/python3.7/site-packages/zict/func.py", line 42, in __setitem__
    self.d[key] = self.dump(value)
  File "/glade/u/home/baird/miniconda3/envs/pangeo/lib/python3.7/site-packages/zict/file.py", line 85, in __setitem__
    f.write(value)
OSError: [Errno 28] No space left on device
distributed.worker - INFO - Failed to put key in memory
Traceback (most recent call last):
  File "/glade/u/home/baird/miniconda3/envs/pangeo/lib/python3.7/site-packages/zict/file.py", line 83, in __setitem__
    f.write(v)
OSError: [Errno 28] No space left on device

During handling of the above exception, another exception occurred:

Traceback (most recent call last):
  File "/glade/u/home/baird/miniconda3/envs/pangeo/lib/python3.7/site-packages/distributed/worker.py", line 1356, in transition_executing_done
    self.put_key_in_memory(key, value, transition=False)
  File "/glade/u/home/baird/miniconda3/envs/pangeo/lib/python3.7/site-packages/distributed/worker.py", line 1548, in put_key_in_memory
    self.data[key] = value
  File "/glade/u/home/baird/miniconda3/envs/pangeo/lib/python3.7/site-packages/zict/buffer.py", line 80, in __setitem__
    self.fast[key] = value
  File "/glade/u/home/baird/miniconda3/envs/pangeo/lib/python3.7/site-packages/zict/lru.py", line 71, in __setitem__
    self.evict()
  File "/glade/u/home/baird/miniconda3/envs/pangeo/lib/python3.7/site-packages/zict/lru.py", line 90, in evict
    cb(k, v)
  File "/glade/u/home/baird/miniconda3/envs/pangeo/lib/python3.7/site-packages/zict/buffer.py", line 52, in fast_to_slow
    self.slow[key] = value
  File "/glade/u/home/baird/miniconda3/envs/pangeo/lib/python3.7/site-packages/zict/func.py", line 42, in __setitem__
    self.d[key] = self.dump(value)
  File "/glade/u/home/baird/miniconda3/envs/pangeo/lib/python3.7/site-packages/zict/file.py", line 85, in __setitem__
    f.write(value)
OSError: [Errno 28] No space left on device
distributed.worker - INFO - Failed to put key in memory
Traceback (most recent call last):
  File "/glade/u/home/baird/miniconda3/envs/pangeo/lib/python3.7/site-packages/zict/file.py", line 83, in __setitem__
    f.write(v)
OSError: [Errno 28] No space left on device

During handling of the above exception, another exception occurred:

Traceback (most recent call last):
  File "/glade/u/home/baird/miniconda3/envs/pangeo/lib/python3.7/site-packages/distributed/worker.py", line 1356, in transition_executing_done
    self.put_key_in_memory(key, value, transition=False)
  File "/glade/u/home/baird/miniconda3/envs/pangeo/lib/python3.7/site-packages/distributed/worker.py", line 1548, in put_key_in_memory
    self.data[key] = value
  File "/glade/u/home/baird/miniconda3/envs/pangeo/lib/python3.7/site-packages/zict/buffer.py", line 80, in __setitem__
    self.fast[key] = value
  File "/glade/u/home/baird/miniconda3/envs/pangeo/lib/python3.7/site-packages/zict/lru.py", line 71, in __setitem__
    self.evict()
  File "/glade/u/home/baird/miniconda3/envs/pangeo/lib/python3.7/site-packages/zict/lru.py", line 90, in evict
    cb(k, v)
  File "/glade/u/home/baird/miniconda3/envs/pangeo/lib/python3.7/site-packages/zict/buffer.py", line 52, in fast_to_slow
    self.slow[key] = value
  File "/glade/u/home/baird/miniconda3/envs/pangeo/lib/python3.7/site-packages/zict/func.py", line 42, in __setitem__
    self.d[key] = self.dump(value)
  File "/glade/u/home/baird/miniconda3/envs/pangeo/lib/python3.7/site-packages/zict/file.py", line 85, in __setitem__
    f.write(value)
OSError: [Errno 28] No space left on device
distributed.worker - INFO - Failed to put key in memory
Traceback (most recent call last):
  File "/glade/u/home/baird/miniconda3/envs/pangeo/lib/python3.7/site-packages/zict/file.py", line 83, in __setitem__
    f.write(v)
OSError: [Errno 28] No space left on device

During handling of the above exception, another exception occurred:

Traceback (most recent call last):
  File "/glade/u/home/baird/miniconda3/envs/pangeo/lib/python3.7/site-packages/distributed/worker.py", line 1356, in transition_executing_done
    self.put_key_in_memory(key, value, transition=False)
  File "/glade/u/home/baird/miniconda3/envs/pangeo/lib/python3.7/site-packages/distributed/worker.py", line 1548, in put_key_in_memory
    self.data[key] = value
  File "/glade/u/home/baird/miniconda3/envs/pangeo/lib/python3.7/site-packages/zict/buffer.py", line 80, in __setitem__
    self.fast[key] = value
  File "/glade/u/home/baird/miniconda3/envs/pangeo/lib/python3.7/site-packages/zict/lru.py", line 71, in __setitem__
    self.evict()
  File "/glade/u/home/baird/miniconda3/envs/pangeo/lib/python3.7/site-packages/zict/lru.py", line 90, in evict
    cb(k, v)
  File "/glade/u/home/baird/miniconda3/envs/pangeo/lib/python3.7/site-packages/zict/buffer.py", line 52, in fast_to_slow
    self.slow[key] = value
  File "/glade/u/home/baird/miniconda3/envs/pangeo/lib/python3.7/site-packages/zict/func.py", line 42, in __setitem__
    self.d[key] = self.dump(value)
  File "/glade/u/home/baird/miniconda3/envs/pangeo/lib/python3.7/site-packages/zict/file.py", line 85, in __setitem__
    f.write(value)
OSError: [Errno 28] No space left on device
distributed.worker - INFO - Failed to put key in memory
Traceback (most recent call last):
  File "/glade/u/home/baird/miniconda3/envs/pangeo/lib/python3.7/site-packages/zict/file.py", line 83, in __setitem__
    f.write(v)
OSError: [Errno 28] No space left on device

During handling of the above exception, another exception occurred:

Traceback (most recent call last):
  File "/glade/u/home/baird/miniconda3/envs/pangeo/lib/python3.7/site-packages/distributed/worker.py", line 1356, in transition_executing_done
    self.put_key_in_memory(key, value, transition=False)
  File "/glade/u/home/baird/miniconda3/envs/pangeo/lib/python3.7/site-packages/distributed/worker.py", line 1548, in put_key_in_memory
    self.data[key] = value
  File "/glade/u/home/baird/miniconda3/envs/pangeo/lib/python3.7/site-packages/zict/buffer.py", line 80, in __setitem__
    self.fast[key] = value
  File "/glade/u/home/baird/miniconda3/envs/pangeo/lib/python3.7/site-packages/zict/lru.py", line 71, in __setitem__
    self.evict()
  File "/glade/u/home/baird/miniconda3/envs/pangeo/lib/python3.7/site-packages/zict/lru.py", line 90, in evict
    cb(k, v)
  File "/glade/u/home/baird/miniconda3/envs/pangeo/lib/python3.7/site-packages/zict/buffer.py", line 52, in fast_to_slow
    self.slow[key] = value
  File "/glade/u/home/baird/miniconda3/envs/pangeo/lib/python3.7/site-packages/zict/func.py", line 42, in __setitem__
    self.d[key] = self.dump(value)
  File "/glade/u/home/baird/miniconda3/envs/pangeo/lib/python3.7/site-packages/zict/file.py", line 85, in __setitem__
    f.write(value)
OSError: [Errno 28] No space left on device
distributed.worker - INFO - Failed to put key in memory
Traceback (most recent call last):
  File "/glade/u/home/baird/miniconda3/envs/pangeo/lib/python3.7/site-packages/zict/file.py", line 83, in __setitem__
    f.write(v)
OSError: [Errno 28] No space left on device

During handling of the above exception, another exception occurred:

Traceback (most recent call last):
  File "/glade/u/home/baird/miniconda3/envs/pangeo/lib/python3.7/site-packages/distributed/worker.py", line 1356, in transition_executing_done
    self.put_key_in_memory(key, value, transition=False)
  File "/glade/u/home/baird/miniconda3/envs/pangeo/lib/python3.7/site-packages/distributed/worker.py", line 1548, in put_key_in_memory
    self.data[key] = value
  File "/glade/u/home/baird/miniconda3/envs/pangeo/lib/python3.7/site-packages/zict/buffer.py", line 80, in __setitem__
    self.fast[key] = value
  File "/glade/u/home/baird/miniconda3/envs/pangeo/lib/python3.7/site-packages/zict/lru.py", line 71, in __setitem__
    self.evict()
  File "/glade/u/home/baird/miniconda3/envs/pangeo/lib/python3.7/site-packages/zict/lru.py", line 90, in evict
    cb(k, v)
  File "/glade/u/home/baird/miniconda3/envs/pangeo/lib/python3.7/site-packages/zict/buffer.py", line 52, in fast_to_slow
    self.slow[key] = value
  File "/glade/u/home/baird/miniconda3/envs/pangeo/lib/python3.7/site-packages/zict/func.py", line 42, in __setitem__
    self.d[key] = self.dump(value)
  File "/glade/u/home/baird/miniconda3/envs/pangeo/lib/python3.7/site-packages/zict/file.py", line 85, in __setitem__
    f.write(value)
OSError: [Errno 28] No space left on device
distributed.worker - INFO - Failed to put key in memory
Traceback (most recent call last):
  File "/glade/u/home/baird/miniconda3/envs/pangeo/lib/python3.7/site-packages/zict/file.py", line 83, in __setitem__
    f.write(v)
OSError: [Errno 28] No space left on device

During handling of the above exception, another exception occurred:

Traceback (most recent call last):
  File "/glade/u/home/baird/miniconda3/envs/pangeo/lib/python3.7/site-packages/distributed/worker.py", line 1356, in transition_executing_done
    self.put_key_in_memory(key, value, transition=False)
  File "/glade/u/home/baird/miniconda3/envs/pangeo/lib/python3.7/site-packages/distributed/worker.py", line 1548, in put_key_in_memory
    self.data[key] = value
  File "/glade/u/home/baird/miniconda3/envs/pangeo/lib/python3.7/site-packages/zict/buffer.py", line 80, in __setitem__
    self.fast[key] = value
  File "/glade/u/home/baird/miniconda3/envs/pangeo/lib/python3.7/site-packages/zict/lru.py", line 71, in __setitem__
    self.evict()
  File "/glade/u/home/baird/miniconda3/envs/pangeo/lib/python3.7/site-packages/zict/lru.py", line 90, in evict
    cb(k, v)
  File "/glade/u/home/baird/miniconda3/envs/pangeo/lib/python3.7/site-packages/zict/buffer.py", line 52, in fast_to_slow
    self.slow[key] = value
  File "/glade/u/home/baird/miniconda3/envs/pangeo/lib/python3.7/site-packages/zict/func.py", line 42, in __setitem__
    self.d[key] = self.dump(value)
  File "/glade/u/home/baird/miniconda3/envs/pangeo/lib/python3.7/site-packages/zict/file.py", line 85, in __setitem__
    f.write(value)
OSError: [Errno 28] No space left on device
distributed.worker - ERROR - "('concatenate-d2fe6d71716384862735cab74de7be2d', 16, 6, 4)"
Traceback (most recent call last):
  File "/glade/u/home/baird/miniconda3/envs/pangeo/lib/python3.7/site-packages/distributed/worker.py", line 2053, in execute
    data[k] = self.data[k]
  File "/glade/u/home/baird/miniconda3/envs/pangeo/lib/python3.7/site-packages/zict/buffer.py", line 72, in __getitem__
    raise KeyError(key)
KeyError: "('concatenate-d2fe6d71716384862735cab74de7be2d', 16, 6, 4)"

During handling of the above exception, another exception occurred:

Traceback (most recent call last):
  File "/glade/u/home/baird/miniconda3/envs/pangeo/lib/python3.7/site-packages/distributed/worker.py", line 2056, in execute
    data[k] = Actor(type(self.actors[k]), self.address, k, self)
KeyError: "('concatenate-d2fe6d71716384862735cab74de7be2d', 16, 6, 4)"
distributed.worker - ERROR - "('concatenate-d2fe6d71716384862735cab74de7be2d', 2, 5, 8)"
Traceback (most recent call last):
  File "/glade/u/home/baird/miniconda3/envs/pangeo/lib/python3.7/site-packages/distributed/worker.py", line 2053, in execute
    data[k] = self.data[k]
  File "/glade/u/home/baird/miniconda3/envs/pangeo/lib/python3.7/site-packages/zict/buffer.py", line 72, in __getitem__
    raise KeyError(key)
KeyError: "('concatenate-d2fe6d71716384862735cab74de7be2d', 2, 5, 8)"

During handling of the above exception, another exception occurred:

Traceback (most recent call last):
  File "/glade/u/home/baird/miniconda3/envs/pangeo/lib/python3.7/site-packages/distributed/worker.py", line 2056, in execute
    data[k] = Actor(type(self.actors[k]), self.address, k, self)
KeyError: "('concatenate-d2fe6d71716384862735cab74de7be2d', 2, 5, 8)"
distributed.worker - ERROR - "('concatenate-d2fe6d71716384862735cab74de7be2d', 0, 6, 1)"
Traceback (most recent call last):
  File "/glade/u/home/baird/miniconda3/envs/pangeo/lib/python3.7/site-packages/distributed/worker.py", line 2053, in execute
    data[k] = self.data[k]
  File "/glade/u/home/baird/miniconda3/envs/pangeo/lib/python3.7/site-packages/zict/buffer.py", line 72, in __getitem__
    raise KeyError(key)
KeyError: "('concatenate-d2fe6d71716384862735cab74de7be2d', 0, 6, 1)"

During handling of the above exception, another exception occurred:

Traceback (most recent call last):
  File "/glade/u/home/baird/miniconda3/envs/pangeo/lib/python3.7/site-packages/distributed/worker.py", line 2056, in execute
    data[k] = Actor(type(self.actors[k]), self.address, k, self)
KeyError: "('concatenate-d2fe6d71716384862735cab74de7be2d', 0, 6, 1)"
distributed.worker - ERROR - "('concatenate-d2fe6d71716384862735cab74de7be2d', 2, 5, 5)"
Traceback (most recent call last):
  File "/glade/u/home/baird/miniconda3/envs/pangeo/lib/python3.7/site-packages/distributed/worker.py", line 2053, in execute
    data[k] = self.data[k]
  File "/glade/u/home/baird/miniconda3/envs/pangeo/lib/python3.7/site-packages/zict/buffer.py", line 72, in __getitem__
    raise KeyError(key)
KeyError: "('concatenate-d2fe6d71716384862735cab74de7be2d', 2, 5, 5)"

During handling of the above exception, another exception occurred:

Traceback (most recent call last):
  File "/glade/u/home/baird/miniconda3/envs/pangeo/lib/python3.7/site-packages/distributed/worker.py", line 2056, in execute
    data[k] = Actor(type(self.actors[k]), self.address, k, self)
KeyError: "('concatenate-d2fe6d71716384862735cab74de7be2d', 2, 5, 5)"
distributed.worker - ERROR - "('concatenate-d2fe6d71716384862735cab74de7be2d', 14, 2, 10)"
Traceback (most recent call last):
  File "/glade/u/home/baird/miniconda3/envs/pangeo/lib/python3.7/site-packages/distributed/worker.py", line 2053, in execute
    data[k] = self.data[k]
  File "/glade/u/home/baird/miniconda3/envs/pangeo/lib/python3.7/site-packages/zict/buffer.py", line 72, in __getitem__
    raise KeyError(key)
KeyError: "('concatenate-d2fe6d71716384862735cab74de7be2d', 14, 2, 10)"

During handling of the above exception, another exception occurred:

Traceback (most recent call last):
  File "/glade/u/home/baird/miniconda3/envs/pangeo/lib/python3.7/site-packages/distributed/worker.py", line 2056, in execute
    data[k] = Actor(type(self.actors[k]), self.address, k, self)
KeyError: "('concatenate-d2fe6d71716384862735cab74de7be2d', 14, 2, 10)"
distributed.worker - ERROR - "('concatenate-d2fe6d71716384862735cab74de7be2d', 17, 5, 2)"
Traceback (most recent call last):
  File "/glade/u/home/baird/miniconda3/envs/pangeo/lib/python3.7/site-packages/distributed/worker.py", line 2053, in execute
    data[k] = self.data[k]
  File "/glade/u/home/baird/miniconda3/envs/pangeo/lib/python3.7/site-packages/zict/buffer.py", line 72, in __getitem__
    raise KeyError(key)
KeyError: "('concatenate-d2fe6d71716384862735cab74de7be2d', 17, 5, 2)"

During handling of the above exception, another exception occurred:

Traceback (most recent call last):
  File "/glade/u/home/baird/miniconda3/envs/pangeo/lib/python3.7/site-packages/distributed/worker.py", line 2056, in execute
    data[k] = Actor(type(self.actors[k]), self.address, k, self)
KeyError: "('concatenate-d2fe6d71716384862735cab74de7be2d', 17, 5, 2)"
tornado.application - ERROR - Exception in callback functools.partial(<function wrap.<locals>.null_wrapper at 0x2aab6cca32f0>, <Future finished exception=KeyError("('concatenate-d2fe6d71716384862735cab74de7be2d', 16, 6, 4)")>)
Traceback (most recent call last):
  File "/glade/u/home/baird/miniconda3/envs/pangeo/lib/python3.7/site-packages/distributed/worker.py", line 2053, in execute
    data[k] = self.data[k]
  File "/glade/u/home/baird/miniconda3/envs/pangeo/lib/python3.7/site-packages/zict/buffer.py", line 72, in __getitem__
    raise KeyError(key)
KeyError: "('concatenate-d2fe6d71716384862735cab74de7be2d', 16, 6, 4)"

During handling of the above exception, another exception occurred:

Traceback (most recent call last):
  File "/glade/u/home/baird/miniconda3/envs/pangeo/lib/python3.7/site-packages/tornado/ioloop.py", line 758, in _run_callback
    ret = callback()
  File "/glade/u/home/baird/miniconda3/envs/pangeo/lib/python3.7/site-packages/tornado/stack_context.py", line 300, in null_wrapper
    return fn(*args, **kwargs)
  File "/glade/u/home/baird/miniconda3/envs/pangeo/lib/python3.7/site-packages/tornado/ioloop.py", line 779, in _discard_future_result
    future.result()
  File "/glade/u/home/baird/miniconda3/envs/pangeo/lib/python3.7/site-packages/tornado/gen.py", line 326, in wrapper
    yielded = next(result)
  File "/glade/u/home/baird/miniconda3/envs/pangeo/lib/python3.7/site-packages/distributed/worker.py", line 2056, in execute
    data[k] = Actor(type(self.actors[k]), self.address, k, self)
KeyError: "('concatenate-d2fe6d71716384862735cab74de7be2d', 16, 6, 4)"
tornado.application - ERROR - Exception in callback functools.partial(<function wrap.<locals>.null_wrapper at 0x2aaabdf4b158>, <Future finished exception=KeyError("('concatenate-d2fe6d71716384862735cab74de7be2d', 2, 5, 8)")>)
Traceback (most recent call last):
  File "/glade/u/home/baird/miniconda3/envs/pangeo/lib/python3.7/site-packages/distributed/worker.py", line 2053, in execute
    data[k] = self.data[k]
  File "/glade/u/home/baird/miniconda3/envs/pangeo/lib/python3.7/site-packages/zict/buffer.py", line 72, in __getitem__
    raise KeyError(key)
KeyError: "('concatenate-d2fe6d71716384862735cab74de7be2d', 2, 5, 8)"

During handling of the above exception, another exception occurred:

Traceback (most recent call last):
  File "/glade/u/home/baird/miniconda3/envs/pangeo/lib/python3.7/site-packages/tornado/ioloop.py", line 758, in _run_callback
    ret = callback()
  File "/glade/u/home/baird/miniconda3/envs/pangeo/lib/python3.7/site-packages/tornado/stack_context.py", line 300, in null_wrapper
    return fn(*args, **kwargs)
  File "/glade/u/home/baird/miniconda3/envs/pangeo/lib/python3.7/site-packages/tornado/ioloop.py", line 779, in _discard_future_result
    future.result()
  File "/glade/u/home/baird/miniconda3/envs/pangeo/lib/python3.7/site-packages/tornado/gen.py", line 326, in wrapper
    yielded = next(result)
  File "/glade/u/home/baird/miniconda3/envs/pangeo/lib/python3.7/site-packages/distributed/worker.py", line 2056, in execute
    data[k] = Actor(type(self.actors[k]), self.address, k, self)
KeyError: "('concatenate-d2fe6d71716384862735cab74de7be2d', 2, 5, 8)"
tornado.application - ERROR - Exception in callback functools.partial(<function wrap.<locals>.null_wrapper at 0x2aabd8035620>, <Future finished exception=KeyError("('concatenate-d2fe6d71716384862735cab74de7be2d', 0, 6, 1)")>)
Traceback (most recent call last):
  File "/glade/u/home/baird/miniconda3/envs/pangeo/lib/python3.7/site-packages/distributed/worker.py", line 2053, in execute
    data[k] = self.data[k]
  File "/glade/u/home/baird/miniconda3/envs/pangeo/lib/python3.7/site-packages/zict/buffer.py", line 72, in __getitem__
    raise KeyError(key)
KeyError: "('concatenate-d2fe6d71716384862735cab74de7be2d', 0, 6, 1)"

During handling of the above exception, another exception occurred:

Traceback (most recent call last):
  File "/glade/u/home/baird/miniconda3/envs/pangeo/lib/python3.7/site-packages/tornado/ioloop.py", line 758, in _run_callback
    ret = callback()
  File "/glade/u/home/baird/miniconda3/envs/pangeo/lib/python3.7/site-packages/tornado/stack_context.py", line 300, in null_wrapper
    return fn(*args, **kwargs)
  File "/glade/u/home/baird/miniconda3/envs/pangeo/lib/python3.7/site-packages/tornado/ioloop.py", line 779, in _discard_future_result
    future.result()
  File "/glade/u/home/baird/miniconda3/envs/pangeo/lib/python3.7/site-packages/tornado/gen.py", line 326, in wrapper
    yielded = next(result)
  File "/glade/u/home/baird/miniconda3/envs/pangeo/lib/python3.7/site-packages/distributed/worker.py", line 2056, in execute
    data[k] = Actor(type(self.actors[k]), self.address, k, self)
KeyError: "('concatenate-d2fe6d71716384862735cab74de7be2d', 0, 6, 1)"
tornado.application - ERROR - Exception in callback functools.partial(<function wrap.<locals>.null_wrapper at 0x2aab6c06a488>, <Future finished exception=KeyError("('concatenate-d2fe6d71716384862735cab74de7be2d', 2, 5, 5)")>)
Traceback (most recent call last):
  File "/glade/u/home/baird/miniconda3/envs/pangeo/lib/python3.7/site-packages/distributed/worker.py", line 2053, in execute
    data[k] = self.data[k]
  File "/glade/u/home/baird/miniconda3/envs/pangeo/lib/python3.7/site-packages/zict/buffer.py", line 72, in __getitem__
    raise KeyError(key)
KeyError: "('concatenate-d2fe6d71716384862735cab74de7be2d', 2, 5, 5)"

During handling of the above exception, another exception occurred:

Traceback (most recent call last):
  File "/glade/u/home/baird/miniconda3/envs/pangeo/lib/python3.7/site-packages/tornado/ioloop.py", line 758, in _run_callback
    ret = callback()
  File "/glade/u/home/baird/miniconda3/envs/pangeo/lib/python3.7/site-packages/tornado/stack_context.py", line 300, in null_wrapper
    return fn(*args, **kwargs)
  File "/glade/u/home/baird/miniconda3/envs/pangeo/lib/python3.7/site-packages/tornado/ioloop.py", line 779, in _discard_future_result
    future.result()
  File "/glade/u/home/baird/miniconda3/envs/pangeo/lib/python3.7/site-packages/tornado/gen.py", line 326, in wrapper
    yielded = next(result)
  File "/glade/u/home/baird/miniconda3/envs/pangeo/lib/python3.7/site-packages/distributed/worker.py", line 2056, in execute
    data[k] = Actor(type(self.actors[k]), self.address, k, self)
KeyError: "('concatenate-d2fe6d71716384862735cab74de7be2d', 2, 5, 5)"
tornado.application - ERROR - Exception in callback functools.partial(<function wrap.<locals>.null_wrapper at 0x2aab6c06ac80>, <Future finished exception=KeyError("('concatenate-d2fe6d71716384862735cab74de7be2d', 14, 2, 10)")>)
Traceback (most recent call last):
  File "/glade/u/home/baird/miniconda3/envs/pangeo/lib/python3.7/site-packages/distributed/worker.py", line 2053, in execute
    data[k] = self.data[k]
  File "/glade/u/home/baird/miniconda3/envs/pangeo/lib/python3.7/site-packages/zict/buffer.py", line 72, in __getitem__
    raise KeyError(key)
KeyError: "('concatenate-d2fe6d71716384862735cab74de7be2d', 14, 2, 10)"

During handling of the above exception, another exception occurred:

Traceback (most recent call last):
  File "/glade/u/home/baird/miniconda3/envs/pangeo/lib/python3.7/site-packages/tornado/ioloop.py", line 758, in _run_callback
    ret = callback()
  File "/glade/u/home/baird/miniconda3/envs/pangeo/lib/python3.7/site-packages/tornado/stack_context.py", line 300, in null_wrapper
    return fn(*args, **kwargs)
  File "/glade/u/home/baird/miniconda3/envs/pangeo/lib/python3.7/site-packages/tornado/ioloop.py", line 779, in _discard_future_result
    future.result()
  File "/glade/u/home/baird/miniconda3/envs/pangeo/lib/python3.7/site-packages/tornado/gen.py", line 326, in wrapper
    yielded = next(result)
  File "/glade/u/home/baird/miniconda3/envs/pangeo/lib/python3.7/site-packages/distributed/worker.py", line 2056, in execute
    data[k] = Actor(type(self.actors[k]), self.address, k, self)
KeyError: "('concatenate-d2fe6d71716384862735cab74de7be2d', 14, 2, 10)"
tornado.application - ERROR - Exception in callback functools.partial(<function wrap.<locals>.null_wrapper at 0x2aaabd9aab70>, <Future finished exception=KeyError("('concatenate-d2fe6d71716384862735cab74de7be2d', 17, 5, 2)")>)
Traceback (most recent call last):
  File "/glade/u/home/baird/miniconda3/envs/pangeo/lib/python3.7/site-packages/distributed/worker.py", line 2053, in execute
    data[k] = self.data[k]
  File "/glade/u/home/baird/miniconda3/envs/pangeo/lib/python3.7/site-packages/zict/buffer.py", line 72, in __getitem__
    raise KeyError(key)
KeyError: "('concatenate-d2fe6d71716384862735cab74de7be2d', 17, 5, 2)"

During handling of the above exception, another exception occurred:

Traceback (most recent call last):
  File "/glade/u/home/baird/miniconda3/envs/pangeo/lib/python3.7/site-packages/tornado/ioloop.py", line 758, in _run_callback
    ret = callback()
  File "/glade/u/home/baird/miniconda3/envs/pangeo/lib/python3.7/site-packages/tornado/stack_context.py", line 300, in null_wrapper
    return fn(*args, **kwargs)
  File "/glade/u/home/baird/miniconda3/envs/pangeo/lib/python3.7/site-packages/tornado/ioloop.py", line 779, in _discard_future_result
    future.result()
  File "/glade/u/home/baird/miniconda3/envs/pangeo/lib/python3.7/site-packages/tornado/gen.py", line 326, in wrapper
    yielded = next(result)
  File "/glade/u/home/baird/miniconda3/envs/pangeo/lib/python3.7/site-packages/distributed/worker.py", line 2056, in execute
    data[k] = Actor(type(self.actors[k]), self.address, k, self)
KeyError: "('concatenate-d2fe6d71716384862735cab74de7be2d', 17, 5, 2)"
distributed.worker - ERROR - "('concatenate-d2fe6d71716384862735cab74de7be2d', 0, 6, 1)"
Traceback (most recent call last):
  File "/glade/u/home/baird/miniconda3/envs/pangeo/lib/python3.7/site-packages/distributed/worker.py", line 2053, in execute
    data[k] = self.data[k]
  File "/glade/u/home/baird/miniconda3/envs/pangeo/lib/python3.7/site-packages/zict/buffer.py", line 72, in __getitem__
    raise KeyError(key)
KeyError: "('concatenate-d2fe6d71716384862735cab74de7be2d', 0, 6, 1)"

During handling of the above exception, another exception occurred:

Traceback (most recent call last):
  File "/glade/u/home/baird/miniconda3/envs/pangeo/lib/python3.7/site-packages/distributed/worker.py", line 2056, in execute
    data[k] = Actor(type(self.actors[k]), self.address, k, self)
KeyError: "('concatenate-d2fe6d71716384862735cab74de7be2d', 0, 6, 1)"
tornado.application - ERROR - Exception in callback functools.partial(<function wrap.<locals>.null_wrapper at 0x2aab6df48620>, <Future finished exception=KeyError("('concatenate-d2fe6d71716384862735cab74de7be2d', 0, 6, 1)")>)
Traceback (most recent call last):
  File "/glade/u/home/baird/miniconda3/envs/pangeo/lib/python3.7/site-packages/distributed/worker.py", line 2053, in execute
    data[k] = self.data[k]
  File "/glade/u/home/baird/miniconda3/envs/pangeo/lib/python3.7/site-packages/zict/buffer.py", line 72, in __getitem__
    raise KeyError(key)
KeyError: "('concatenate-d2fe6d71716384862735cab74de7be2d', 0, 6, 1)"

During handling of the above exception, another exception occurred:

Traceback (most recent call last):
  File "/glade/u/home/baird/miniconda3/envs/pangeo/lib/python3.7/site-packages/tornado/ioloop.py", line 758, in _run_callback
    ret = callback()
  File "/glade/u/home/baird/miniconda3/envs/pangeo/lib/python3.7/site-packages/tornado/stack_context.py", line 300, in null_wrapper
    return fn(*args, **kwargs)
  File "/glade/u/home/baird/miniconda3/envs/pangeo/lib/python3.7/site-packages/tornado/ioloop.py", line 779, in _discard_future_result
    future.result()
  File "/glade/u/home/baird/miniconda3/envs/pangeo/lib/python3.7/site-packages/tornado/gen.py", line 326, in wrapper
    yielded = next(result)
  File "/glade/u/home/baird/miniconda3/envs/pangeo/lib/python3.7/site-packages/distributed/worker.py", line 2056, in execute
    data[k] = Actor(type(self.actors[k]), self.address, k, self)
KeyError: "('concatenate-d2fe6d71716384862735cab74de7be2d', 0, 6, 1)"
distributed.worker - ERROR - "('concatenate-d2fe6d71716384862735cab74de7be2d', 1, 3, 6)"
Traceback (most recent call last):
  File "/glade/u/home/baird/miniconda3/envs/pangeo/lib/python3.7/site-packages/distributed/worker.py", line 2053, in execute
    data[k] = self.data[k]
  File "/glade/u/home/baird/miniconda3/envs/pangeo/lib/python3.7/site-packages/zict/buffer.py", line 72, in __getitem__
    raise KeyError(key)
KeyError: "('concatenate-d2fe6d71716384862735cab74de7be2d', 1, 3, 6)"

During handling of the above exception, another exception occurred:

Traceback (most recent call last):
  File "/glade/u/home/baird/miniconda3/envs/pangeo/lib/python3.7/site-packages/distributed/worker.py", line 2056, in execute
    data[k] = Actor(type(self.actors[k]), self.address, k, self)
KeyError: "('concatenate-d2fe6d71716384862735cab74de7be2d', 1, 3, 6)"
tornado.application - ERROR - Exception in callback functools.partial(<function wrap.<locals>.null_wrapper at 0x2aab73915510>, <Future finished exception=KeyError("('concatenate-d2fe6d71716384862735cab74de7be2d', 1, 3, 6)")>)
Traceback (most recent call last):
  File "/glade/u/home/baird/miniconda3/envs/pangeo/lib/python3.7/site-packages/distributed/worker.py", line 2053, in execute
    data[k] = self.data[k]
  File "/glade/u/home/baird/miniconda3/envs/pangeo/lib/python3.7/site-packages/zict/buffer.py", line 72, in __getitem__
    raise KeyError(key)
KeyError: "('concatenate-d2fe6d71716384862735cab74de7be2d', 1, 3, 6)"

During handling of the above exception, another exception occurred:

Traceback (most recent call last):
  File "/glade/u/home/baird/miniconda3/envs/pangeo/lib/python3.7/site-packages/tornado/ioloop.py", line 758, in _run_callback
    ret = callback()
  File "/glade/u/home/baird/miniconda3/envs/pangeo/lib/python3.7/site-packages/tornado/stack_context.py", line 300, in null_wrapper
    return fn(*args, **kwargs)
  File "/glade/u/home/baird/miniconda3/envs/pangeo/lib/python3.7/site-packages/tornado/ioloop.py", line 779, in _discard_future_result
    future.result()
  File "/glade/u/home/baird/miniconda3/envs/pangeo/lib/python3.7/site-packages/tornado/gen.py", line 326, in wrapper
    yielded = next(result)
  File "/glade/u/home/baird/miniconda3/envs/pangeo/lib/python3.7/site-packages/distributed/worker.py", line 2056, in execute
    data[k] = Actor(type(self.actors[k]), self.address, k, self)
KeyError: "('concatenate-d2fe6d71716384862735cab74de7be2d', 1, 3, 6)"
distributed.worker - ERROR - "('concatenate-d2fe6d71716384862735cab74de7be2d', 15, 7, 9)"
Traceback (most recent call last):
  File "/glade/u/home/baird/miniconda3/envs/pangeo/lib/python3.7/site-packages/distributed/worker.py", line 2053, in execute
    data[k] = self.data[k]
  File "/glade/u/home/baird/miniconda3/envs/pangeo/lib/python3.7/site-packages/zict/buffer.py", line 72, in __getitem__
    raise KeyError(key)
KeyError: "('concatenate-d2fe6d71716384862735cab74de7be2d', 15, 7, 9)"

During handling of the above exception, another exception occurred:

Traceback (most recent call last):
  File "/glade/u/home/baird/miniconda3/envs/pangeo/lib/python3.7/site-packages/distributed/worker.py", line 2056, in execute
    data[k] = Actor(type(self.actors[k]), self.address, k, self)
KeyError: "('concatenate-d2fe6d71716384862735cab74de7be2d', 15, 7, 9)"
tornado.application - ERROR - Exception in callback functools.partial(<function wrap.<locals>.null_wrapper at 0x2aab6fbbb620>, <Future finished exception=KeyError("('concatenate-d2fe6d71716384862735cab74de7be2d', 15, 7, 9)")>)
Traceback (most recent call last):
  File "/glade/u/home/baird/miniconda3/envs/pangeo/lib/python3.7/site-packages/distributed/worker.py", line 2053, in execute
    data[k] = self.data[k]
  File "/glade/u/home/baird/miniconda3/envs/pangeo/lib/python3.7/site-packages/zict/buffer.py", line 72, in __getitem__
    raise KeyError(key)
KeyError: "('concatenate-d2fe6d71716384862735cab74de7be2d', 15, 7, 9)"

During handling of the above exception, another exception occurred:

Traceback (most recent call last):
  File "/glade/u/home/baird/miniconda3/envs/pangeo/lib/python3.7/site-packages/tornado/ioloop.py", line 758, in _run_callback
    ret = callback()
  File "/glade/u/home/baird/miniconda3/envs/pangeo/lib/python3.7/site-packages/tornado/stack_context.py", line 300, in null_wrapper
    return fn(*args, **kwargs)
  File "/glade/u/home/baird/miniconda3/envs/pangeo/lib/python3.7/site-packages/tornado/ioloop.py", line 779, in _discard_future_result
    future.result()
  File "/glade/u/home/baird/miniconda3/envs/pangeo/lib/python3.7/site-packages/tornado/gen.py", line 326, in wrapper
    yielded = next(result)
  File "/glade/u/home/baird/miniconda3/envs/pangeo/lib/python3.7/site-packages/distributed/worker.py", line 2056, in execute
    data[k] = Actor(type(self.actors[k]), self.address, k, self)
KeyError: "('concatenate-d2fe6d71716384862735cab74de7be2d', 15, 7, 9)"
distributed.worker - ERROR - "('concatenate-d2fe6d71716384862735cab74de7be2d', 3, 4, 4)"
Traceback (most recent call last):
  File "/glade/u/home/baird/miniconda3/envs/pangeo/lib/python3.7/site-packages/distributed/worker.py", line 2053, in execute
    data[k] = self.data[k]
  File "/glade/u/home/baird/miniconda3/envs/pangeo/lib/python3.7/site-packages/zict/buffer.py", line 72, in __getitem__
    raise KeyError(key)
KeyError: "('concatenate-d2fe6d71716384862735cab74de7be2d', 3, 4, 4)"

During handling of the above exception, another exception occurred:

Traceback (most recent call last):
  File "/glade/u/home/baird/miniconda3/envs/pangeo/lib/python3.7/site-packages/distributed/worker.py", line 2056, in execute
    data[k] = Actor(type(self.actors[k]), self.address, k, self)
KeyError: "('concatenate-d2fe6d71716384862735cab74de7be2d', 3, 4, 4)"
tornado.application - ERROR - Exception in callback functools.partial(<function wrap.<locals>.null_wrapper at 0x2aab13ac38c8>, <Future finished exception=KeyError("('concatenate-d2fe6d71716384862735cab74de7be2d', 3, 4, 4)")>)
Traceback (most recent call last):
  File "/glade/u/home/baird/miniconda3/envs/pangeo/lib/python3.7/site-packages/distributed/worker.py", line 2053, in execute
    data[k] = self.data[k]
  File "/glade/u/home/baird/miniconda3/envs/pangeo/lib/python3.7/site-packages/zict/buffer.py", line 72, in __getitem__
    raise KeyError(key)
KeyError: "('concatenate-d2fe6d71716384862735cab74de7be2d', 3, 4, 4)"

During handling of the above exception, another exception occurred:

Traceback (most recent call last):
  File "/glade/u/home/baird/miniconda3/envs/pangeo/lib/python3.7/site-packages/tornado/ioloop.py", line 758, in _run_callback
    ret = callback()
  File "/glade/u/home/baird/miniconda3/envs/pangeo/lib/python3.7/site-packages/tornado/stack_context.py", line 300, in null_wrapper
    return fn(*args, **kwargs)
  File "/glade/u/home/baird/miniconda3/envs/pangeo/lib/python3.7/site-packages/tornado/ioloop.py", line 779, in _discard_future_result
    future.result()
  File "/glade/u/home/baird/miniconda3/envs/pangeo/lib/python3.7/site-packages/tornado/gen.py", line 326, in wrapper
    yielded = next(result)
  File "/glade/u/home/baird/miniconda3/envs/pangeo/lib/python3.7/site-packages/distributed/worker.py", line 2056, in execute
    data[k] = Actor(type(self.actors[k]), self.address, k, self)
KeyError: "('concatenate-d2fe6d71716384862735cab74de7be2d', 3, 4, 4)"
distributed.worker - INFO - Stopping worker at tcp://10.148.9.132:35176
distributed.worker - INFO - Connection to scheduler broken.  Reconnecting...
distributed.worker - INFO - -------------------------------------------------
distributed.nanny - INFO - Closing Nanny at 'tcp://10.148.9.132:34490'
distributed.dask_worker - INFO - End worker
