distributed.nanny - INFO -         Start Nanny at: 'tcp://10.148.7.239:38222'
distributed.worker - INFO -       Start worker at:   tcp://10.148.7.239:59258
distributed.worker - INFO -          Listening to:   tcp://10.148.7.239:59258
distributed.worker - INFO -              nanny at:         10.148.7.239:38222
distributed.worker - INFO -              bokeh at:         10.148.7.239:59730
distributed.worker - INFO - Waiting to connect to:  tcp://10.148.13.150:44940
distributed.worker - INFO - -------------------------------------------------
distributed.worker - INFO -               Threads:                         36
distributed.worker - INFO -                Memory:                  100.00 GB
distributed.worker - INFO -       Local Directory: /var/tmp/pbs.4277319.chadmin1/worker-znhshg0e
distributed.worker - INFO - -------------------------------------------------
distributed.worker - INFO -         Registered to:  tcp://10.148.13.150:44940
distributed.worker - INFO - -------------------------------------------------
distributed.core - INFO - Starting established connection
distributed.core - INFO - Event loop was unresponsive in Worker for 10.46s.  This is often caused by long-running GIL-holding functions or moving large chunks of data. This can cause timeouts and instability.
distributed.core - INFO - Event loop was unresponsive in Worker for 42.82s.  This is often caused by long-running GIL-holding functions or moving large chunks of data. This can cause timeouts and instability.
distributed.core - INFO - Event loop was unresponsive in Worker for 41.49s.  This is often caused by long-running GIL-holding functions or moving large chunks of data. This can cause timeouts and instability.
distributed.worker - INFO - Failed to put key in memory
Traceback (most recent call last):
  File "/glade/u/home/baird/miniconda3/envs/pangeo/lib/python3.7/site-packages/distributed/worker.py", line 1356, in transition_executing_done
    self.put_key_in_memory(key, value, transition=False)
  File "/glade/u/home/baird/miniconda3/envs/pangeo/lib/python3.7/site-packages/distributed/worker.py", line 1548, in put_key_in_memory
    self.data[key] = value
  File "/glade/u/home/baird/miniconda3/envs/pangeo/lib/python3.7/site-packages/zict/buffer.py", line 80, in __setitem__
    self.fast[key] = value
  File "/glade/u/home/baird/miniconda3/envs/pangeo/lib/python3.7/site-packages/zict/lru.py", line 71, in __setitem__
    self.evict()
  File "/glade/u/home/baird/miniconda3/envs/pangeo/lib/python3.7/site-packages/zict/lru.py", line 90, in evict
    cb(k, v)
  File "/glade/u/home/baird/miniconda3/envs/pangeo/lib/python3.7/site-packages/zict/buffer.py", line 52, in fast_to_slow
    self.slow[key] = value
  File "/glade/u/home/baird/miniconda3/envs/pangeo/lib/python3.7/site-packages/zict/func.py", line 42, in __setitem__
    self.d[key] = self.dump(value)
  File "/glade/u/home/baird/miniconda3/envs/pangeo/lib/python3.7/site-packages/zict/file.py", line 83, in __setitem__
    f.write(v)
OSError: [Errno 28] No space left on device
distributed.core - INFO - Event loop was unresponsive in Worker for 171.97s.  This is often caused by long-running GIL-holding functions or moving large chunks of data. This can cause timeouts and instability.
distributed.core - INFO - Event loop was unresponsive in Worker for 47.56s.  This is often caused by long-running GIL-holding functions or moving large chunks of data. This can cause timeouts and instability.
distributed.worker - INFO - Failed to put key in memory
Traceback (most recent call last):
  File "/glade/u/home/baird/miniconda3/envs/pangeo/lib/python3.7/site-packages/distributed/worker.py", line 1356, in transition_executing_done
    self.put_key_in_memory(key, value, transition=False)
  File "/glade/u/home/baird/miniconda3/envs/pangeo/lib/python3.7/site-packages/distributed/worker.py", line 1548, in put_key_in_memory
    self.data[key] = value
  File "/glade/u/home/baird/miniconda3/envs/pangeo/lib/python3.7/site-packages/zict/buffer.py", line 80, in __setitem__
    self.fast[key] = value
  File "/glade/u/home/baird/miniconda3/envs/pangeo/lib/python3.7/site-packages/zict/lru.py", line 71, in __setitem__
    self.evict()
  File "/glade/u/home/baird/miniconda3/envs/pangeo/lib/python3.7/site-packages/zict/lru.py", line 90, in evict
    cb(k, v)
  File "/glade/u/home/baird/miniconda3/envs/pangeo/lib/python3.7/site-packages/zict/buffer.py", line 52, in fast_to_slow
    self.slow[key] = value
  File "/glade/u/home/baird/miniconda3/envs/pangeo/lib/python3.7/site-packages/zict/func.py", line 42, in __setitem__
    self.d[key] = self.dump(value)
  File "/glade/u/home/baird/miniconda3/envs/pangeo/lib/python3.7/site-packages/zict/file.py", line 83, in __setitem__
    f.write(v)
OSError: [Errno 28] No space left on device
distributed.worker - INFO - Failed to put key in memory
Traceback (most recent call last):
  File "/glade/u/home/baird/miniconda3/envs/pangeo/lib/python3.7/site-packages/zict/file.py", line 83, in __setitem__
    f.write(v)
OSError: [Errno 28] No space left on device

During handling of the above exception, another exception occurred:

Traceback (most recent call last):
  File "/glade/u/home/baird/miniconda3/envs/pangeo/lib/python3.7/site-packages/distributed/worker.py", line 1356, in transition_executing_done
    self.put_key_in_memory(key, value, transition=False)
  File "/glade/u/home/baird/miniconda3/envs/pangeo/lib/python3.7/site-packages/distributed/worker.py", line 1548, in put_key_in_memory
    self.data[key] = value
  File "/glade/u/home/baird/miniconda3/envs/pangeo/lib/python3.7/site-packages/zict/buffer.py", line 80, in __setitem__
    self.fast[key] = value
  File "/glade/u/home/baird/miniconda3/envs/pangeo/lib/python3.7/site-packages/zict/lru.py", line 71, in __setitem__
    self.evict()
  File "/glade/u/home/baird/miniconda3/envs/pangeo/lib/python3.7/site-packages/zict/lru.py", line 90, in evict
    cb(k, v)
  File "/glade/u/home/baird/miniconda3/envs/pangeo/lib/python3.7/site-packages/zict/buffer.py", line 52, in fast_to_slow
    self.slow[key] = value
  File "/glade/u/home/baird/miniconda3/envs/pangeo/lib/python3.7/site-packages/zict/func.py", line 42, in __setitem__
    self.d[key] = self.dump(value)
  File "/glade/u/home/baird/miniconda3/envs/pangeo/lib/python3.7/site-packages/zict/file.py", line 85, in __setitem__
    f.write(value)
OSError: [Errno 28] No space left on device
distributed.worker - INFO - Failed to put key in memory
Traceback (most recent call last):
  File "/glade/u/home/baird/miniconda3/envs/pangeo/lib/python3.7/site-packages/distributed/worker.py", line 1356, in transition_executing_done
    self.put_key_in_memory(key, value, transition=False)
  File "/glade/u/home/baird/miniconda3/envs/pangeo/lib/python3.7/site-packages/distributed/worker.py", line 1548, in put_key_in_memory
    self.data[key] = value
  File "/glade/u/home/baird/miniconda3/envs/pangeo/lib/python3.7/site-packages/zict/buffer.py", line 80, in __setitem__
    self.fast[key] = value
  File "/glade/u/home/baird/miniconda3/envs/pangeo/lib/python3.7/site-packages/zict/lru.py", line 71, in __setitem__
    self.evict()
  File "/glade/u/home/baird/miniconda3/envs/pangeo/lib/python3.7/site-packages/zict/lru.py", line 90, in evict
    cb(k, v)
  File "/glade/u/home/baird/miniconda3/envs/pangeo/lib/python3.7/site-packages/zict/buffer.py", line 52, in fast_to_slow
    self.slow[key] = value
  File "/glade/u/home/baird/miniconda3/envs/pangeo/lib/python3.7/site-packages/zict/func.py", line 42, in __setitem__
    self.d[key] = self.dump(value)
  File "/glade/u/home/baird/miniconda3/envs/pangeo/lib/python3.7/site-packages/zict/file.py", line 83, in __setitem__
    f.write(v)
OSError: [Errno 28] No space left on device
distributed.worker - INFO - Failed to put key in memory
Traceback (most recent call last):
  File "/glade/u/home/baird/miniconda3/envs/pangeo/lib/python3.7/site-packages/zict/file.py", line 83, in __setitem__
    f.write(v)
OSError: [Errno 28] No space left on device

During handling of the above exception, another exception occurred:

Traceback (most recent call last):
  File "/glade/u/home/baird/miniconda3/envs/pangeo/lib/python3.7/site-packages/distributed/worker.py", line 1356, in transition_executing_done
    self.put_key_in_memory(key, value, transition=False)
  File "/glade/u/home/baird/miniconda3/envs/pangeo/lib/python3.7/site-packages/distributed/worker.py", line 1548, in put_key_in_memory
    self.data[key] = value
  File "/glade/u/home/baird/miniconda3/envs/pangeo/lib/python3.7/site-packages/zict/buffer.py", line 80, in __setitem__
    self.fast[key] = value
  File "/glade/u/home/baird/miniconda3/envs/pangeo/lib/python3.7/site-packages/zict/lru.py", line 71, in __setitem__
    self.evict()
  File "/glade/u/home/baird/miniconda3/envs/pangeo/lib/python3.7/site-packages/zict/lru.py", line 90, in evict
    cb(k, v)
  File "/glade/u/home/baird/miniconda3/envs/pangeo/lib/python3.7/site-packages/zict/buffer.py", line 52, in fast_to_slow
    self.slow[key] = value
  File "/glade/u/home/baird/miniconda3/envs/pangeo/lib/python3.7/site-packages/zict/func.py", line 42, in __setitem__
    self.d[key] = self.dump(value)
  File "/glade/u/home/baird/miniconda3/envs/pangeo/lib/python3.7/site-packages/zict/file.py", line 85, in __setitem__
    f.write(value)
OSError: [Errno 28] No space left on device
distributed.worker - INFO - Failed to put key in memory
Traceback (most recent call last):
  File "/glade/u/home/baird/miniconda3/envs/pangeo/lib/python3.7/site-packages/zict/file.py", line 83, in __setitem__
    f.write(v)
OSError: [Errno 28] No space left on device

During handling of the above exception, another exception occurred:

Traceback (most recent call last):
  File "/glade/u/home/baird/miniconda3/envs/pangeo/lib/python3.7/site-packages/distributed/worker.py", line 1356, in transition_executing_done
    self.put_key_in_memory(key, value, transition=False)
  File "/glade/u/home/baird/miniconda3/envs/pangeo/lib/python3.7/site-packages/distributed/worker.py", line 1548, in put_key_in_memory
    self.data[key] = value
  File "/glade/u/home/baird/miniconda3/envs/pangeo/lib/python3.7/site-packages/zict/buffer.py", line 80, in __setitem__
    self.fast[key] = value
  File "/glade/u/home/baird/miniconda3/envs/pangeo/lib/python3.7/site-packages/zict/lru.py", line 71, in __setitem__
    self.evict()
  File "/glade/u/home/baird/miniconda3/envs/pangeo/lib/python3.7/site-packages/zict/lru.py", line 90, in evict
    cb(k, v)
  File "/glade/u/home/baird/miniconda3/envs/pangeo/lib/python3.7/site-packages/zict/buffer.py", line 52, in fast_to_slow
    self.slow[key] = value
  File "/glade/u/home/baird/miniconda3/envs/pangeo/lib/python3.7/site-packages/zict/func.py", line 42, in __setitem__
    self.d[key] = self.dump(value)
  File "/glade/u/home/baird/miniconda3/envs/pangeo/lib/python3.7/site-packages/zict/file.py", line 85, in __setitem__
    f.write(value)
OSError: [Errno 28] No space left on device
distributed.worker - INFO - Failed to put key in memory
Traceback (most recent call last):
  File "/glade/u/home/baird/miniconda3/envs/pangeo/lib/python3.7/site-packages/zict/file.py", line 83, in __setitem__
    f.write(v)
OSError: [Errno 28] No space left on device

During handling of the above exception, another exception occurred:

Traceback (most recent call last):
  File "/glade/u/home/baird/miniconda3/envs/pangeo/lib/python3.7/site-packages/distributed/worker.py", line 1356, in transition_executing_done
    self.put_key_in_memory(key, value, transition=False)
  File "/glade/u/home/baird/miniconda3/envs/pangeo/lib/python3.7/site-packages/distributed/worker.py", line 1548, in put_key_in_memory
    self.data[key] = value
  File "/glade/u/home/baird/miniconda3/envs/pangeo/lib/python3.7/site-packages/zict/buffer.py", line 80, in __setitem__
    self.fast[key] = value
  File "/glade/u/home/baird/miniconda3/envs/pangeo/lib/python3.7/site-packages/zict/lru.py", line 71, in __setitem__
    self.evict()
  File "/glade/u/home/baird/miniconda3/envs/pangeo/lib/python3.7/site-packages/zict/lru.py", line 90, in evict
    cb(k, v)
  File "/glade/u/home/baird/miniconda3/envs/pangeo/lib/python3.7/site-packages/zict/buffer.py", line 52, in fast_to_slow
    self.slow[key] = value
  File "/glade/u/home/baird/miniconda3/envs/pangeo/lib/python3.7/site-packages/zict/func.py", line 42, in __setitem__
    self.d[key] = self.dump(value)
  File "/glade/u/home/baird/miniconda3/envs/pangeo/lib/python3.7/site-packages/zict/file.py", line 85, in __setitem__
    f.write(value)
OSError: [Errno 28] No space left on device
distributed.worker - ERROR - [Errno 28] No space left on device
Traceback (most recent call last):
  File "/glade/u/home/baird/miniconda3/envs/pangeo/lib/python3.7/site-packages/zict/file.py", line 83, in __setitem__
    f.write(v)
OSError: [Errno 28] No space left on device

During handling of the above exception, another exception occurred:

Traceback (most recent call last):
  File "/glade/u/home/baird/miniconda3/envs/pangeo/lib/python3.7/site-packages/distributed/worker.py", line 1225, in transition_dep_flight_memory
    self.put_key_in_memory(dep, value)
  File "/glade/u/home/baird/miniconda3/envs/pangeo/lib/python3.7/site-packages/distributed/worker.py", line 1548, in put_key_in_memory
    self.data[key] = value
  File "/glade/u/home/baird/miniconda3/envs/pangeo/lib/python3.7/site-packages/zict/buffer.py", line 80, in __setitem__
    self.fast[key] = value
  File "/glade/u/home/baird/miniconda3/envs/pangeo/lib/python3.7/site-packages/zict/lru.py", line 71, in __setitem__
    self.evict()
  File "/glade/u/home/baird/miniconda3/envs/pangeo/lib/python3.7/site-packages/zict/lru.py", line 90, in evict
    cb(k, v)
  File "/glade/u/home/baird/miniconda3/envs/pangeo/lib/python3.7/site-packages/zict/buffer.py", line 52, in fast_to_slow
    self.slow[key] = value
  File "/glade/u/home/baird/miniconda3/envs/pangeo/lib/python3.7/site-packages/zict/func.py", line 42, in __setitem__
    self.d[key] = self.dump(value)
  File "/glade/u/home/baird/miniconda3/envs/pangeo/lib/python3.7/site-packages/zict/file.py", line 85, in __setitem__
    f.write(value)
OSError: [Errno 28] No space left on device
distributed.utils - ERROR - [Errno 28] No space left on device
Traceback (most recent call last):
  File "/glade/u/home/baird/miniconda3/envs/pangeo/lib/python3.7/site-packages/zict/file.py", line 83, in __setitem__
    f.write(v)
OSError: [Errno 28] No space left on device

During handling of the above exception, another exception occurred:

Traceback (most recent call last):
  File "/glade/u/home/baird/miniconda3/envs/pangeo/lib/python3.7/site-packages/distributed/utils.py", line 648, in log_errors
    yield
  File "/glade/u/home/baird/miniconda3/envs/pangeo/lib/python3.7/site-packages/distributed/worker.py", line 1669, in gather_dep
    self.transition_dep(d, 'memory', value=data[d])
  File "/glade/u/home/baird/miniconda3/envs/pangeo/lib/python3.7/site-packages/distributed/worker.py", line 1160, in transition_dep
    state = func(dep, **kwargs)
  File "/glade/u/home/baird/miniconda3/envs/pangeo/lib/python3.7/site-packages/distributed/worker.py", line 1225, in transition_dep_flight_memory
    self.put_key_in_memory(dep, value)
  File "/glade/u/home/baird/miniconda3/envs/pangeo/lib/python3.7/site-packages/distributed/worker.py", line 1548, in put_key_in_memory
    self.data[key] = value
  File "/glade/u/home/baird/miniconda3/envs/pangeo/lib/python3.7/site-packages/zict/buffer.py", line 80, in __setitem__
    self.fast[key] = value
  File "/glade/u/home/baird/miniconda3/envs/pangeo/lib/python3.7/site-packages/zict/lru.py", line 71, in __setitem__
    self.evict()
  File "/glade/u/home/baird/miniconda3/envs/pangeo/lib/python3.7/site-packages/zict/lru.py", line 90, in evict
    cb(k, v)
  File "/glade/u/home/baird/miniconda3/envs/pangeo/lib/python3.7/site-packages/zict/buffer.py", line 52, in fast_to_slow
    self.slow[key] = value
  File "/glade/u/home/baird/miniconda3/envs/pangeo/lib/python3.7/site-packages/zict/func.py", line 42, in __setitem__
    self.d[key] = self.dump(value)
  File "/glade/u/home/baird/miniconda3/envs/pangeo/lib/python3.7/site-packages/zict/file.py", line 85, in __setitem__
    f.write(value)
OSError: [Errno 28] No space left on device
tornado.application - ERROR - Exception in callback functools.partial(<function wrap.<locals>.null_wrapper at 0x2aab6c83b730>, <Future finished exception=OSError(28, 'No space left on device')>)
Traceback (most recent call last):
  File "/glade/u/home/baird/miniconda3/envs/pangeo/lib/python3.7/site-packages/zict/file.py", line 83, in __setitem__
    f.write(v)
OSError: [Errno 28] No space left on device

During handling of the above exception, another exception occurred:

Traceback (most recent call last):
  File "/glade/u/home/baird/miniconda3/envs/pangeo/lib/python3.7/site-packages/tornado/ioloop.py", line 758, in _run_callback
    ret = callback()
  File "/glade/u/home/baird/miniconda3/envs/pangeo/lib/python3.7/site-packages/tornado/stack_context.py", line 300, in null_wrapper
    return fn(*args, **kwargs)
  File "/glade/u/home/baird/miniconda3/envs/pangeo/lib/python3.7/site-packages/tornado/ioloop.py", line 779, in _discard_future_result
    future.result()
  File "/glade/u/home/baird/miniconda3/envs/pangeo/lib/python3.7/site-packages/tornado/gen.py", line 1147, in run
    yielded = self.gen.send(value)
  File "/glade/u/home/baird/miniconda3/envs/pangeo/lib/python3.7/site-packages/distributed/worker.py", line 1669, in gather_dep
    self.transition_dep(d, 'memory', value=data[d])
  File "/glade/u/home/baird/miniconda3/envs/pangeo/lib/python3.7/site-packages/distributed/worker.py", line 1160, in transition_dep
    state = func(dep, **kwargs)
  File "/glade/u/home/baird/miniconda3/envs/pangeo/lib/python3.7/site-packages/distributed/worker.py", line 1225, in transition_dep_flight_memory
    self.put_key_in_memory(dep, value)
  File "/glade/u/home/baird/miniconda3/envs/pangeo/lib/python3.7/site-packages/distributed/worker.py", line 1548, in put_key_in_memory
    self.data[key] = value
  File "/glade/u/home/baird/miniconda3/envs/pangeo/lib/python3.7/site-packages/zict/buffer.py", line 80, in __setitem__
    self.fast[key] = value
  File "/glade/u/home/baird/miniconda3/envs/pangeo/lib/python3.7/site-packages/zict/lru.py", line 71, in __setitem__
    self.evict()
  File "/glade/u/home/baird/miniconda3/envs/pangeo/lib/python3.7/site-packages/zict/lru.py", line 90, in evict
    cb(k, v)
  File "/glade/u/home/baird/miniconda3/envs/pangeo/lib/python3.7/site-packages/zict/buffer.py", line 52, in fast_to_slow
    self.slow[key] = value
  File "/glade/u/home/baird/miniconda3/envs/pangeo/lib/python3.7/site-packages/zict/func.py", line 42, in __setitem__
    self.d[key] = self.dump(value)
  File "/glade/u/home/baird/miniconda3/envs/pangeo/lib/python3.7/site-packages/zict/file.py", line 85, in __setitem__
    f.write(value)
OSError: [Errno 28] No space left on device
distributed.worker - INFO - Failed to put key in memory
Traceback (most recent call last):
  File "/glade/u/home/baird/miniconda3/envs/pangeo/lib/python3.7/site-packages/zict/file.py", line 83, in __setitem__
    f.write(v)
OSError: [Errno 28] No space left on device

During handling of the above exception, another exception occurred:

Traceback (most recent call last):
  File "/glade/u/home/baird/miniconda3/envs/pangeo/lib/python3.7/site-packages/distributed/worker.py", line 1356, in transition_executing_done
    self.put_key_in_memory(key, value, transition=False)
  File "/glade/u/home/baird/miniconda3/envs/pangeo/lib/python3.7/site-packages/distributed/worker.py", line 1548, in put_key_in_memory
    self.data[key] = value
  File "/glade/u/home/baird/miniconda3/envs/pangeo/lib/python3.7/site-packages/zict/buffer.py", line 80, in __setitem__
    self.fast[key] = value
  File "/glade/u/home/baird/miniconda3/envs/pangeo/lib/python3.7/site-packages/zict/lru.py", line 71, in __setitem__
    self.evict()
  File "/glade/u/home/baird/miniconda3/envs/pangeo/lib/python3.7/site-packages/zict/lru.py", line 90, in evict
    cb(k, v)
  File "/glade/u/home/baird/miniconda3/envs/pangeo/lib/python3.7/site-packages/zict/buffer.py", line 52, in fast_to_slow
    self.slow[key] = value
  File "/glade/u/home/baird/miniconda3/envs/pangeo/lib/python3.7/site-packages/zict/func.py", line 42, in __setitem__
    self.d[key] = self.dump(value)
  File "/glade/u/home/baird/miniconda3/envs/pangeo/lib/python3.7/site-packages/zict/file.py", line 85, in __setitem__
    f.write(value)
OSError: [Errno 28] No space left on device
distributed.worker - INFO - Failed to put key in memory
Traceback (most recent call last):
  File "/glade/u/home/baird/miniconda3/envs/pangeo/lib/python3.7/site-packages/zict/file.py", line 83, in __setitem__
    f.write(v)
OSError: [Errno 28] No space left on device

During handling of the above exception, another exception occurred:

Traceback (most recent call last):
  File "/glade/u/home/baird/miniconda3/envs/pangeo/lib/python3.7/site-packages/distributed/worker.py", line 1356, in transition_executing_done
    self.put_key_in_memory(key, value, transition=False)
  File "/glade/u/home/baird/miniconda3/envs/pangeo/lib/python3.7/site-packages/distributed/worker.py", line 1548, in put_key_in_memory
    self.data[key] = value
  File "/glade/u/home/baird/miniconda3/envs/pangeo/lib/python3.7/site-packages/zict/buffer.py", line 80, in __setitem__
    self.fast[key] = value
  File "/glade/u/home/baird/miniconda3/envs/pangeo/lib/python3.7/site-packages/zict/lru.py", line 71, in __setitem__
    self.evict()
  File "/glade/u/home/baird/miniconda3/envs/pangeo/lib/python3.7/site-packages/zict/lru.py", line 90, in evict
    cb(k, v)
  File "/glade/u/home/baird/miniconda3/envs/pangeo/lib/python3.7/site-packages/zict/buffer.py", line 52, in fast_to_slow
    self.slow[key] = value
  File "/glade/u/home/baird/miniconda3/envs/pangeo/lib/python3.7/site-packages/zict/func.py", line 42, in __setitem__
    self.d[key] = self.dump(value)
  File "/glade/u/home/baird/miniconda3/envs/pangeo/lib/python3.7/site-packages/zict/file.py", line 85, in __setitem__
    f.write(value)
OSError: [Errno 28] No space left on device
distributed.worker - INFO - Can't find dependencies for key ('getitem-9b35b2fb40f7cc4a57eb77b82250a3fd', 14, 0, 5, 0)
distributed.worker - INFO - Dependent not found: ('func-overlap-getitem-9b35b2fb40f7cc4a57eb77b82250a3fd', 14, 0, 5, 0) 0 .  Asking scheduler
distributed.worker - INFO - Can't find dependencies for key ('getitem-9b35b2fb40f7cc4a57eb77b82250a3fd', 17, 5, 14, 0)
distributed.worker - INFO - Dependent not found: ('func-overlap-getitem-9b35b2fb40f7cc4a57eb77b82250a3fd', 17, 5, 14, 0) 0 .  Asking scheduler
distributed.worker - INFO - Failed to put key in memory
Traceback (most recent call last):
  File "/glade/u/home/baird/miniconda3/envs/pangeo/lib/python3.7/site-packages/zict/file.py", line 83, in __setitem__
    f.write(v)
OSError: [Errno 28] No space left on device

During handling of the above exception, another exception occurred:

Traceback (most recent call last):
  File "/glade/u/home/baird/miniconda3/envs/pangeo/lib/python3.7/site-packages/distributed/worker.py", line 1356, in transition_executing_done
    self.put_key_in_memory(key, value, transition=False)
  File "/glade/u/home/baird/miniconda3/envs/pangeo/lib/python3.7/site-packages/distributed/worker.py", line 1548, in put_key_in_memory
    self.data[key] = value
  File "/glade/u/home/baird/miniconda3/envs/pangeo/lib/python3.7/site-packages/zict/buffer.py", line 80, in __setitem__
    self.fast[key] = value
  File "/glade/u/home/baird/miniconda3/envs/pangeo/lib/python3.7/site-packages/zict/lru.py", line 71, in __setitem__
    self.evict()
  File "/glade/u/home/baird/miniconda3/envs/pangeo/lib/python3.7/site-packages/zict/lru.py", line 90, in evict
    cb(k, v)
  File "/glade/u/home/baird/miniconda3/envs/pangeo/lib/python3.7/site-packages/zict/buffer.py", line 52, in fast_to_slow
    self.slow[key] = value
  File "/glade/u/home/baird/miniconda3/envs/pangeo/lib/python3.7/site-packages/zict/func.py", line 42, in __setitem__
    self.d[key] = self.dump(value)
  File "/glade/u/home/baird/miniconda3/envs/pangeo/lib/python3.7/site-packages/zict/file.py", line 85, in __setitem__
    f.write(value)
OSError: [Errno 28] No space left on device
distributed.worker - INFO - Failed to put key in memory
Traceback (most recent call last):
  File "/glade/u/home/baird/miniconda3/envs/pangeo/lib/python3.7/site-packages/zict/file.py", line 83, in __setitem__
    f.write(v)
OSError: [Errno 28] No space left on device

During handling of the above exception, another exception occurred:

Traceback (most recent call last):
  File "/glade/u/home/baird/miniconda3/envs/pangeo/lib/python3.7/site-packages/distributed/worker.py", line 1356, in transition_executing_done
    self.put_key_in_memory(key, value, transition=False)
  File "/glade/u/home/baird/miniconda3/envs/pangeo/lib/python3.7/site-packages/distributed/worker.py", line 1548, in put_key_in_memory
    self.data[key] = value
  File "/glade/u/home/baird/miniconda3/envs/pangeo/lib/python3.7/site-packages/zict/buffer.py", line 80, in __setitem__
    self.fast[key] = value
  File "/glade/u/home/baird/miniconda3/envs/pangeo/lib/python3.7/site-packages/zict/lru.py", line 71, in __setitem__
    self.evict()
  File "/glade/u/home/baird/miniconda3/envs/pangeo/lib/python3.7/site-packages/zict/lru.py", line 90, in evict
    cb(k, v)
  File "/glade/u/home/baird/miniconda3/envs/pangeo/lib/python3.7/site-packages/zict/buffer.py", line 52, in fast_to_slow
    self.slow[key] = value
  File "/glade/u/home/baird/miniconda3/envs/pangeo/lib/python3.7/site-packages/zict/func.py", line 42, in __setitem__
    self.d[key] = self.dump(value)
  File "/glade/u/home/baird/miniconda3/envs/pangeo/lib/python3.7/site-packages/zict/file.py", line 85, in __setitem__
    f.write(value)
OSError: [Errno 28] No space left on device
distributed.worker - INFO - Can't find dependencies for key ('getitem-9b35b2fb40f7cc4a57eb77b82250a3fd', 13, 2, 14, 0)
distributed.worker - INFO - Dependent not found: ('func-overlap-getitem-9b35b2fb40f7cc4a57eb77b82250a3fd', 13, 2, 14, 0) 0 .  Asking scheduler
distributed.worker - INFO - Failed to put key in memory
Traceback (most recent call last):
  File "/glade/u/home/baird/miniconda3/envs/pangeo/lib/python3.7/site-packages/zict/file.py", line 83, in __setitem__
    f.write(v)
OSError: [Errno 28] No space left on device

During handling of the above exception, another exception occurred:

Traceback (most recent call last):
  File "/glade/u/home/baird/miniconda3/envs/pangeo/lib/python3.7/site-packages/distributed/worker.py", line 1356, in transition_executing_done
    self.put_key_in_memory(key, value, transition=False)
  File "/glade/u/home/baird/miniconda3/envs/pangeo/lib/python3.7/site-packages/distributed/worker.py", line 1548, in put_key_in_memory
    self.data[key] = value
  File "/glade/u/home/baird/miniconda3/envs/pangeo/lib/python3.7/site-packages/zict/buffer.py", line 80, in __setitem__
    self.fast[key] = value
  File "/glade/u/home/baird/miniconda3/envs/pangeo/lib/python3.7/site-packages/zict/lru.py", line 71, in __setitem__
    self.evict()
  File "/glade/u/home/baird/miniconda3/envs/pangeo/lib/python3.7/site-packages/zict/lru.py", line 90, in evict
    cb(k, v)
  File "/glade/u/home/baird/miniconda3/envs/pangeo/lib/python3.7/site-packages/zict/buffer.py", line 52, in fast_to_slow
    self.slow[key] = value
  File "/glade/u/home/baird/miniconda3/envs/pangeo/lib/python3.7/site-packages/zict/func.py", line 42, in __setitem__
    self.d[key] = self.dump(value)
  File "/glade/u/home/baird/miniconda3/envs/pangeo/lib/python3.7/site-packages/zict/file.py", line 85, in __setitem__
    f.write(value)
OSError: [Errno 28] No space left on device
distributed.worker - INFO - Failed to put key in memory
Traceback (most recent call last):
  File "/glade/u/home/baird/miniconda3/envs/pangeo/lib/python3.7/site-packages/zict/file.py", line 83, in __setitem__
    f.write(v)
OSError: [Errno 28] No space left on device

During handling of the above exception, another exception occurred:

Traceback (most recent call last):
  File "/glade/u/home/baird/miniconda3/envs/pangeo/lib/python3.7/site-packages/distributed/worker.py", line 1356, in transition_executing_done
    self.put_key_in_memory(key, value, transition=False)
  File "/glade/u/home/baird/miniconda3/envs/pangeo/lib/python3.7/site-packages/distributed/worker.py", line 1548, in put_key_in_memory
    self.data[key] = value
  File "/glade/u/home/baird/miniconda3/envs/pangeo/lib/python3.7/site-packages/zict/buffer.py", line 80, in __setitem__
    self.fast[key] = value
  File "/glade/u/home/baird/miniconda3/envs/pangeo/lib/python3.7/site-packages/zict/lru.py", line 71, in __setitem__
    self.evict()
  File "/glade/u/home/baird/miniconda3/envs/pangeo/lib/python3.7/site-packages/zict/lru.py", line 90, in evict
    cb(k, v)
  File "/glade/u/home/baird/miniconda3/envs/pangeo/lib/python3.7/site-packages/zict/buffer.py", line 52, in fast_to_slow
    self.slow[key] = value
  File "/glade/u/home/baird/miniconda3/envs/pangeo/lib/python3.7/site-packages/zict/func.py", line 42, in __setitem__
    self.d[key] = self.dump(value)
  File "/glade/u/home/baird/miniconda3/envs/pangeo/lib/python3.7/site-packages/zict/file.py", line 85, in __setitem__
    f.write(value)
OSError: [Errno 28] No space left on device
distributed.core - ERROR - [Errno 28] No space left on device
Traceback (most recent call last):
  File "/glade/u/home/baird/miniconda3/envs/pangeo/lib/python3.7/site-packages/distributed/core.py", line 346, in handle_comm
    result = yield result
  File "/glade/u/home/baird/miniconda3/envs/pangeo/lib/python3.7/site-packages/tornado/gen.py", line 1133, in run
    value = future.result()
  File "/glade/u/home/baird/miniconda3/envs/pangeo/lib/python3.7/site-packages/tornado/gen.py", line 326, in wrapper
    yielded = next(result)
  File "/glade/u/home/baird/miniconda3/envs/pangeo/lib/python3.7/site-packages/distributed/worker.py", line 932, in get_data
    data = {k: self.data[k] for k in keys if k in self.data}
  File "/glade/u/home/baird/miniconda3/envs/pangeo/lib/python3.7/site-packages/distributed/worker.py", line 932, in <dictcomp>
    data = {k: self.data[k] for k in keys if k in self.data}
  File "/glade/u/home/baird/miniconda3/envs/pangeo/lib/python3.7/site-packages/zict/buffer.py", line 70, in __getitem__
    return self.slow_to_fast(key)
  File "/glade/u/home/baird/miniconda3/envs/pangeo/lib/python3.7/site-packages/zict/buffer.py", line 61, in slow_to_fast
    self.fast[key] = value
  File "/glade/u/home/baird/miniconda3/envs/pangeo/lib/python3.7/site-packages/zict/lru.py", line 71, in __setitem__
    self.evict()
  File "/glade/u/home/baird/miniconda3/envs/pangeo/lib/python3.7/site-packages/zict/lru.py", line 90, in evict
    cb(k, v)
  File "/glade/u/home/baird/miniconda3/envs/pangeo/lib/python3.7/site-packages/zict/buffer.py", line 52, in fast_to_slow
    self.slow[key] = value
  File "/glade/u/home/baird/miniconda3/envs/pangeo/lib/python3.7/site-packages/zict/func.py", line 42, in __setitem__
    self.d[key] = self.dump(value)
  File "/glade/u/home/baird/miniconda3/envs/pangeo/lib/python3.7/site-packages/zict/file.py", line 83, in __setitem__
    f.write(v)
OSError: [Errno 28] No space left on device
distributed.worker - INFO - Can't find dependencies for key ('getitem-9b35b2fb40f7cc4a57eb77b82250a3fd', 13, 4, 7, 0)
distributed.worker - INFO - Dependent not found: ('func-overlap-getitem-9b35b2fb40f7cc4a57eb77b82250a3fd', 13, 4, 7, 0) 0 .  Asking scheduler
distributed.worker - INFO - Can't find dependencies for key ('getitem-9b35b2fb40f7cc4a57eb77b82250a3fd', 7, 5, 2, 0)
distributed.worker - INFO - Dependent not found: ('func-overlap-getitem-9b35b2fb40f7cc4a57eb77b82250a3fd', 7, 5, 2, 0) 0 .  Asking scheduler
distributed.worker - INFO - Can't find dependencies for key ('getitem-9b35b2fb40f7cc4a57eb77b82250a3fd', 8, 5, 2, 0)
distributed.worker - INFO - Dependent not found: ('func-overlap-getitem-9b35b2fb40f7cc4a57eb77b82250a3fd', 8, 5, 2, 0) 0 .  Asking scheduler
distributed.worker - INFO - Failed to put key in memory
Traceback (most recent call last):
  File "/glade/u/home/baird/miniconda3/envs/pangeo/lib/python3.7/site-packages/distributed/worker.py", line 1356, in transition_executing_done
    self.put_key_in_memory(key, value, transition=False)
  File "/glade/u/home/baird/miniconda3/envs/pangeo/lib/python3.7/site-packages/distributed/worker.py", line 1548, in put_key_in_memory
    self.data[key] = value
  File "/glade/u/home/baird/miniconda3/envs/pangeo/lib/python3.7/site-packages/zict/buffer.py", line 80, in __setitem__
    self.fast[key] = value
  File "/glade/u/home/baird/miniconda3/envs/pangeo/lib/python3.7/site-packages/zict/lru.py", line 71, in __setitem__
    self.evict()
  File "/glade/u/home/baird/miniconda3/envs/pangeo/lib/python3.7/site-packages/zict/lru.py", line 90, in evict
    cb(k, v)
  File "/glade/u/home/baird/miniconda3/envs/pangeo/lib/python3.7/site-packages/zict/buffer.py", line 52, in fast_to_slow
    self.slow[key] = value
  File "/glade/u/home/baird/miniconda3/envs/pangeo/lib/python3.7/site-packages/zict/func.py", line 42, in __setitem__
    self.d[key] = self.dump(value)
  File "/glade/u/home/baird/miniconda3/envs/pangeo/lib/python3.7/site-packages/zict/file.py", line 83, in __setitem__
    f.write(v)
OSError: [Errno 28] No space left on device
distributed.worker - ERROR - "('getitem-0492d4f74ee1dd7cebb39de1317245fa', 5, 4, 13)"
Traceback (most recent call last):
  File "/glade/u/home/baird/miniconda3/envs/pangeo/lib/python3.7/site-packages/distributed/worker.py", line 2053, in execute
    data[k] = self.data[k]
  File "/glade/u/home/baird/miniconda3/envs/pangeo/lib/python3.7/site-packages/zict/buffer.py", line 72, in __getitem__
    raise KeyError(key)
KeyError: "('getitem-0492d4f74ee1dd7cebb39de1317245fa', 5, 4, 13)"

During handling of the above exception, another exception occurred:

Traceback (most recent call last):
  File "/glade/u/home/baird/miniconda3/envs/pangeo/lib/python3.7/site-packages/distributed/worker.py", line 2056, in execute
    data[k] = Actor(type(self.actors[k]), self.address, k, self)
KeyError: "('getitem-0492d4f74ee1dd7cebb39de1317245fa', 5, 4, 13)"
tornado.application - ERROR - Exception in callback functools.partial(<function wrap.<locals>.null_wrapper at 0x2aab6c889d90>, <Future finished exception=KeyError("('getitem-0492d4f74ee1dd7cebb39de1317245fa', 5, 4, 13)")>)
Traceback (most recent call last):
  File "/glade/u/home/baird/miniconda3/envs/pangeo/lib/python3.7/site-packages/distributed/worker.py", line 2053, in execute
    data[k] = self.data[k]
  File "/glade/u/home/baird/miniconda3/envs/pangeo/lib/python3.7/site-packages/zict/buffer.py", line 72, in __getitem__
    raise KeyError(key)
KeyError: "('getitem-0492d4f74ee1dd7cebb39de1317245fa', 5, 4, 13)"

During handling of the above exception, another exception occurred:

Traceback (most recent call last):
  File "/glade/u/home/baird/miniconda3/envs/pangeo/lib/python3.7/site-packages/tornado/ioloop.py", line 758, in _run_callback
    ret = callback()
  File "/glade/u/home/baird/miniconda3/envs/pangeo/lib/python3.7/site-packages/tornado/stack_context.py", line 300, in null_wrapper
    return fn(*args, **kwargs)
  File "/glade/u/home/baird/miniconda3/envs/pangeo/lib/python3.7/site-packages/tornado/ioloop.py", line 779, in _discard_future_result
    future.result()
  File "/glade/u/home/baird/miniconda3/envs/pangeo/lib/python3.7/site-packages/tornado/gen.py", line 326, in wrapper
    yielded = next(result)
  File "/glade/u/home/baird/miniconda3/envs/pangeo/lib/python3.7/site-packages/distributed/worker.py", line 2056, in execute
    data[k] = Actor(type(self.actors[k]), self.address, k, self)
KeyError: "('getitem-0492d4f74ee1dd7cebb39de1317245fa', 5, 4, 13)"
distributed.worker - INFO - Failed to put key in memory
Traceback (most recent call last):
  File "/glade/u/home/baird/miniconda3/envs/pangeo/lib/python3.7/site-packages/distributed/worker.py", line 1356, in transition_executing_done
    self.put_key_in_memory(key, value, transition=False)
  File "/glade/u/home/baird/miniconda3/envs/pangeo/lib/python3.7/site-packages/distributed/worker.py", line 1548, in put_key_in_memory
    self.data[key] = value
  File "/glade/u/home/baird/miniconda3/envs/pangeo/lib/python3.7/site-packages/zict/buffer.py", line 80, in __setitem__
    self.fast[key] = value
  File "/glade/u/home/baird/miniconda3/envs/pangeo/lib/python3.7/site-packages/zict/lru.py", line 71, in __setitem__
    self.evict()
  File "/glade/u/home/baird/miniconda3/envs/pangeo/lib/python3.7/site-packages/zict/lru.py", line 90, in evict
    cb(k, v)
  File "/glade/u/home/baird/miniconda3/envs/pangeo/lib/python3.7/site-packages/zict/buffer.py", line 52, in fast_to_slow
    self.slow[key] = value
  File "/glade/u/home/baird/miniconda3/envs/pangeo/lib/python3.7/site-packages/zict/func.py", line 42, in __setitem__
    self.d[key] = self.dump(value)
  File "/glade/u/home/baird/miniconda3/envs/pangeo/lib/python3.7/site-packages/zict/file.py", line 83, in __setitem__
    f.write(v)
OSError: [Errno 28] No space left on device
distributed.worker - ERROR - "('getitem-0492d4f74ee1dd7cebb39de1317245fa', 7, 5, 7)"
Traceback (most recent call last):
  File "/glade/u/home/baird/miniconda3/envs/pangeo/lib/python3.7/site-packages/distributed/worker.py", line 2053, in execute
    data[k] = self.data[k]
  File "/glade/u/home/baird/miniconda3/envs/pangeo/lib/python3.7/site-packages/zict/buffer.py", line 72, in __getitem__
    raise KeyError(key)
KeyError: "('getitem-0492d4f74ee1dd7cebb39de1317245fa', 7, 5, 7)"

During handling of the above exception, another exception occurred:

Traceback (most recent call last):
  File "/glade/u/home/baird/miniconda3/envs/pangeo/lib/python3.7/site-packages/distributed/worker.py", line 2056, in execute
    data[k] = Actor(type(self.actors[k]), self.address, k, self)
KeyError: "('getitem-0492d4f74ee1dd7cebb39de1317245fa', 7, 5, 7)"
tornado.application - ERROR - Exception in callback functools.partial(<function wrap.<locals>.null_wrapper at 0x2aaaadefa6a8>, <Future finished exception=KeyError("('getitem-0492d4f74ee1dd7cebb39de1317245fa', 7, 5, 7)")>)
Traceback (most recent call last):
  File "/glade/u/home/baird/miniconda3/envs/pangeo/lib/python3.7/site-packages/distributed/worker.py", line 2053, in execute
    data[k] = self.data[k]
  File "/glade/u/home/baird/miniconda3/envs/pangeo/lib/python3.7/site-packages/zict/buffer.py", line 72, in __getitem__
    raise KeyError(key)
KeyError: "('getitem-0492d4f74ee1dd7cebb39de1317245fa', 7, 5, 7)"

During handling of the above exception, another exception occurred:

Traceback (most recent call last):
  File "/glade/u/home/baird/miniconda3/envs/pangeo/lib/python3.7/site-packages/tornado/ioloop.py", line 758, in _run_callback
    ret = callback()
  File "/glade/u/home/baird/miniconda3/envs/pangeo/lib/python3.7/site-packages/tornado/stack_context.py", line 300, in null_wrapper
    return fn(*args, **kwargs)
  File "/glade/u/home/baird/miniconda3/envs/pangeo/lib/python3.7/site-packages/tornado/ioloop.py", line 779, in _discard_future_result
    future.result()
  File "/glade/u/home/baird/miniconda3/envs/pangeo/lib/python3.7/site-packages/tornado/gen.py", line 326, in wrapper
    yielded = next(result)
  File "/glade/u/home/baird/miniconda3/envs/pangeo/lib/python3.7/site-packages/distributed/worker.py", line 2056, in execute
    data[k] = Actor(type(self.actors[k]), self.address, k, self)
KeyError: "('getitem-0492d4f74ee1dd7cebb39de1317245fa', 7, 5, 7)"
distributed.worker - ERROR - "('getitem-0492d4f74ee1dd7cebb39de1317245fa', 16.9, 5, 3)"
Traceback (most recent call last):
  File "/glade/u/home/baird/miniconda3/envs/pangeo/lib/python3.7/site-packages/distributed/worker.py", line 1881, in release_dep
    del self.types[dep]
KeyError: "('getitem-0492d4f74ee1dd7cebb39de1317245fa', 16.9, 5, 3)"
Future exception was never retrieved
future: <Future finished exception=KeyError("('getitem-0492d4f74ee1dd7cebb39de1317245fa', 16.9, 5, 3)")>
Traceback (most recent call last):
  File "/glade/u/home/baird/miniconda3/envs/pangeo/lib/python3.7/site-packages/tornado/gen.py", line 326, in wrapper
    yielded = next(result)
  File "/glade/u/home/baird/miniconda3/envs/pangeo/lib/python3.7/site-packages/distributed/worker.py", line 1018, in delete_data
    self.release_dep(key)
  File "/glade/u/home/baird/miniconda3/envs/pangeo/lib/python3.7/site-packages/distributed/worker.py", line 1881, in release_dep
    del self.types[dep]
KeyError: "('getitem-0492d4f74ee1dd7cebb39de1317245fa', 16.9, 5, 3)"
distributed.worker - INFO - Failed to put key in memory
Traceback (most recent call last):
  File "/glade/u/home/baird/miniconda3/envs/pangeo/lib/python3.7/site-packages/distributed/worker.py", line 1356, in transition_executing_done
    self.put_key_in_memory(key, value, transition=False)
  File "/glade/u/home/baird/miniconda3/envs/pangeo/lib/python3.7/site-packages/distributed/worker.py", line 1548, in put_key_in_memory
    self.data[key] = value
  File "/glade/u/home/baird/miniconda3/envs/pangeo/lib/python3.7/site-packages/zict/buffer.py", line 80, in __setitem__
    self.fast[key] = value
  File "/glade/u/home/baird/miniconda3/envs/pangeo/lib/python3.7/site-packages/zict/lru.py", line 71, in __setitem__
    self.evict()
  File "/glade/u/home/baird/miniconda3/envs/pangeo/lib/python3.7/site-packages/zict/lru.py", line 90, in evict
    cb(k, v)
  File "/glade/u/home/baird/miniconda3/envs/pangeo/lib/python3.7/site-packages/zict/buffer.py", line 52, in fast_to_slow
    self.slow[key] = value
  File "/glade/u/home/baird/miniconda3/envs/pangeo/lib/python3.7/site-packages/zict/func.py", line 42, in __setitem__
    self.d[key] = self.dump(value)
  File "/glade/u/home/baird/miniconda3/envs/pangeo/lib/python3.7/site-packages/zict/file.py", line 83, in __setitem__
    f.write(v)
OSError: [Errno 28] No space left on device
distributed.worker - INFO - Failed to put key in memory
Traceback (most recent call last):
  File "/glade/u/home/baird/miniconda3/envs/pangeo/lib/python3.7/site-packages/zict/file.py", line 83, in __setitem__
    f.write(v)
OSError: [Errno 28] No space left on device

During handling of the above exception, another exception occurred:

Traceback (most recent call last):
  File "/glade/u/home/baird/miniconda3/envs/pangeo/lib/python3.7/site-packages/distributed/worker.py", line 1356, in transition_executing_done
    self.put_key_in_memory(key, value, transition=False)
  File "/glade/u/home/baird/miniconda3/envs/pangeo/lib/python3.7/site-packages/distributed/worker.py", line 1548, in put_key_in_memory
    self.data[key] = value
  File "/glade/u/home/baird/miniconda3/envs/pangeo/lib/python3.7/site-packages/zict/buffer.py", line 80, in __setitem__
    self.fast[key] = value
  File "/glade/u/home/baird/miniconda3/envs/pangeo/lib/python3.7/site-packages/zict/lru.py", line 71, in __setitem__
    self.evict()
  File "/glade/u/home/baird/miniconda3/envs/pangeo/lib/python3.7/site-packages/zict/lru.py", line 90, in evict
    cb(k, v)
  File "/glade/u/home/baird/miniconda3/envs/pangeo/lib/python3.7/site-packages/zict/buffer.py", line 52, in fast_to_slow
    self.slow[key] = value
  File "/glade/u/home/baird/miniconda3/envs/pangeo/lib/python3.7/site-packages/zict/func.py", line 42, in __setitem__
    self.d[key] = self.dump(value)
  File "/glade/u/home/baird/miniconda3/envs/pangeo/lib/python3.7/site-packages/zict/file.py", line 85, in __setitem__
    f.write(value)
OSError: [Errno 28] No space left on device
distributed.worker - INFO - Failed to put key in memory
Traceback (most recent call last):
  File "/glade/u/home/baird/miniconda3/envs/pangeo/lib/python3.7/site-packages/zict/file.py", line 83, in __setitem__
    f.write(v)
OSError: [Errno 28] No space left on device

During handling of the above exception, another exception occurred:

Traceback (most recent call last):
  File "/glade/u/home/baird/miniconda3/envs/pangeo/lib/python3.7/site-packages/distributed/worker.py", line 1356, in transition_executing_done
    self.put_key_in_memory(key, value, transition=False)
  File "/glade/u/home/baird/miniconda3/envs/pangeo/lib/python3.7/site-packages/distributed/worker.py", line 1548, in put_key_in_memory
    self.data[key] = value
  File "/glade/u/home/baird/miniconda3/envs/pangeo/lib/python3.7/site-packages/zict/buffer.py", line 80, in __setitem__
    self.fast[key] = value
  File "/glade/u/home/baird/miniconda3/envs/pangeo/lib/python3.7/site-packages/zict/lru.py", line 71, in __setitem__
    self.evict()
  File "/glade/u/home/baird/miniconda3/envs/pangeo/lib/python3.7/site-packages/zict/lru.py", line 90, in evict
    cb(k, v)
  File "/glade/u/home/baird/miniconda3/envs/pangeo/lib/python3.7/site-packages/zict/buffer.py", line 52, in fast_to_slow
    self.slow[key] = value
  File "/glade/u/home/baird/miniconda3/envs/pangeo/lib/python3.7/site-packages/zict/func.py", line 42, in __setitem__
    self.d[key] = self.dump(value)
  File "/glade/u/home/baird/miniconda3/envs/pangeo/lib/python3.7/site-packages/zict/file.py", line 85, in __setitem__
    f.write(value)
OSError: [Errno 28] No space left on device
distributed.worker - INFO - Failed to put key in memory
Traceback (most recent call last):
  File "/glade/u/home/baird/miniconda3/envs/pangeo/lib/python3.7/site-packages/zict/file.py", line 83, in __setitem__
    f.write(v)
OSError: [Errno 28] No space left on device

During handling of the above exception, another exception occurred:

Traceback (most recent call last):
  File "/glade/u/home/baird/miniconda3/envs/pangeo/lib/python3.7/site-packages/distributed/worker.py", line 1356, in transition_executing_done
    self.put_key_in_memory(key, value, transition=False)
  File "/glade/u/home/baird/miniconda3/envs/pangeo/lib/python3.7/site-packages/distributed/worker.py", line 1548, in put_key_in_memory
    self.data[key] = value
  File "/glade/u/home/baird/miniconda3/envs/pangeo/lib/python3.7/site-packages/zict/buffer.py", line 80, in __setitem__
    self.fast[key] = value
  File "/glade/u/home/baird/miniconda3/envs/pangeo/lib/python3.7/site-packages/zict/lru.py", line 71, in __setitem__
    self.evict()
  File "/glade/u/home/baird/miniconda3/envs/pangeo/lib/python3.7/site-packages/zict/lru.py", line 90, in evict
    cb(k, v)
  File "/glade/u/home/baird/miniconda3/envs/pangeo/lib/python3.7/site-packages/zict/buffer.py", line 52, in fast_to_slow
    self.slow[key] = value
  File "/glade/u/home/baird/miniconda3/envs/pangeo/lib/python3.7/site-packages/zict/func.py", line 42, in __setitem__
    self.d[key] = self.dump(value)
  File "/glade/u/home/baird/miniconda3/envs/pangeo/lib/python3.7/site-packages/zict/file.py", line 85, in __setitem__
    f.write(value)
OSError: [Errno 28] No space left on device
=>> PBS: job killed: walltime 10864 exceeded limit 10800
distributed.dask_worker - INFO - Exiting on signal 15
distributed.nanny - INFO - Closing Nanny at 'tcp://10.148.7.239:38222'
distributed.nanny - WARNING - Worker process 40026 was killed by unknown signal
distributed.dask_worker - INFO - End worker
